2022-02-05 20:39:31 WARNING (SyncWorker_0) [homeassistant.loader] We found a custom integration ble_monitor which has not been tested by Home Assistant. This component might cause stability problems, be sure to disable it if you experience issues with Home Assistant
2022-02-05 20:39:31 WARNING (SyncWorker_1) [homeassistant.loader] We found a custom integration hacs which has not been tested by Home Assistant. This component might cause stability problems, be sure to disable it if you experience issues with Home Assistant
2022-02-05 20:39:37 WARNING (MainThread) [homeassistant.helpers.frame] Detected code that uses str (diagnostic) for entity category. This is deprecated and will stop working in Home Assistant 2022.4, it should be updated to use EntityCategory instead. Please report this issue.
Stack (most recent call last):
  File "/usr/local/lib/python3.9/runpy.py", line 197, in _run_module_as_main
    return _run_code(code, main_globals, None,
  File "/usr/local/lib/python3.9/runpy.py", line 87, in _run_code
    exec(code, run_globals)
  File "/usr/src/homeassistant/homeassistant/__main__.py", line 203, in <module>
    sys.exit(main())
  File "/usr/src/homeassistant/homeassistant/__main__.py", line 191, in main
    exit_code = runner.run(runtime_conf)
  File "/usr/src/homeassistant/homeassistant/runner.py", line 119, in run
    return loop.run_until_complete(setup_and_run_hass(runtime_config))
  File "/usr/local/lib/python3.9/asyncio/base_events.py", line 629, in run_until_complete
    self.run_forever()
  File "/usr/local/lib/python3.9/asyncio/base_events.py", line 596, in run_forever
    self._run_once()
  File "/usr/local/lib/python3.9/asyncio/base_events.py", line 1890, in _run_once
    handle._run()
  File "/usr/local/lib/python3.9/asyncio/events.py", line 80, in _run
    self._context.run(self._callback, *self._args)
  File "/usr/src/homeassistant/homeassistant/helpers/entity_platform.py", line 510, in _async_add_entity
    entry = entity_registry.async_get_or_create(
  File "/usr/src/homeassistant/homeassistant/helpers/entity_registry.py", line 401, in async_get_or_create
    entity_category=_convert_to_entity_category(entity_category),
  File "/usr/src/homeassistant/homeassistant/helpers/entity_registry.py", line 103, in _convert_to_entity_category
    return convert_to_entity_category(value, raise_report=raise_report)
  File "/usr/src/homeassistant/homeassistant/helpers/entity.py", line 214, in convert_to_entity_category
    report(
  File "/usr/src/homeassistant/homeassistant/helpers/frame.py", line 74, in report
    _LOGGER.warning(msg, stack_info=True)
Stack (most recent call last):
  File "/usr/local/lib/python3.9/runpy.py", line 197, in _run_module_as_main
    return _run_code(code, main_globals, None,
  File "/usr/local/lib/python3.9/runpy.py", line 87, in _run_code
    exec(code, run_globals)
  File "/usr/src/homeassistant/homeassistant/__main__.py", line 203, in <module>
    sys.exit(main())
  File "/usr/src/homeassistant/homeassistant/__main__.py", line 191, in main
    exit_code = runner.run(runtime_conf)
  File "/usr/src/homeassistant/homeassistant/runner.py", line 119, in run
    return loop.run_until_complete(setup_and_run_hass(runtime_config))
  File "/usr/local/lib/python3.9/asyncio/base_events.py", line 629, in run_until_complete
    self.run_forever()
  File "/usr/local/lib/python3.9/asyncio/base_events.py", line 596, in run_forever
    self._run_once()
  File "/usr/local/lib/python3.9/asyncio/base_events.py", line 1890, in _run_once
    handle._run()
  File "/usr/local/lib/python3.9/asyncio/events.py", line 80, in _run
    self._context.run(self._callback, *self._args)
  File "/usr/src/homeassistant/homeassistant/helpers/entity_platform.py", line 510, in _async_add_entity
    entry = entity_registry.async_get_or_create(
  File "/usr/src/homeassistant/homeassistant/helpers/entity_registry.py", line 401, in async_get_or_create
    entity_category=_convert_to_entity_category(entity_category),
  File "/usr/src/homeassistant/homeassistant/helpers/entity_registry.py", line 103, in _convert_to_entity_category
    return convert_to_entity_category(value, raise_report=raise_report)
  File "/usr/src/homeassistant/homeassistant/helpers/entity.py", line 214, in convert_to_entity_category
    report(
  File "/usr/src/homeassistant/homeassistant/helpers/frame.py", line 74, in report
    _LOGGER.warning(msg, stack_info=True)
2022-02-05 20:39:37 WARNING (MainThread) [homeassistant.helpers.frame] Detected code that uses str (diagnostic) for entity category. This is deprecated and will stop working in Home Assistant 2022.4, it should be updated to use EntityCategory instead. Please report this issue.
Stack (most recent call last):
  File "/usr/local/lib/python3.9/runpy.py", line 197, in _run_module_as_main
    return _run_code(code, main_globals, None,
  File "/usr/local/lib/python3.9/runpy.py", line 87, in _run_code
    exec(code, run_globals)
  File "/usr/src/homeassistant/homeassistant/__main__.py", line 203, in <module>
    sys.exit(main())
  File "/usr/src/homeassistant/homeassistant/__main__.py", line 191, in main
    exit_code = runner.run(runtime_conf)
  File "/usr/src/homeassistant/homeassistant/runner.py", line 119, in run
    return loop.run_until_complete(setup_and_run_hass(runtime_config))
  File "/usr/local/lib/python3.9/asyncio/base_events.py", line 629, in run_until_complete
    self.run_forever()
  File "/usr/local/lib/python3.9/asyncio/base_events.py", line 596, in run_forever
    self._run_once()
  File "/usr/local/lib/python3.9/asyncio/base_events.py", line 1890, in _run_once
    handle._run()
  File "/usr/local/lib/python3.9/asyncio/events.py", line 80, in _run
    self._context.run(self._callback, *self._args)
  File "/usr/src/homeassistant/homeassistant/helpers/entity_platform.py", line 510, in _async_add_entity
    entry = entity_registry.async_get_or_create(
  File "/usr/src/homeassistant/homeassistant/helpers/entity_registry.py", line 401, in async_get_or_create
    entity_category=_convert_to_entity_category(entity_category),
  File "/usr/src/homeassistant/homeassistant/helpers/entity_registry.py", line 103, in _convert_to_entity_category
    return convert_to_entity_category(value, raise_report=raise_report)
  File "/usr/src/homeassistant/homeassistant/helpers/entity.py", line 214, in convert_to_entity_category
    report(
  File "/usr/src/homeassistant/homeassistant/helpers/frame.py", line 74, in report
    _LOGGER.warning(msg, stack_info=True)
Stack (most recent call last):
  File "/usr/local/lib/python3.9/runpy.py", line 197, in _run_module_as_main
    return _run_code(code, main_globals, None,
  File "/usr/local/lib/python3.9/runpy.py", line 87, in _run_code
    exec(code, run_globals)
  File "/usr/src/homeassistant/homeassistant/__main__.py", line 203, in <module>
    sys.exit(main())
  File "/usr/src/homeassistant/homeassistant/__main__.py", line 191, in main
    exit_code = runner.run(runtime_conf)
  File "/usr/src/homeassistant/homeassistant/runner.py", line 119, in run
    return loop.run_until_complete(setup_and_run_hass(runtime_config))
  File "/usr/local/lib/python3.9/asyncio/base_events.py", line 629, in run_until_complete
    self.run_forever()
  File "/usr/local/lib/python3.9/asyncio/base_events.py", line 596, in run_forever
    self._run_once()
  File "/usr/local/lib/python3.9/asyncio/base_events.py", line 1890, in _run_once
    handle._run()
  File "/usr/local/lib/python3.9/asyncio/events.py", line 80, in _run
    self._context.run(self._callback, *self._args)
  File "/usr/src/homeassistant/homeassistant/helpers/entity_platform.py", line 510, in _async_add_entity
    entry = entity_registry.async_get_or_create(
  File "/usr/src/homeassistant/homeassistant/helpers/entity_registry.py", line 401, in async_get_or_create
    entity_category=_convert_to_entity_category(entity_category),
  File "/usr/src/homeassistant/homeassistant/helpers/entity_registry.py", line 103, in _convert_to_entity_category
    return convert_to_entity_category(value, raise_report=raise_report)
  File "/usr/src/homeassistant/homeassistant/helpers/entity.py", line 214, in convert_to_entity_category
    report(
  File "/usr/src/homeassistant/homeassistant/helpers/frame.py", line 74, in report
    _LOGGER.warning(msg, stack_info=True)
2022-02-05 20:39:37 WARNING (MainThread) [homeassistant.helpers.frame] Detected code that uses str (diagnostic) for entity category. This is deprecated and will stop working in Home Assistant 2022.4, it should be updated to use EntityCategory instead. Please report this issue.
Stack (most recent call last):
  File "/usr/local/lib/python3.9/runpy.py", line 197, in _run_module_as_main
    return _run_code(code, main_globals, None,
  File "/usr/local/lib/python3.9/runpy.py", line 87, in _run_code
    exec(code, run_globals)
  File "/usr/src/homeassistant/homeassistant/__main__.py", line 203, in <module>
    sys.exit(main())
  File "/usr/src/homeassistant/homeassistant/__main__.py", line 191, in main
    exit_code = runner.run(runtime_conf)
  File "/usr/src/homeassistant/homeassistant/runner.py", line 119, in run
    return loop.run_until_complete(setup_and_run_hass(runtime_config))
  File "/usr/local/lib/python3.9/asyncio/base_events.py", line 629, in run_until_complete
    self.run_forever()
  File "/usr/local/lib/python3.9/asyncio/base_events.py", line 596, in run_forever
    self._run_once()
  File "/usr/local/lib/python3.9/asyncio/base_events.py", line 1890, in _run_once
    handle._run()
  File "/usr/local/lib/python3.9/asyncio/events.py", line 80, in _run
    self._context.run(self._callback, *self._args)
  File "/usr/src/homeassistant/homeassistant/helpers/entity_platform.py", line 510, in _async_add_entity
    entry = entity_registry.async_get_or_create(
  File "/usr/src/homeassistant/homeassistant/helpers/entity_registry.py", line 401, in async_get_or_create
    entity_category=_convert_to_entity_category(entity_category),
  File "/usr/src/homeassistant/homeassistant/helpers/entity_registry.py", line 103, in _convert_to_entity_category
    return convert_to_entity_category(value, raise_report=raise_report)
  File "/usr/src/homeassistant/homeassistant/helpers/entity.py", line 214, in convert_to_entity_category
    report(
  File "/usr/src/homeassistant/homeassistant/helpers/frame.py", line 74, in report
    _LOGGER.warning(msg, stack_info=True)
Stack (most recent call last):
  File "/usr/local/lib/python3.9/runpy.py", line 197, in _run_module_as_main
    return _run_code(code, main_globals, None,
  File "/usr/local/lib/python3.9/runpy.py", line 87, in _run_code
    exec(code, run_globals)
  File "/usr/src/homeassistant/homeassistant/__main__.py", line 203, in <module>
    sys.exit(main())
  File "/usr/src/homeassistant/homeassistant/__main__.py", line 191, in main
    exit_code = runner.run(runtime_conf)
  File "/usr/src/homeassistant/homeassistant/runner.py", line 119, in run
    return loop.run_until_complete(setup_and_run_hass(runtime_config))
  File "/usr/local/lib/python3.9/asyncio/base_events.py", line 629, in run_until_complete
    self.run_forever()
  File "/usr/local/lib/python3.9/asyncio/base_events.py", line 596, in run_forever
    self._run_once()
  File "/usr/local/lib/python3.9/asyncio/base_events.py", line 1890, in _run_once
    handle._run()
  File "/usr/local/lib/python3.9/asyncio/events.py", line 80, in _run
    self._context.run(self._callback, *self._args)
  File "/usr/src/homeassistant/homeassistant/helpers/entity_platform.py", line 510, in _async_add_entity
    entry = entity_registry.async_get_or_create(
  File "/usr/src/homeassistant/homeassistant/helpers/entity_registry.py", line 401, in async_get_or_create
    entity_category=_convert_to_entity_category(entity_category),
  File "/usr/src/homeassistant/homeassistant/helpers/entity_registry.py", line 103, in _convert_to_entity_category
    return convert_to_entity_category(value, raise_report=raise_report)
  File "/usr/src/homeassistant/homeassistant/helpers/entity.py", line 214, in convert_to_entity_category
    report(
  File "/usr/src/homeassistant/homeassistant/helpers/frame.py", line 74, in report
    _LOGGER.warning(msg, stack_info=True)
2022-02-05 20:39:37 WARNING (MainThread) [homeassistant.helpers.frame] Detected code that uses str (diagnostic) for entity category. This is deprecated and will stop working in Home Assistant 2022.4, it should be updated to use EntityCategory instead. Please report this issue.
Stack (most recent call last):
  File "/usr/local/lib/python3.9/runpy.py", line 197, in _run_module_as_main
    return _run_code(code, main_globals, None,
  File "/usr/local/lib/python3.9/runpy.py", line 87, in _run_code
    exec(code, run_globals)
  File "/usr/src/homeassistant/homeassistant/__main__.py", line 203, in <module>
    sys.exit(main())
  File "/usr/src/homeassistant/homeassistant/__main__.py", line 191, in main
    exit_code = runner.run(runtime_conf)
  File "/usr/src/homeassistant/homeassistant/runner.py", line 119, in run
    return loop.run_until_complete(setup_and_run_hass(runtime_config))
  File "/usr/local/lib/python3.9/asyncio/base_events.py", line 629, in run_until_complete
    self.run_forever()
  File "/usr/local/lib/python3.9/asyncio/base_events.py", line 596, in run_forever
    self._run_once()
  File "/usr/local/lib/python3.9/asyncio/base_events.py", line 1890, in _run_once
    handle._run()
  File "/usr/local/lib/python3.9/asyncio/events.py", line 80, in _run
    self._context.run(self._callback, *self._args)
  File "/usr/src/homeassistant/homeassistant/helpers/entity_platform.py", line 510, in _async_add_entity
    entry = entity_registry.async_get_or_create(
  File "/usr/src/homeassistant/homeassistant/helpers/entity_registry.py", line 401, in async_get_or_create
    entity_category=_convert_to_entity_category(entity_category),
  File "/usr/src/homeassistant/homeassistant/helpers/entity_registry.py", line 103, in _convert_to_entity_category
    return convert_to_entity_category(value, raise_report=raise_report)
  File "/usr/src/homeassistant/homeassistant/helpers/entity.py", line 214, in convert_to_entity_category
    report(
  File "/usr/src/homeassistant/homeassistant/helpers/frame.py", line 74, in report
    _LOGGER.warning(msg, stack_info=True)
Stack (most recent call last):
  File "/usr/local/lib/python3.9/runpy.py", line 197, in _run_module_as_main
    return _run_code(code, main_globals, None,
  File "/usr/local/lib/python3.9/runpy.py", line 87, in _run_code
    exec(code, run_globals)
  File "/usr/src/homeassistant/homeassistant/__main__.py", line 203, in <module>
    sys.exit(main())
  File "/usr/src/homeassistant/homeassistant/__main__.py", line 191, in main
    exit_code = runner.run(runtime_conf)
  File "/usr/src/homeassistant/homeassistant/runner.py", line 119, in run
    return loop.run_until_complete(setup_and_run_hass(runtime_config))
  File "/usr/local/lib/python3.9/asyncio/base_events.py", line 629, in run_until_complete
    self.run_forever()
  File "/usr/local/lib/python3.9/asyncio/base_events.py", line 596, in run_forever
    self._run_once()
  File "/usr/local/lib/python3.9/asyncio/base_events.py", line 1890, in _run_once
    handle._run()
  File "/usr/local/lib/python3.9/asyncio/events.py", line 80, in _run
    self._context.run(self._callback, *self._args)
  File "/usr/src/homeassistant/homeassistant/helpers/entity_platform.py", line 510, in _async_add_entity
    entry = entity_registry.async_get_or_create(
  File "/usr/src/homeassistant/homeassistant/helpers/entity_registry.py", line 401, in async_get_or_create
    entity_category=_convert_to_entity_category(entity_category),
  File "/usr/src/homeassistant/homeassistant/helpers/entity_registry.py", line 103, in _convert_to_entity_category
    return convert_to_entity_category(value, raise_report=raise_report)
  File "/usr/src/homeassistant/homeassistant/helpers/entity.py", line 214, in convert_to_entity_category
    report(
  File "/usr/src/homeassistant/homeassistant/helpers/frame.py", line 74, in report
    _LOGGER.warning(msg, stack_info=True)
2022-02-05 20:39:38 WARNING (MainThread) [homeassistant.helpers.frame] Detected code that uses str (diagnostic) for entity category. This is deprecated and will stop working in Home Assistant 2022.4, it should be updated to use EntityCategory instead. Please report this issue.
Stack (most recent call last):
  File "/usr/local/lib/python3.9/runpy.py", line 197, in _run_module_as_main
    return _run_code(code, main_globals, None,
  File "/usr/local/lib/python3.9/runpy.py", line 87, in _run_code
    exec(code, run_globals)
  File "/usr/src/homeassistant/homeassistant/__main__.py", line 203, in <module>
    sys.exit(main())
  File "/usr/src/homeassistant/homeassistant/__main__.py", line 191, in main
    exit_code = runner.run(runtime_conf)
  File "/usr/src/homeassistant/homeassistant/runner.py", line 119, in run
    return loop.run_until_complete(setup_and_run_hass(runtime_config))
  File "/usr/local/lib/python3.9/asyncio/base_events.py", line 629, in run_until_complete
    self.run_forever()
  File "/usr/local/lib/python3.9/asyncio/base_events.py", line 596, in run_forever
    self._run_once()
  File "/usr/local/lib/python3.9/asyncio/base_events.py", line 1890, in _run_once
    handle._run()
  File "/usr/local/lib/python3.9/asyncio/events.py", line 80, in _run
    self._context.run(self._callback, *self._args)
  File "/usr/src/homeassistant/homeassistant/helpers/entity_platform.py", line 510, in _async_add_entity
    entry = entity_registry.async_get_or_create(
  File "/usr/src/homeassistant/homeassistant/helpers/entity_registry.py", line 401, in async_get_or_create
    entity_category=_convert_to_entity_category(entity_category),
  File "/usr/src/homeassistant/homeassistant/helpers/entity_registry.py", line 103, in _convert_to_entity_category
    return convert_to_entity_category(value, raise_report=raise_report)
  File "/usr/src/homeassistant/homeassistant/helpers/entity.py", line 214, in convert_to_entity_category
    report(
  File "/usr/src/homeassistant/homeassistant/helpers/frame.py", line 74, in report
    _LOGGER.warning(msg, stack_info=True)
Stack (most recent call last):
  File "/usr/local/lib/python3.9/runpy.py", line 197, in _run_module_as_main
    return _run_code(code, main_globals, None,
  File "/usr/local/lib/python3.9/runpy.py", line 87, in _run_code
    exec(code, run_globals)
  File "/usr/src/homeassistant/homeassistant/__main__.py", line 203, in <module>
    sys.exit(main())
  File "/usr/src/homeassistant/homeassistant/__main__.py", line 191, in main
    exit_code = runner.run(runtime_conf)
  File "/usr/src/homeassistant/homeassistant/runner.py", line 119, in run
    return loop.run_until_complete(setup_and_run_hass(runtime_config))
  File "/usr/local/lib/python3.9/asyncio/base_events.py", line 629, in run_until_complete
    self.run_forever()
  File "/usr/local/lib/python3.9/asyncio/base_events.py", line 596, in run_forever
    self._run_once()
  File "/usr/local/lib/python3.9/asyncio/base_events.py", line 1890, in _run_once
    handle._run()
  File "/usr/local/lib/python3.9/asyncio/events.py", line 80, in _run
    self._context.run(self._callback, *self._args)
  File "/usr/src/homeassistant/homeassistant/helpers/entity_platform.py", line 510, in _async_add_entity
    entry = entity_registry.async_get_or_create(
  File "/usr/src/homeassistant/homeassistant/helpers/entity_registry.py", line 401, in async_get_or_create
    entity_category=_convert_to_entity_category(entity_category),
  File "/usr/src/homeassistant/homeassistant/helpers/entity_registry.py", line 103, in _convert_to_entity_category
    return convert_to_entity_category(value, raise_report=raise_report)
  File "/usr/src/homeassistant/homeassistant/helpers/entity.py", line 214, in convert_to_entity_category
    report(
  File "/usr/src/homeassistant/homeassistant/helpers/frame.py", line 74, in report
    _LOGGER.warning(msg, stack_info=True)
2022-02-05 20:39:38 WARNING (MainThread) [homeassistant.helpers.frame] Detected code that uses str (diagnostic) for entity category. This is deprecated and will stop working in Home Assistant 2022.4, it should be updated to use EntityCategory instead. Please report this issue.
Stack (most recent call last):
  File "/usr/local/lib/python3.9/runpy.py", line 197, in _run_module_as_main
    return _run_code(code, main_globals, None,
  File "/usr/local/lib/python3.9/runpy.py", line 87, in _run_code
    exec(code, run_globals)
  File "/usr/src/homeassistant/homeassistant/__main__.py", line 203, in <module>
    sys.exit(main())
  File "/usr/src/homeassistant/homeassistant/__main__.py", line 191, in main
    exit_code = runner.run(runtime_conf)
  File "/usr/src/homeassistant/homeassistant/runner.py", line 119, in run
    return loop.run_until_complete(setup_and_run_hass(runtime_config))
  File "/usr/local/lib/python3.9/asyncio/base_events.py", line 629, in run_until_complete
    self.run_forever()
  File "/usr/local/lib/python3.9/asyncio/base_events.py", line 596, in run_forever
    self._run_once()
  File "/usr/local/lib/python3.9/asyncio/base_events.py", line 1890, in _run_once
    handle._run()
  File "/usr/local/lib/python3.9/asyncio/events.py", line 80, in _run
    self._context.run(self._callback, *self._args)
  File "/usr/src/homeassistant/homeassistant/helpers/entity_platform.py", line 510, in _async_add_entity
    entry = entity_registry.async_get_or_create(
  File "/usr/src/homeassistant/homeassistant/helpers/entity_registry.py", line 401, in async_get_or_create
    entity_category=_convert_to_entity_category(entity_category),
  File "/usr/src/homeassistant/homeassistant/helpers/entity_registry.py", line 103, in _convert_to_entity_category
    return convert_to_entity_category(value, raise_report=raise_report)
  File "/usr/src/homeassistant/homeassistant/helpers/entity.py", line 214, in convert_to_entity_category
    report(
  File "/usr/src/homeassistant/homeassistant/helpers/frame.py", line 74, in report
    _LOGGER.warning(msg, stack_info=True)
Stack (most recent call last):
  File "/usr/local/lib/python3.9/runpy.py", line 197, in _run_module_as_main
    return _run_code(code, main_globals, None,
  File "/usr/local/lib/python3.9/runpy.py", line 87, in _run_code
    exec(code, run_globals)
  File "/usr/src/homeassistant/homeassistant/__main__.py", line 203, in <module>
    sys.exit(main())
  File "/usr/src/homeassistant/homeassistant/__main__.py", line 191, in main
    exit_code = runner.run(runtime_conf)
  File "/usr/src/homeassistant/homeassistant/runner.py", line 119, in run
    return loop.run_until_complete(setup_and_run_hass(runtime_config))
  File "/usr/local/lib/python3.9/asyncio/base_events.py", line 629, in run_until_complete
    self.run_forever()
  File "/usr/local/lib/python3.9/asyncio/base_events.py", line 596, in run_forever
    self._run_once()
  File "/usr/local/lib/python3.9/asyncio/base_events.py", line 1890, in _run_once
    handle._run()
  File "/usr/local/lib/python3.9/asyncio/events.py", line 80, in _run
    self._context.run(self._callback, *self._args)
  File "/usr/src/homeassistant/homeassistant/helpers/entity_platform.py", line 510, in _async_add_entity
    entry = entity_registry.async_get_or_create(
  File "/usr/src/homeassistant/homeassistant/helpers/entity_registry.py", line 401, in async_get_or_create
    entity_category=_convert_to_entity_category(entity_category),
  File "/usr/src/homeassistant/homeassistant/helpers/entity_registry.py", line 103, in _convert_to_entity_category
    return convert_to_entity_category(value, raise_report=raise_report)
  File "/usr/src/homeassistant/homeassistant/helpers/entity.py", line 214, in convert_to_entity_category
    report(
  File "/usr/src/homeassistant/homeassistant/helpers/frame.py", line 74, in report
    _LOGGER.warning(msg, stack_info=True)
2022-02-05 20:39:38 WARNING (MainThread) [homeassistant.helpers.frame] Detected code that uses str (diagnostic) for entity category. This is deprecated and will stop working in Home Assistant 2022.4, it should be updated to use EntityCategory instead. Please report this issue.
Stack (most recent call last):
  File "/usr/local/lib/python3.9/runpy.py", line 197, in _run_module_as_main
    return _run_code(code, main_globals, None,
  File "/usr/local/lib/python3.9/runpy.py", line 87, in _run_code
    exec(code, run_globals)
  File "/usr/src/homeassistant/homeassistant/__main__.py", line 203, in <module>
    sys.exit(main())
  File "/usr/src/homeassistant/homeassistant/__main__.py", line 191, in main
    exit_code = runner.run(runtime_conf)
  File "/usr/src/homeassistant/homeassistant/runner.py", line 119, in run
    return loop.run_until_complete(setup_and_run_hass(runtime_config))
  File "/usr/local/lib/python3.9/asyncio/base_events.py", line 629, in run_until_complete
    self.run_forever()
  File "/usr/local/lib/python3.9/asyncio/base_events.py", line 596, in run_forever
    self._run_once()
  File "/usr/local/lib/python3.9/asyncio/base_events.py", line 1890, in _run_once
    handle._run()
  File "/usr/local/lib/python3.9/asyncio/events.py", line 80, in _run
    self._context.run(self._callback, *self._args)
  File "/usr/src/homeassistant/homeassistant/helpers/entity_platform.py", line 510, in _async_add_entity
    entry = entity_registry.async_get_or_create(
  File "/usr/src/homeassistant/homeassistant/helpers/entity_registry.py", line 401, in async_get_or_create
    entity_category=_convert_to_entity_category(entity_category),
  File "/usr/src/homeassistant/homeassistant/helpers/entity_registry.py", line 103, in _convert_to_entity_category
    return convert_to_entity_category(value, raise_report=raise_report)
  File "/usr/src/homeassistant/homeassistant/helpers/entity.py", line 214, in convert_to_entity_category
    report(
  File "/usr/src/homeassistant/homeassistant/helpers/frame.py", line 74, in report
    _LOGGER.warning(msg, stack_info=True)
Stack (most recent call last):
  File "/usr/local/lib/python3.9/runpy.py", line 197, in _run_module_as_main
    return _run_code(code, main_globals, None,
  File "/usr/local/lib/python3.9/runpy.py", line 87, in _run_code
    exec(code, run_globals)
  File "/usr/src/homeassistant/homeassistant/__main__.py", line 203, in <module>
    sys.exit(main())
  File "/usr/src/homeassistant/homeassistant/__main__.py", line 191, in main
    exit_code = runner.run(runtime_conf)
  File "/usr/src/homeassistant/homeassistant/runner.py", line 119, in run
    return loop.run_until_complete(setup_and_run_hass(runtime_config))
  File "/usr/local/lib/python3.9/asyncio/base_events.py", line 629, in run_until_complete
    self.run_forever()
  File "/usr/local/lib/python3.9/asyncio/base_events.py", line 596, in run_forever
    self._run_once()
  File "/usr/local/lib/python3.9/asyncio/base_events.py", line 1890, in _run_once
    handle._run()
  File "/usr/local/lib/python3.9/asyncio/events.py", line 80, in _run
    self._context.run(self._callback, *self._args)
  File "/usr/src/homeassistant/homeassistant/helpers/entity_platform.py", line 510, in _async_add_entity
    entry = entity_registry.async_get_or_create(
  File "/usr/src/homeassistant/homeassistant/helpers/entity_registry.py", line 401, in async_get_or_create
    entity_category=_convert_to_entity_category(entity_category),
  File "/usr/src/homeassistant/homeassistant/helpers/entity_registry.py", line 103, in _convert_to_entity_category
    return convert_to_entity_category(value, raise_report=raise_report)
  File "/usr/src/homeassistant/homeassistant/helpers/entity.py", line 214, in convert_to_entity_category
    report(
  File "/usr/src/homeassistant/homeassistant/helpers/frame.py", line 74, in report
    _LOGGER.warning(msg, stack_info=True)
2022-02-05 20:39:38 WARNING (MainThread) [homeassistant.helpers.frame] Detected code that uses str (diagnostic) for entity category. This is deprecated and will stop working in Home Assistant 2022.4, it should be updated to use EntityCategory instead. Please report this issue.
Stack (most recent call last):
  File "/usr/local/lib/python3.9/runpy.py", line 197, in _run_module_as_main
    return _run_code(code, main_globals, None,
  File "/usr/local/lib/python3.9/runpy.py", line 87, in _run_code
    exec(code, run_globals)
  File "/usr/src/homeassistant/homeassistant/__main__.py", line 203, in <module>
    sys.exit(main())
  File "/usr/src/homeassistant/homeassistant/__main__.py", line 191, in main
    exit_code = runner.run(runtime_conf)
  File "/usr/src/homeassistant/homeassistant/runner.py", line 119, in run
    return loop.run_until_complete(setup_and_run_hass(runtime_config))
  File "/usr/local/lib/python3.9/asyncio/base_events.py", line 629, in run_until_complete
    self.run_forever()
  File "/usr/local/lib/python3.9/asyncio/base_events.py", line 596, in run_forever
    self._run_once()
  File "/usr/local/lib/python3.9/asyncio/base_events.py", line 1890, in _run_once
    handle._run()
  File "/usr/local/lib/python3.9/asyncio/events.py", line 80, in _run
    self._context.run(self._callback, *self._args)
  File "/usr/src/homeassistant/homeassistant/helpers/entity_platform.py", line 510, in _async_add_entity
    entry = entity_registry.async_get_or_create(
  File "/usr/src/homeassistant/homeassistant/helpers/entity_registry.py", line 401, in async_get_or_create
    entity_category=_convert_to_entity_category(entity_category),
  File "/usr/src/homeassistant/homeassistant/helpers/entity_registry.py", line 103, in _convert_to_entity_category
    return convert_to_entity_category(value, raise_report=raise_report)
  File "/usr/src/homeassistant/homeassistant/helpers/entity.py", line 214, in convert_to_entity_category
    report(
  File "/usr/src/homeassistant/homeassistant/helpers/frame.py", line 74, in report
    _LOGGER.warning(msg, stack_info=True)
Stack (most recent call last):
  File "/usr/local/lib/python3.9/runpy.py", line 197, in _run_module_as_main
    return _run_code(code, main_globals, None,
  File "/usr/local/lib/python3.9/runpy.py", line 87, in _run_code
    exec(code, run_globals)
  File "/usr/src/homeassistant/homeassistant/__main__.py", line 203, in <module>
    sys.exit(main())
  File "/usr/src/homeassistant/homeassistant/__main__.py", line 191, in main
    exit_code = runner.run(runtime_conf)
  File "/usr/src/homeassistant/homeassistant/runner.py", line 119, in run
    return loop.run_until_complete(setup_and_run_hass(runtime_config))
  File "/usr/local/lib/python3.9/asyncio/base_events.py", line 629, in run_until_complete
    self.run_forever()
  File "/usr/local/lib/python3.9/asyncio/base_events.py", line 596, in run_forever
    self._run_once()
  File "/usr/local/lib/python3.9/asyncio/base_events.py", line 1890, in _run_once
    handle._run()
  File "/usr/local/lib/python3.9/asyncio/events.py", line 80, in _run
    self._context.run(self._callback, *self._args)
  File "/usr/src/homeassistant/homeassistant/helpers/entity_platform.py", line 510, in _async_add_entity
    entry = entity_registry.async_get_or_create(
  File "/usr/src/homeassistant/homeassistant/helpers/entity_registry.py", line 401, in async_get_or_create
    entity_category=_convert_to_entity_category(entity_category),
  File "/usr/src/homeassistant/homeassistant/helpers/entity_registry.py", line 103, in _convert_to_entity_category
    return convert_to_entity_category(value, raise_report=raise_report)
  File "/usr/src/homeassistant/homeassistant/helpers/entity.py", line 214, in convert_to_entity_category
    report(
  File "/usr/src/homeassistant/homeassistant/helpers/frame.py", line 74, in report
    _LOGGER.warning(msg, stack_info=True)
2022-02-05 20:39:38 WARNING (MainThread) [homeassistant.helpers.frame] Detected code that uses str (diagnostic) for entity category. This is deprecated and will stop working in Home Assistant 2022.4, it should be updated to use EntityCategory instead. Please report this issue.
Stack (most recent call last):
  File "/usr/local/lib/python3.9/runpy.py", line 197, in _run_module_as_main
    return _run_code(code, main_globals, None,
  File "/usr/local/lib/python3.9/runpy.py", line 87, in _run_code
    exec(code, run_globals)
  File "/usr/src/homeassistant/homeassistant/__main__.py", line 203, in <module>
    sys.exit(main())
  File "/usr/src/homeassistant/homeassistant/__main__.py", line 191, in main
    exit_code = runner.run(runtime_conf)
  File "/usr/src/homeassistant/homeassistant/runner.py", line 119, in run
    return loop.run_until_complete(setup_and_run_hass(runtime_config))
  File "/usr/local/lib/python3.9/asyncio/base_events.py", line 629, in run_until_complete
    self.run_forever()
  File "/usr/local/lib/python3.9/asyncio/base_events.py", line 596, in run_forever
    self._run_once()
  File "/usr/local/lib/python3.9/asyncio/base_events.py", line 1890, in _run_once
    handle._run()
  File "/usr/local/lib/python3.9/asyncio/events.py", line 80, in _run
    self._context.run(self._callback, *self._args)
  File "/usr/src/homeassistant/homeassistant/helpers/entity_platform.py", line 510, in _async_add_entity
    entry = entity_registry.async_get_or_create(
  File "/usr/src/homeassistant/homeassistant/helpers/entity_registry.py", line 401, in async_get_or_create
    entity_category=_convert_to_entity_category(entity_category),
  File "/usr/src/homeassistant/homeassistant/helpers/entity_registry.py", line 103, in _convert_to_entity_category
    return convert_to_entity_category(value, raise_report=raise_report)
  File "/usr/src/homeassistant/homeassistant/helpers/entity.py", line 214, in convert_to_entity_category
    report(
  File "/usr/src/homeassistant/homeassistant/helpers/frame.py", line 74, in report
    _LOGGER.warning(msg, stack_info=True)
Stack (most recent call last):
  File "/usr/local/lib/python3.9/runpy.py", line 197, in _run_module_as_main
    return _run_code(code, main_globals, None,
  File "/usr/local/lib/python3.9/runpy.py", line 87, in _run_code
    exec(code, run_globals)
  File "/usr/src/homeassistant/homeassistant/__main__.py", line 203, in <module>
    sys.exit(main())
  File "/usr/src/homeassistant/homeassistant/__main__.py", line 191, in main
    exit_code = runner.run(runtime_conf)
  File "/usr/src/homeassistant/homeassistant/runner.py", line 119, in run
    return loop.run_until_complete(setup_and_run_hass(runtime_config))
  File "/usr/local/lib/python3.9/asyncio/base_events.py", line 629, in run_until_complete
    self.run_forever()
  File "/usr/local/lib/python3.9/asyncio/base_events.py", line 596, in run_forever
    self._run_once()
  File "/usr/local/lib/python3.9/asyncio/base_events.py", line 1890, in _run_once
    handle._run()
  File "/usr/local/lib/python3.9/asyncio/events.py", line 80, in _run
    self._context.run(self._callback, *self._args)
  File "/usr/src/homeassistant/homeassistant/helpers/entity_platform.py", line 510, in _async_add_entity
    entry = entity_registry.async_get_or_create(
  File "/usr/src/homeassistant/homeassistant/helpers/entity_registry.py", line 401, in async_get_or_create
    entity_category=_convert_to_entity_category(entity_category),
  File "/usr/src/homeassistant/homeassistant/helpers/entity_registry.py", line 103, in _convert_to_entity_category
    return convert_to_entity_category(value, raise_report=raise_report)
  File "/usr/src/homeassistant/homeassistant/helpers/entity.py", line 214, in convert_to_entity_category
    report(
  File "/usr/src/homeassistant/homeassistant/helpers/frame.py", line 74, in report
    _LOGGER.warning(msg, stack_info=True)
2022-02-05 20:39:38 WARNING (MainThread) [homeassistant.helpers.frame] Detected code that uses str (diagnostic) for entity category. This is deprecated and will stop working in Home Assistant 2022.4, it should be updated to use EntityCategory instead. Please report this issue.
Stack (most recent call last):
  File "/usr/local/lib/python3.9/runpy.py", line 197, in _run_module_as_main
    return _run_code(code, main_globals, None,
  File "/usr/local/lib/python3.9/runpy.py", line 87, in _run_code
    exec(code, run_globals)
  File "/usr/src/homeassistant/homeassistant/__main__.py", line 203, in <module>
    sys.exit(main())
  File "/usr/src/homeassistant/homeassistant/__main__.py", line 191, in main
    exit_code = runner.run(runtime_conf)
  File "/usr/src/homeassistant/homeassistant/runner.py", line 119, in run
    return loop.run_until_complete(setup_and_run_hass(runtime_config))
  File "/usr/local/lib/python3.9/asyncio/base_events.py", line 629, in run_until_complete
    self.run_forever()
  File "/usr/local/lib/python3.9/asyncio/base_events.py", line 596, in run_forever
    self._run_once()
  File "/usr/local/lib/python3.9/asyncio/base_events.py", line 1890, in _run_once
    handle._run()
  File "/usr/local/lib/python3.9/asyncio/events.py", line 80, in _run
    self._context.run(self._callback, *self._args)
  File "/usr/src/homeassistant/homeassistant/helpers/entity_platform.py", line 510, in _async_add_entity
    entry = entity_registry.async_get_or_create(
  File "/usr/src/homeassistant/homeassistant/helpers/entity_registry.py", line 401, in async_get_or_create
    entity_category=_convert_to_entity_category(entity_category),
  File "/usr/src/homeassistant/homeassistant/helpers/entity_registry.py", line 103, in _convert_to_entity_category
    return convert_to_entity_category(value, raise_report=raise_report)
  File "/usr/src/homeassistant/homeassistant/helpers/entity.py", line 214, in convert_to_entity_category
    report(
  File "/usr/src/homeassistant/homeassistant/helpers/frame.py", line 74, in report
    _LOGGER.warning(msg, stack_info=True)
Stack (most recent call last):
  File "/usr/local/lib/python3.9/runpy.py", line 197, in _run_module_as_main
    return _run_code(code, main_globals, None,
  File "/usr/local/lib/python3.9/runpy.py", line 87, in _run_code
    exec(code, run_globals)
  File "/usr/src/homeassistant/homeassistant/__main__.py", line 203, in <module>
    sys.exit(main())
  File "/usr/src/homeassistant/homeassistant/__main__.py", line 191, in main
    exit_code = runner.run(runtime_conf)
  File "/usr/src/homeassistant/homeassistant/runner.py", line 119, in run
    return loop.run_until_complete(setup_and_run_hass(runtime_config))
  File "/usr/local/lib/python3.9/asyncio/base_events.py", line 629, in run_until_complete
    self.run_forever()
  File "/usr/local/lib/python3.9/asyncio/base_events.py", line 596, in run_forever
    self._run_once()
  File "/usr/local/lib/python3.9/asyncio/base_events.py", line 1890, in _run_once
    handle._run()
  File "/usr/local/lib/python3.9/asyncio/events.py", line 80, in _run
    self._context.run(self._callback, *self._args)
  File "/usr/src/homeassistant/homeassistant/helpers/entity_platform.py", line 510, in _async_add_entity
    entry = entity_registry.async_get_or_create(
  File "/usr/src/homeassistant/homeassistant/helpers/entity_registry.py", line 401, in async_get_or_create
    entity_category=_convert_to_entity_category(entity_category),
  File "/usr/src/homeassistant/homeassistant/helpers/entity_registry.py", line 103, in _convert_to_entity_category
    return convert_to_entity_category(value, raise_report=raise_report)
  File "/usr/src/homeassistant/homeassistant/helpers/entity.py", line 214, in convert_to_entity_category
    report(
  File "/usr/src/homeassistant/homeassistant/helpers/frame.py", line 74, in report
    _LOGGER.warning(msg, stack_info=True)
2022-02-05 20:39:38 WARNING (MainThread) [homeassistant.helpers.frame] Detected code that uses str (diagnostic) for entity category. This is deprecated and will stop working in Home Assistant 2022.4, it should be updated to use EntityCategory instead. Please report this issue.
Stack (most recent call last):
  File "/usr/local/lib/python3.9/runpy.py", line 197, in _run_module_as_main
    return _run_code(code, main_globals, None,
  File "/usr/local/lib/python3.9/runpy.py", line 87, in _run_code
    exec(code, run_globals)
  File "/usr/src/homeassistant/homeassistant/__main__.py", line 203, in <module>
    sys.exit(main())
  File "/usr/src/homeassistant/homeassistant/__main__.py", line 191, in main
    exit_code = runner.run(runtime_conf)
  File "/usr/src/homeassistant/homeassistant/runner.py", line 119, in run
    return loop.run_until_complete(setup_and_run_hass(runtime_config))
  File "/usr/local/lib/python3.9/asyncio/base_events.py", line 629, in run_until_complete
    self.run_forever()
  File "/usr/local/lib/python3.9/asyncio/base_events.py", line 596, in run_forever
    self._run_once()
  File "/usr/local/lib/python3.9/asyncio/base_events.py", line 1890, in _run_once
    handle._run()
  File "/usr/local/lib/python3.9/asyncio/events.py", line 80, in _run
    self._context.run(self._callback, *self._args)
  File "/usr/src/homeassistant/homeassistant/helpers/entity_platform.py", line 510, in _async_add_entity
    entry = entity_registry.async_get_or_create(
  File "/usr/src/homeassistant/homeassistant/helpers/entity_registry.py", line 401, in async_get_or_create
    entity_category=_convert_to_entity_category(entity_category),
  File "/usr/src/homeassistant/homeassistant/helpers/entity_registry.py", line 103, in _convert_to_entity_category
    return convert_to_entity_category(value, raise_report=raise_report)
  File "/usr/src/homeassistant/homeassistant/helpers/entity.py", line 214, in convert_to_entity_category
    report(
  File "/usr/src/homeassistant/homeassistant/helpers/frame.py", line 74, in report
    _LOGGER.warning(msg, stack_info=True)
Stack (most recent call last):
  File "/usr/local/lib/python3.9/runpy.py", line 197, in _run_module_as_main
    return _run_code(code, main_globals, None,
  File "/usr/local/lib/python3.9/runpy.py", line 87, in _run_code
    exec(code, run_globals)
  File "/usr/src/homeassistant/homeassistant/__main__.py", line 203, in <module>
    sys.exit(main())
  File "/usr/src/homeassistant/homeassistant/__main__.py", line 191, in main
    exit_code = runner.run(runtime_conf)
  File "/usr/src/homeassistant/homeassistant/runner.py", line 119, in run
    return loop.run_until_complete(setup_and_run_hass(runtime_config))
  File "/usr/local/lib/python3.9/asyncio/base_events.py", line 629, in run_until_complete
    self.run_forever()
  File "/usr/local/lib/python3.9/asyncio/base_events.py", line 596, in run_forever
    self._run_once()
  File "/usr/local/lib/python3.9/asyncio/base_events.py", line 1890, in _run_once
    handle._run()
  File "/usr/local/lib/python3.9/asyncio/events.py", line 80, in _run
    self._context.run(self._callback, *self._args)
  File "/usr/src/homeassistant/homeassistant/helpers/entity_platform.py", line 510, in _async_add_entity
    entry = entity_registry.async_get_or_create(
  File "/usr/src/homeassistant/homeassistant/helpers/entity_registry.py", line 401, in async_get_or_create
    entity_category=_convert_to_entity_category(entity_category),
  File "/usr/src/homeassistant/homeassistant/helpers/entity_registry.py", line 103, in _convert_to_entity_category
    return convert_to_entity_category(value, raise_report=raise_report)
  File "/usr/src/homeassistant/homeassistant/helpers/entity.py", line 214, in convert_to_entity_category
    report(
  File "/usr/src/homeassistant/homeassistant/helpers/frame.py", line 74, in report
    _LOGGER.warning(msg, stack_info=True)
2022-02-05 20:39:38 WARNING (MainThread) [homeassistant.helpers.frame] Detected code that uses str (diagnostic) for entity category. This is deprecated and will stop working in Home Assistant 2022.4, it should be updated to use EntityCategory instead. Please report this issue.
Stack (most recent call last):
  File "/usr/local/lib/python3.9/runpy.py", line 197, in _run_module_as_main
    return _run_code(code, main_globals, None,
  File "/usr/local/lib/python3.9/runpy.py", line 87, in _run_code
    exec(code, run_globals)
  File "/usr/src/homeassistant/homeassistant/__main__.py", line 203, in <module>
    sys.exit(main())
  File "/usr/src/homeassistant/homeassistant/__main__.py", line 191, in main
    exit_code = runner.run(runtime_conf)
  File "/usr/src/homeassistant/homeassistant/runner.py", line 119, in run
    return loop.run_until_complete(setup_and_run_hass(runtime_config))
  File "/usr/local/lib/python3.9/asyncio/base_events.py", line 629, in run_until_complete
    self.run_forever()
  File "/usr/local/lib/python3.9/asyncio/base_events.py", line 596, in run_forever
    self._run_once()
  File "/usr/local/lib/python3.9/asyncio/base_events.py", line 1890, in _run_once
    handle._run()
  File "/usr/local/lib/python3.9/asyncio/events.py", line 80, in _run
    self._context.run(self._callback, *self._args)
  File "/usr/src/homeassistant/homeassistant/helpers/entity_platform.py", line 510, in _async_add_entity
    entry = entity_registry.async_get_or_create(
  File "/usr/src/homeassistant/homeassistant/helpers/entity_registry.py", line 401, in async_get_or_create
    entity_category=_convert_to_entity_category(entity_category),
  File "/usr/src/homeassistant/homeassistant/helpers/entity_registry.py", line 103, in _convert_to_entity_category
    return convert_to_entity_category(value, raise_report=raise_report)
  File "/usr/src/homeassistant/homeassistant/helpers/entity.py", line 214, in convert_to_entity_category
    report(
  File "/usr/src/homeassistant/homeassistant/helpers/frame.py", line 74, in report
    _LOGGER.warning(msg, stack_info=True)
Stack (most recent call last):
  File "/usr/local/lib/python3.9/runpy.py", line 197, in _run_module_as_main
    return _run_code(code, main_globals, None,
  File "/usr/local/lib/python3.9/runpy.py", line 87, in _run_code
    exec(code, run_globals)
  File "/usr/src/homeassistant/homeassistant/__main__.py", line 203, in <module>
    sys.exit(main())
  File "/usr/src/homeassistant/homeassistant/__main__.py", line 191, in main
    exit_code = runner.run(runtime_conf)
  File "/usr/src/homeassistant/homeassistant/runner.py", line 119, in run
    return loop.run_until_complete(setup_and_run_hass(runtime_config))
  File "/usr/local/lib/python3.9/asyncio/base_events.py", line 629, in run_until_complete
    self.run_forever()
  File "/usr/local/lib/python3.9/asyncio/base_events.py", line 596, in run_forever
    self._run_once()
  File "/usr/local/lib/python3.9/asyncio/base_events.py", line 1890, in _run_once
    handle._run()
  File "/usr/local/lib/python3.9/asyncio/events.py", line 80, in _run
    self._context.run(self._callback, *self._args)
  File "/usr/src/homeassistant/homeassistant/helpers/entity_platform.py", line 510, in _async_add_entity
    entry = entity_registry.async_get_or_create(
  File "/usr/src/homeassistant/homeassistant/helpers/entity_registry.py", line 401, in async_get_or_create
    entity_category=_convert_to_entity_category(entity_category),
  File "/usr/src/homeassistant/homeassistant/helpers/entity_registry.py", line 103, in _convert_to_entity_category
    return convert_to_entity_category(value, raise_report=raise_report)
  File "/usr/src/homeassistant/homeassistant/helpers/entity.py", line 214, in convert_to_entity_category
    report(
  File "/usr/src/homeassistant/homeassistant/helpers/frame.py", line 74, in report
    _LOGGER.warning(msg, stack_info=True)
2022-02-05 20:39:38 WARNING (MainThread) [homeassistant.helpers.frame] Detected code that uses str (diagnostic) for entity category. This is deprecated and will stop working in Home Assistant 2022.4, it should be updated to use EntityCategory instead. Please report this issue.
Stack (most recent call last):
  File "/usr/local/lib/python3.9/runpy.py", line 197, in _run_module_as_main
    return _run_code(code, main_globals, None,
  File "/usr/local/lib/python3.9/runpy.py", line 87, in _run_code
    exec(code, run_globals)
  File "/usr/src/homeassistant/homeassistant/__main__.py", line 203, in <module>
    sys.exit(main())
  File "/usr/src/homeassistant/homeassistant/__main__.py", line 191, in main
    exit_code = runner.run(runtime_conf)
  File "/usr/src/homeassistant/homeassistant/runner.py", line 119, in run
    return loop.run_until_complete(setup_and_run_hass(runtime_config))
  File "/usr/local/lib/python3.9/asyncio/base_events.py", line 629, in run_until_complete
    self.run_forever()
  File "/usr/local/lib/python3.9/asyncio/base_events.py", line 596, in run_forever
    self._run_once()
  File "/usr/local/lib/python3.9/asyncio/base_events.py", line 1890, in _run_once
    handle._run()
  File "/usr/local/lib/python3.9/asyncio/events.py", line 80, in _run
    self._context.run(self._callback, *self._args)
  File "/usr/src/homeassistant/homeassistant/helpers/entity_platform.py", line 510, in _async_add_entity
    entry = entity_registry.async_get_or_create(
  File "/usr/src/homeassistant/homeassistant/helpers/entity_registry.py", line 401, in async_get_or_create
    entity_category=_convert_to_entity_category(entity_category),
  File "/usr/src/homeassistant/homeassistant/helpers/entity_registry.py", line 103, in _convert_to_entity_category
    return convert_to_entity_category(value, raise_report=raise_report)
  File "/usr/src/homeassistant/homeassistant/helpers/entity.py", line 214, in convert_to_entity_category
    report(
  File "/usr/src/homeassistant/homeassistant/helpers/frame.py", line 74, in report
    _LOGGER.warning(msg, stack_info=True)
Stack (most recent call last):
  File "/usr/local/lib/python3.9/runpy.py", line 197, in _run_module_as_main
    return _run_code(code, main_globals, None,
  File "/usr/local/lib/python3.9/runpy.py", line 87, in _run_code
    exec(code, run_globals)
  File "/usr/src/homeassistant/homeassistant/__main__.py", line 203, in <module>
    sys.exit(main())
  File "/usr/src/homeassistant/homeassistant/__main__.py", line 191, in main
    exit_code = runner.run(runtime_conf)
  File "/usr/src/homeassistant/homeassistant/runner.py", line 119, in run
    return loop.run_until_complete(setup_and_run_hass(runtime_config))
  File "/usr/local/lib/python3.9/asyncio/base_events.py", line 629, in run_until_complete
    self.run_forever()
  File "/usr/local/lib/python3.9/asyncio/base_events.py", line 596, in run_forever
    self._run_once()
  File "/usr/local/lib/python3.9/asyncio/base_events.py", line 1890, in _run_once
    handle._run()
  File "/usr/local/lib/python3.9/asyncio/events.py", line 80, in _run
    self._context.run(self._callback, *self._args)
  File "/usr/src/homeassistant/homeassistant/helpers/entity_platform.py", line 510, in _async_add_entity
    entry = entity_registry.async_get_or_create(
  File "/usr/src/homeassistant/homeassistant/helpers/entity_registry.py", line 401, in async_get_or_create
    entity_category=_convert_to_entity_category(entity_category),
  File "/usr/src/homeassistant/homeassistant/helpers/entity_registry.py", line 103, in _convert_to_entity_category
    return convert_to_entity_category(value, raise_report=raise_report)
  File "/usr/src/homeassistant/homeassistant/helpers/entity.py", line 214, in convert_to_entity_category
    report(
  File "/usr/src/homeassistant/homeassistant/helpers/frame.py", line 74, in report
    _LOGGER.warning(msg, stack_info=True)
2022-02-05 20:39:38 WARNING (MainThread) [homeassistant.helpers.frame] Detected code that uses str (diagnostic) for entity category. This is deprecated and will stop working in Home Assistant 2022.4, it should be updated to use EntityCategory instead. Please report this issue.
Stack (most recent call last):
  File "/usr/local/lib/python3.9/runpy.py", line 197, in _run_module_as_main
    return _run_code(code, main_globals, None,
  File "/usr/local/lib/python3.9/runpy.py", line 87, in _run_code
    exec(code, run_globals)
  File "/usr/src/homeassistant/homeassistant/__main__.py", line 203, in <module>
    sys.exit(main())
  File "/usr/src/homeassistant/homeassistant/__main__.py", line 191, in main
    exit_code = runner.run(runtime_conf)
  File "/usr/src/homeassistant/homeassistant/runner.py", line 119, in run
    return loop.run_until_complete(setup_and_run_hass(runtime_config))
  File "/usr/local/lib/python3.9/asyncio/base_events.py", line 629, in run_until_complete
    self.run_forever()
  File "/usr/local/lib/python3.9/asyncio/base_events.py", line 596, in run_forever
    self._run_once()
  File "/usr/local/lib/python3.9/asyncio/base_events.py", line 1890, in _run_once
    handle._run()
  File "/usr/local/lib/python3.9/asyncio/events.py", line 80, in _run
    self._context.run(self._callback, *self._args)
  File "/usr/src/homeassistant/homeassistant/helpers/entity_platform.py", line 510, in _async_add_entity
    entry = entity_registry.async_get_or_create(
  File "/usr/src/homeassistant/homeassistant/helpers/entity_registry.py", line 401, in async_get_or_create
    entity_category=_convert_to_entity_category(entity_category),
  File "/usr/src/homeassistant/homeassistant/helpers/entity_registry.py", line 103, in _convert_to_entity_category
    return convert_to_entity_category(value, raise_report=raise_report)
  File "/usr/src/homeassistant/homeassistant/helpers/entity.py", line 214, in convert_to_entity_category
    report(
  File "/usr/src/homeassistant/homeassistant/helpers/frame.py", line 74, in report
    _LOGGER.warning(msg, stack_info=True)
Stack (most recent call last):
  File "/usr/local/lib/python3.9/runpy.py", line 197, in _run_module_as_main
    return _run_code(code, main_globals, None,
  File "/usr/local/lib/python3.9/runpy.py", line 87, in _run_code
    exec(code, run_globals)
  File "/usr/src/homeassistant/homeassistant/__main__.py", line 203, in <module>
    sys.exit(main())
  File "/usr/src/homeassistant/homeassistant/__main__.py", line 191, in main
    exit_code = runner.run(runtime_conf)
  File "/usr/src/homeassistant/homeassistant/runner.py", line 119, in run
    return loop.run_until_complete(setup_and_run_hass(runtime_config))
  File "/usr/local/lib/python3.9/asyncio/base_events.py", line 629, in run_until_complete
    self.run_forever()
  File "/usr/local/lib/python3.9/asyncio/base_events.py", line 596, in run_forever
    self._run_once()
  File "/usr/local/lib/python3.9/asyncio/base_events.py", line 1890, in _run_once
    handle._run()
  File "/usr/local/lib/python3.9/asyncio/events.py", line 80, in _run
    self._context.run(self._callback, *self._args)
  File "/usr/src/homeassistant/homeassistant/helpers/entity_platform.py", line 510, in _async_add_entity
    entry = entity_registry.async_get_or_create(
  File "/usr/src/homeassistant/homeassistant/helpers/entity_registry.py", line 401, in async_get_or_create
    entity_category=_convert_to_entity_category(entity_category),
  File "/usr/src/homeassistant/homeassistant/helpers/entity_registry.py", line 103, in _convert_to_entity_category
    return convert_to_entity_category(value, raise_report=raise_report)
  File "/usr/src/homeassistant/homeassistant/helpers/entity.py", line 214, in convert_to_entity_category
    report(
  File "/usr/src/homeassistant/homeassistant/helpers/frame.py", line 74, in report
    _LOGGER.warning(msg, stack_info=True)
2022-02-05 20:39:38 WARNING (MainThread) [homeassistant.helpers.frame] Detected code that uses str (diagnostic) for entity category. This is deprecated and will stop working in Home Assistant 2022.4, it should be updated to use EntityCategory instead. Please report this issue.
Stack (most recent call last):
  File "/usr/local/lib/python3.9/runpy.py", line 197, in _run_module_as_main
    return _run_code(code, main_globals, None,
  File "/usr/local/lib/python3.9/runpy.py", line 87, in _run_code
    exec(code, run_globals)
  File "/usr/src/homeassistant/homeassistant/__main__.py", line 203, in <module>
    sys.exit(main())
  File "/usr/src/homeassistant/homeassistant/__main__.py", line 191, in main
    exit_code = runner.run(runtime_conf)
  File "/usr/src/homeassistant/homeassistant/runner.py", line 119, in run
    return loop.run_until_complete(setup_and_run_hass(runtime_config))
  File "/usr/local/lib/python3.9/asyncio/base_events.py", line 629, in run_until_complete
    self.run_forever()
  File "/usr/local/lib/python3.9/asyncio/base_events.py", line 596, in run_forever
    self._run_once()
  File "/usr/local/lib/python3.9/asyncio/base_events.py", line 1890, in _run_once
    handle._run()
  File "/usr/local/lib/python3.9/asyncio/events.py", line 80, in _run
    self._context.run(self._callback, *self._args)
  File "/usr/src/homeassistant/homeassistant/helpers/entity_platform.py", line 510, in _async_add_entity
    entry = entity_registry.async_get_or_create(
  File "/usr/src/homeassistant/homeassistant/helpers/entity_registry.py", line 401, in async_get_or_create
    entity_category=_convert_to_entity_category(entity_category),
  File "/usr/src/homeassistant/homeassistant/helpers/entity_registry.py", line 103, in _convert_to_entity_category
    return convert_to_entity_category(value, raise_report=raise_report)
  File "/usr/src/homeassistant/homeassistant/helpers/entity.py", line 214, in convert_to_entity_category
    report(
  File "/usr/src/homeassistant/homeassistant/helpers/frame.py", line 74, in report
    _LOGGER.warning(msg, stack_info=True)
Stack (most recent call last):
  File "/usr/local/lib/python3.9/runpy.py", line 197, in _run_module_as_main
    return _run_code(code, main_globals, None,
  File "/usr/local/lib/python3.9/runpy.py", line 87, in _run_code
    exec(code, run_globals)
  File "/usr/src/homeassistant/homeassistant/__main__.py", line 203, in <module>
    sys.exit(main())
  File "/usr/src/homeassistant/homeassistant/__main__.py", line 191, in main
    exit_code = runner.run(runtime_conf)
  File "/usr/src/homeassistant/homeassistant/runner.py", line 119, in run
    return loop.run_until_complete(setup_and_run_hass(runtime_config))
  File "/usr/local/lib/python3.9/asyncio/base_events.py", line 629, in run_until_complete
    self.run_forever()
  File "/usr/local/lib/python3.9/asyncio/base_events.py", line 596, in run_forever
    self._run_once()
  File "/usr/local/lib/python3.9/asyncio/base_events.py", line 1890, in _run_once
    handle._run()
  File "/usr/local/lib/python3.9/asyncio/events.py", line 80, in _run
    self._context.run(self._callback, *self._args)
  File "/usr/src/homeassistant/homeassistant/helpers/entity_platform.py", line 510, in _async_add_entity
    entry = entity_registry.async_get_or_create(
  File "/usr/src/homeassistant/homeassistant/helpers/entity_registry.py", line 401, in async_get_or_create
    entity_category=_convert_to_entity_category(entity_category),
  File "/usr/src/homeassistant/homeassistant/helpers/entity_registry.py", line 103, in _convert_to_entity_category
    return convert_to_entity_category(value, raise_report=raise_report)
  File "/usr/src/homeassistant/homeassistant/helpers/entity.py", line 214, in convert_to_entity_category
    report(
  File "/usr/src/homeassistant/homeassistant/helpers/frame.py", line 74, in report
    _LOGGER.warning(msg, stack_info=True)
2022-02-05 20:39:38 WARNING (MainThread) [homeassistant.helpers.frame] Detected code that uses str (diagnostic) for entity category. This is deprecated and will stop working in Home Assistant 2022.4, it should be updated to use EntityCategory instead. Please report this issue.
Stack (most recent call last):
  File "/usr/local/lib/python3.9/runpy.py", line 197, in _run_module_as_main
    return _run_code(code, main_globals, None,
  File "/usr/local/lib/python3.9/runpy.py", line 87, in _run_code
    exec(code, run_globals)
  File "/usr/src/homeassistant/homeassistant/__main__.py", line 203, in <module>
    sys.exit(main())
  File "/usr/src/homeassistant/homeassistant/__main__.py", line 191, in main
    exit_code = runner.run(runtime_conf)
  File "/usr/src/homeassistant/homeassistant/runner.py", line 119, in run
    return loop.run_until_complete(setup_and_run_hass(runtime_config))
  File "/usr/local/lib/python3.9/asyncio/base_events.py", line 629, in run_until_complete
    self.run_forever()
  File "/usr/local/lib/python3.9/asyncio/base_events.py", line 596, in run_forever
    self._run_once()
  File "/usr/local/lib/python3.9/asyncio/base_events.py", line 1890, in _run_once
    handle._run()
  File "/usr/local/lib/python3.9/asyncio/events.py", line 80, in _run
    self._context.run(self._callback, *self._args)
  File "/usr/src/homeassistant/homeassistant/helpers/entity_platform.py", line 510, in _async_add_entity
    entry = entity_registry.async_get_or_create(
  File "/usr/src/homeassistant/homeassistant/helpers/entity_registry.py", line 401, in async_get_or_create
    entity_category=_convert_to_entity_category(entity_category),
  File "/usr/src/homeassistant/homeassistant/helpers/entity_registry.py", line 103, in _convert_to_entity_category
    return convert_to_entity_category(value, raise_report=raise_report)
  File "/usr/src/homeassistant/homeassistant/helpers/entity.py", line 214, in convert_to_entity_category
    report(
  File "/usr/src/homeassistant/homeassistant/helpers/frame.py", line 74, in report
    _LOGGER.warning(msg, stack_info=True)
Stack (most recent call last):
  File "/usr/local/lib/python3.9/runpy.py", line 197, in _run_module_as_main
    return _run_code(code, main_globals, None,
  File "/usr/local/lib/python3.9/runpy.py", line 87, in _run_code
    exec(code, run_globals)
  File "/usr/src/homeassistant/homeassistant/__main__.py", line 203, in <module>
    sys.exit(main())
  File "/usr/src/homeassistant/homeassistant/__main__.py", line 191, in main
    exit_code = runner.run(runtime_conf)
  File "/usr/src/homeassistant/homeassistant/runner.py", line 119, in run
    return loop.run_until_complete(setup_and_run_hass(runtime_config))
  File "/usr/local/lib/python3.9/asyncio/base_events.py", line 629, in run_until_complete
    self.run_forever()
  File "/usr/local/lib/python3.9/asyncio/base_events.py", line 596, in run_forever
    self._run_once()
  File "/usr/local/lib/python3.9/asyncio/base_events.py", line 1890, in _run_once
    handle._run()
  File "/usr/local/lib/python3.9/asyncio/events.py", line 80, in _run
    self._context.run(self._callback, *self._args)
  File "/usr/src/homeassistant/homeassistant/helpers/entity_platform.py", line 510, in _async_add_entity
    entry = entity_registry.async_get_or_create(
  File "/usr/src/homeassistant/homeassistant/helpers/entity_registry.py", line 401, in async_get_or_create
    entity_category=_convert_to_entity_category(entity_category),
  File "/usr/src/homeassistant/homeassistant/helpers/entity_registry.py", line 103, in _convert_to_entity_category
    return convert_to_entity_category(value, raise_report=raise_report)
  File "/usr/src/homeassistant/homeassistant/helpers/entity.py", line 214, in convert_to_entity_category
    report(
  File "/usr/src/homeassistant/homeassistant/helpers/frame.py", line 74, in report
    _LOGGER.warning(msg, stack_info=True)
2022-02-05 20:39:38 WARNING (MainThread) [homeassistant.helpers.frame] Detected code that uses str (diagnostic) for entity category. This is deprecated and will stop working in Home Assistant 2022.4, it should be updated to use EntityCategory instead. Please report this issue.
Stack (most recent call last):
  File "/usr/local/lib/python3.9/runpy.py", line 197, in _run_module_as_main
    return _run_code(code, main_globals, None,
  File "/usr/local/lib/python3.9/runpy.py", line 87, in _run_code
    exec(code, run_globals)
  File "/usr/src/homeassistant/homeassistant/__main__.py", line 203, in <module>
    sys.exit(main())
  File "/usr/src/homeassistant/homeassistant/__main__.py", line 191, in main
    exit_code = runner.run(runtime_conf)
  File "/usr/src/homeassistant/homeassistant/runner.py", line 119, in run
    return loop.run_until_complete(setup_and_run_hass(runtime_config))
  File "/usr/local/lib/python3.9/asyncio/base_events.py", line 629, in run_until_complete
    self.run_forever()
  File "/usr/local/lib/python3.9/asyncio/base_events.py", line 596, in run_forever
    self._run_once()
  File "/usr/local/lib/python3.9/asyncio/base_events.py", line 1890, in _run_once
    handle._run()
  File "/usr/local/lib/python3.9/asyncio/events.py", line 80, in _run
    self._context.run(self._callback, *self._args)
  File "/usr/src/homeassistant/homeassistant/helpers/entity_platform.py", line 510, in _async_add_entity
    entry = entity_registry.async_get_or_create(
  File "/usr/src/homeassistant/homeassistant/helpers/entity_registry.py", line 401, in async_get_or_create
    entity_category=_convert_to_entity_category(entity_category),
  File "/usr/src/homeassistant/homeassistant/helpers/entity_registry.py", line 103, in _convert_to_entity_category
    return convert_to_entity_category(value, raise_report=raise_report)
  File "/usr/src/homeassistant/homeassistant/helpers/entity.py", line 214, in convert_to_entity_category
    report(
  File "/usr/src/homeassistant/homeassistant/helpers/frame.py", line 74, in report
    _LOGGER.warning(msg, stack_info=True)
Stack (most recent call last):
  File "/usr/local/lib/python3.9/runpy.py", line 197, in _run_module_as_main
    return _run_code(code, main_globals, None,
  File "/usr/local/lib/python3.9/runpy.py", line 87, in _run_code
    exec(code, run_globals)
  File "/usr/src/homeassistant/homeassistant/__main__.py", line 203, in <module>
    sys.exit(main())
  File "/usr/src/homeassistant/homeassistant/__main__.py", line 191, in main
    exit_code = runner.run(runtime_conf)
  File "/usr/src/homeassistant/homeassistant/runner.py", line 119, in run
    return loop.run_until_complete(setup_and_run_hass(runtime_config))
  File "/usr/local/lib/python3.9/asyncio/base_events.py", line 629, in run_until_complete
    self.run_forever()
  File "/usr/local/lib/python3.9/asyncio/base_events.py", line 596, in run_forever
    self._run_once()
  File "/usr/local/lib/python3.9/asyncio/base_events.py", line 1890, in _run_once
    handle._run()
  File "/usr/local/lib/python3.9/asyncio/events.py", line 80, in _run
    self._context.run(self._callback, *self._args)
  File "/usr/src/homeassistant/homeassistant/helpers/entity_platform.py", line 510, in _async_add_entity
    entry = entity_registry.async_get_or_create(
  File "/usr/src/homeassistant/homeassistant/helpers/entity_registry.py", line 401, in async_get_or_create
    entity_category=_convert_to_entity_category(entity_category),
  File "/usr/src/homeassistant/homeassistant/helpers/entity_registry.py", line 103, in _convert_to_entity_category
    return convert_to_entity_category(value, raise_report=raise_report)
  File "/usr/src/homeassistant/homeassistant/helpers/entity.py", line 214, in convert_to_entity_category
    report(
  File "/usr/src/homeassistant/homeassistant/helpers/frame.py", line 74, in report
    _LOGGER.warning(msg, stack_info=True)
2022-02-05 20:39:38 WARNING (MainThread) [homeassistant.helpers.frame] Detected code that uses str (diagnostic) for entity category. This is deprecated and will stop working in Home Assistant 2022.4, it should be updated to use EntityCategory instead. Please report this issue.
Stack (most recent call last):
  File "/usr/local/lib/python3.9/runpy.py", line 197, in _run_module_as_main
    return _run_code(code, main_globals, None,
  File "/usr/local/lib/python3.9/runpy.py", line 87, in _run_code
    exec(code, run_globals)
  File "/usr/src/homeassistant/homeassistant/__main__.py", line 203, in <module>
    sys.exit(main())
  File "/usr/src/homeassistant/homeassistant/__main__.py", line 191, in main
    exit_code = runner.run(runtime_conf)
  File "/usr/src/homeassistant/homeassistant/runner.py", line 119, in run
    return loop.run_until_complete(setup_and_run_hass(runtime_config))
  File "/usr/local/lib/python3.9/asyncio/base_events.py", line 629, in run_until_complete
    self.run_forever()
  File "/usr/local/lib/python3.9/asyncio/base_events.py", line 596, in run_forever
    self._run_once()
  File "/usr/local/lib/python3.9/asyncio/base_events.py", line 1890, in _run_once
    handle._run()
  File "/usr/local/lib/python3.9/asyncio/events.py", line 80, in _run
    self._context.run(self._callback, *self._args)
  File "/usr/src/homeassistant/homeassistant/helpers/entity_platform.py", line 510, in _async_add_entity
    entry = entity_registry.async_get_or_create(
  File "/usr/src/homeassistant/homeassistant/helpers/entity_registry.py", line 401, in async_get_or_create
    entity_category=_convert_to_entity_category(entity_category),
  File "/usr/src/homeassistant/homeassistant/helpers/entity_registry.py", line 103, in _convert_to_entity_category
    return convert_to_entity_category(value, raise_report=raise_report)
  File "/usr/src/homeassistant/homeassistant/helpers/entity.py", line 214, in convert_to_entity_category
    report(
  File "/usr/src/homeassistant/homeassistant/helpers/frame.py", line 74, in report
    _LOGGER.warning(msg, stack_info=True)
Stack (most recent call last):
  File "/usr/local/lib/python3.9/runpy.py", line 197, in _run_module_as_main
    return _run_code(code, main_globals, None,
  File "/usr/local/lib/python3.9/runpy.py", line 87, in _run_code
    exec(code, run_globals)
  File "/usr/src/homeassistant/homeassistant/__main__.py", line 203, in <module>
    sys.exit(main())
  File "/usr/src/homeassistant/homeassistant/__main__.py", line 191, in main
    exit_code = runner.run(runtime_conf)
  File "/usr/src/homeassistant/homeassistant/runner.py", line 119, in run
    return loop.run_until_complete(setup_and_run_hass(runtime_config))
  File "/usr/local/lib/python3.9/asyncio/base_events.py", line 629, in run_until_complete
    self.run_forever()
  File "/usr/local/lib/python3.9/asyncio/base_events.py", line 596, in run_forever
    self._run_once()
  File "/usr/local/lib/python3.9/asyncio/base_events.py", line 1890, in _run_once
    handle._run()
  File "/usr/local/lib/python3.9/asyncio/events.py", line 80, in _run
    self._context.run(self._callback, *self._args)
  File "/usr/src/homeassistant/homeassistant/helpers/entity_platform.py", line 510, in _async_add_entity
    entry = entity_registry.async_get_or_create(
  File "/usr/src/homeassistant/homeassistant/helpers/entity_registry.py", line 401, in async_get_or_create
    entity_category=_convert_to_entity_category(entity_category),
  File "/usr/src/homeassistant/homeassistant/helpers/entity_registry.py", line 103, in _convert_to_entity_category
    return convert_to_entity_category(value, raise_report=raise_report)
  File "/usr/src/homeassistant/homeassistant/helpers/entity.py", line 214, in convert_to_entity_category
    report(
  File "/usr/src/homeassistant/homeassistant/helpers/frame.py", line 74, in report
    _LOGGER.warning(msg, stack_info=True)
2022-02-05 20:39:38 WARNING (MainThread) [homeassistant.helpers.frame] Detected code that uses str (diagnostic) for entity category. This is deprecated and will stop working in Home Assistant 2022.4, it should be updated to use EntityCategory instead. Please report this issue.
Stack (most recent call last):
  File "/usr/local/lib/python3.9/runpy.py", line 197, in _run_module_as_main
    return _run_code(code, main_globals, None,
  File "/usr/local/lib/python3.9/runpy.py", line 87, in _run_code
    exec(code, run_globals)
  File "/usr/src/homeassistant/homeassistant/__main__.py", line 203, in <module>
    sys.exit(main())
  File "/usr/src/homeassistant/homeassistant/__main__.py", line 191, in main
    exit_code = runner.run(runtime_conf)
  File "/usr/src/homeassistant/homeassistant/runner.py", line 119, in run
    return loop.run_until_complete(setup_and_run_hass(runtime_config))
  File "/usr/local/lib/python3.9/asyncio/base_events.py", line 629, in run_until_complete
    self.run_forever()
  File "/usr/local/lib/python3.9/asyncio/base_events.py", line 596, in run_forever
    self._run_once()
  File "/usr/local/lib/python3.9/asyncio/base_events.py", line 1890, in _run_once
    handle._run()
  File "/usr/local/lib/python3.9/asyncio/events.py", line 80, in _run
    self._context.run(self._callback, *self._args)
  File "/usr/src/homeassistant/homeassistant/helpers/entity_platform.py", line 510, in _async_add_entity
    entry = entity_registry.async_get_or_create(
  File "/usr/src/homeassistant/homeassistant/helpers/entity_registry.py", line 401, in async_get_or_create
    entity_category=_convert_to_entity_category(entity_category),
  File "/usr/src/homeassistant/homeassistant/helpers/entity_registry.py", line 103, in _convert_to_entity_category
    return convert_to_entity_category(value, raise_report=raise_report)
  File "/usr/src/homeassistant/homeassistant/helpers/entity.py", line 214, in convert_to_entity_category
    report(
  File "/usr/src/homeassistant/homeassistant/helpers/frame.py", line 74, in report
    _LOGGER.warning(msg, stack_info=True)
Stack (most recent call last):
  File "/usr/local/lib/python3.9/runpy.py", line 197, in _run_module_as_main
    return _run_code(code, main_globals, None,
  File "/usr/local/lib/python3.9/runpy.py", line 87, in _run_code
    exec(code, run_globals)
  File "/usr/src/homeassistant/homeassistant/__main__.py", line 203, in <module>
    sys.exit(main())
  File "/usr/src/homeassistant/homeassistant/__main__.py", line 191, in main
    exit_code = runner.run(runtime_conf)
  File "/usr/src/homeassistant/homeassistant/runner.py", line 119, in run
    return loop.run_until_complete(setup_and_run_hass(runtime_config))
  File "/usr/local/lib/python3.9/asyncio/base_events.py", line 629, in run_until_complete
    self.run_forever()
  File "/usr/local/lib/python3.9/asyncio/base_events.py", line 596, in run_forever
    self._run_once()
  File "/usr/local/lib/python3.9/asyncio/base_events.py", line 1890, in _run_once
    handle._run()
  File "/usr/local/lib/python3.9/asyncio/events.py", line 80, in _run
    self._context.run(self._callback, *self._args)
  File "/usr/src/homeassistant/homeassistant/helpers/entity_platform.py", line 510, in _async_add_entity
    entry = entity_registry.async_get_or_create(
  File "/usr/src/homeassistant/homeassistant/helpers/entity_registry.py", line 401, in async_get_or_create
    entity_category=_convert_to_entity_category(entity_category),
  File "/usr/src/homeassistant/homeassistant/helpers/entity_registry.py", line 103, in _convert_to_entity_category
    return convert_to_entity_category(value, raise_report=raise_report)
  File "/usr/src/homeassistant/homeassistant/helpers/entity.py", line 214, in convert_to_entity_category
    report(
  File "/usr/src/homeassistant/homeassistant/helpers/frame.py", line 74, in report
    _LOGGER.warning(msg, stack_info=True)
2022-02-05 20:39:38 WARNING (MainThread) [homeassistant.helpers.frame] Detected code that uses str (diagnostic) for entity category. This is deprecated and will stop working in Home Assistant 2022.4, it should be updated to use EntityCategory instead. Please report this issue.
Stack (most recent call last):
  File "/usr/local/lib/python3.9/runpy.py", line 197, in _run_module_as_main
    return _run_code(code, main_globals, None,
  File "/usr/local/lib/python3.9/runpy.py", line 87, in _run_code
    exec(code, run_globals)
  File "/usr/src/homeassistant/homeassistant/__main__.py", line 203, in <module>
    sys.exit(main())
  File "/usr/src/homeassistant/homeassistant/__main__.py", line 191, in main
    exit_code = runner.run(runtime_conf)
  File "/usr/src/homeassistant/homeassistant/runner.py", line 119, in run
    return loop.run_until_complete(setup_and_run_hass(runtime_config))
  File "/usr/local/lib/python3.9/asyncio/base_events.py", line 629, in run_until_complete
    self.run_forever()
  File "/usr/local/lib/python3.9/asyncio/base_events.py", line 596, in run_forever
    self._run_once()
  File "/usr/local/lib/python3.9/asyncio/base_events.py", line 1890, in _run_once
    handle._run()
  File "/usr/local/lib/python3.9/asyncio/events.py", line 80, in _run
    self._context.run(self._callback, *self._args)
  File "/usr/src/homeassistant/homeassistant/helpers/entity_platform.py", line 510, in _async_add_entity
    entry = entity_registry.async_get_or_create(
  File "/usr/src/homeassistant/homeassistant/helpers/entity_registry.py", line 401, in async_get_or_create
    entity_category=_convert_to_entity_category(entity_category),
  File "/usr/src/homeassistant/homeassistant/helpers/entity_registry.py", line 103, in _convert_to_entity_category
    return convert_to_entity_category(value, raise_report=raise_report)
  File "/usr/src/homeassistant/homeassistant/helpers/entity.py", line 214, in convert_to_entity_category
    report(
  File "/usr/src/homeassistant/homeassistant/helpers/frame.py", line 74, in report
    _LOGGER.warning(msg, stack_info=True)
Stack (most recent call last):
  File "/usr/local/lib/python3.9/runpy.py", line 197, in _run_module_as_main
    return _run_code(code, main_globals, None,
  File "/usr/local/lib/python3.9/runpy.py", line 87, in _run_code
    exec(code, run_globals)
  File "/usr/src/homeassistant/homeassistant/__main__.py", line 203, in <module>
    sys.exit(main())
  File "/usr/src/homeassistant/homeassistant/__main__.py", line 191, in main
    exit_code = runner.run(runtime_conf)
  File "/usr/src/homeassistant/homeassistant/runner.py", line 119, in run
    return loop.run_until_complete(setup_and_run_hass(runtime_config))
  File "/usr/local/lib/python3.9/asyncio/base_events.py", line 629, in run_until_complete
    self.run_forever()
  File "/usr/local/lib/python3.9/asyncio/base_events.py", line 596, in run_forever
    self._run_once()
  File "/usr/local/lib/python3.9/asyncio/base_events.py", line 1890, in _run_once
    handle._run()
  File "/usr/local/lib/python3.9/asyncio/events.py", line 80, in _run
    self._context.run(self._callback, *self._args)
  File "/usr/src/homeassistant/homeassistant/helpers/entity_platform.py", line 510, in _async_add_entity
    entry = entity_registry.async_get_or_create(
  File "/usr/src/homeassistant/homeassistant/helpers/entity_registry.py", line 401, in async_get_or_create
    entity_category=_convert_to_entity_category(entity_category),
  File "/usr/src/homeassistant/homeassistant/helpers/entity_registry.py", line 103, in _convert_to_entity_category
    return convert_to_entity_category(value, raise_report=raise_report)
  File "/usr/src/homeassistant/homeassistant/helpers/entity.py", line 214, in convert_to_entity_category
    report(
  File "/usr/src/homeassistant/homeassistant/helpers/frame.py", line 74, in report
    _LOGGER.warning(msg, stack_info=True)
2022-02-05 20:39:38 WARNING (MainThread) [homeassistant.helpers.frame] Detected code that uses str (diagnostic) for entity category. This is deprecated and will stop working in Home Assistant 2022.4, it should be updated to use EntityCategory instead. Please report this issue.
Stack (most recent call last):
  File "/usr/local/lib/python3.9/runpy.py", line 197, in _run_module_as_main
    return _run_code(code, main_globals, None,
  File "/usr/local/lib/python3.9/runpy.py", line 87, in _run_code
    exec(code, run_globals)
  File "/usr/src/homeassistant/homeassistant/__main__.py", line 203, in <module>
    sys.exit(main())
  File "/usr/src/homeassistant/homeassistant/__main__.py", line 191, in main
    exit_code = runner.run(runtime_conf)
  File "/usr/src/homeassistant/homeassistant/runner.py", line 119, in run
    return loop.run_until_complete(setup_and_run_hass(runtime_config))
  File "/usr/local/lib/python3.9/asyncio/base_events.py", line 629, in run_until_complete
    self.run_forever()
  File "/usr/local/lib/python3.9/asyncio/base_events.py", line 596, in run_forever
    self._run_once()
  File "/usr/local/lib/python3.9/asyncio/base_events.py", line 1890, in _run_once
    handle._run()
  File "/usr/local/lib/python3.9/asyncio/events.py", line 80, in _run
    self._context.run(self._callback, *self._args)
  File "/usr/src/homeassistant/homeassistant/helpers/entity_platform.py", line 510, in _async_add_entity
    entry = entity_registry.async_get_or_create(
  File "/usr/src/homeassistant/homeassistant/helpers/entity_registry.py", line 401, in async_get_or_create
    entity_category=_convert_to_entity_category(entity_category),
  File "/usr/src/homeassistant/homeassistant/helpers/entity_registry.py", line 103, in _convert_to_entity_category
    return convert_to_entity_category(value, raise_report=raise_report)
  File "/usr/src/homeassistant/homeassistant/helpers/entity.py", line 214, in convert_to_entity_category
    report(
  File "/usr/src/homeassistant/homeassistant/helpers/frame.py", line 74, in report
    _LOGGER.warning(msg, stack_info=True)
Stack (most recent call last):
  File "/usr/local/lib/python3.9/runpy.py", line 197, in _run_module_as_main
    return _run_code(code, main_globals, None,
  File "/usr/local/lib/python3.9/runpy.py", line 87, in _run_code
    exec(code, run_globals)
  File "/usr/src/homeassistant/homeassistant/__main__.py", line 203, in <module>
    sys.exit(main())
  File "/usr/src/homeassistant/homeassistant/__main__.py", line 191, in main
    exit_code = runner.run(runtime_conf)
  File "/usr/src/homeassistant/homeassistant/runner.py", line 119, in run
    return loop.run_until_complete(setup_and_run_hass(runtime_config))
  File "/usr/local/lib/python3.9/asyncio/base_events.py", line 629, in run_until_complete
    self.run_forever()
  File "/usr/local/lib/python3.9/asyncio/base_events.py", line 596, in run_forever
    self._run_once()
  File "/usr/local/lib/python3.9/asyncio/base_events.py", line 1890, in _run_once
    handle._run()
  File "/usr/local/lib/python3.9/asyncio/events.py", line 80, in _run
    self._context.run(self._callback, *self._args)
  File "/usr/src/homeassistant/homeassistant/helpers/entity_platform.py", line 510, in _async_add_entity
    entry = entity_registry.async_get_or_create(
  File "/usr/src/homeassistant/homeassistant/helpers/entity_registry.py", line 401, in async_get_or_create
    entity_category=_convert_to_entity_category(entity_category),
  File "/usr/src/homeassistant/homeassistant/helpers/entity_registry.py", line 103, in _convert_to_entity_category
    return convert_to_entity_category(value, raise_report=raise_report)
  File "/usr/src/homeassistant/homeassistant/helpers/entity.py", line 214, in convert_to_entity_category
    report(
  File "/usr/src/homeassistant/homeassistant/helpers/frame.py", line 74, in report
    _LOGGER.warning(msg, stack_info=True)
2022-02-05 20:39:38 WARNING (MainThread) [homeassistant.helpers.frame] Detected code that uses str (diagnostic) for entity category. This is deprecated and will stop working in Home Assistant 2022.4, it should be updated to use EntityCategory instead. Please report this issue.
Stack (most recent call last):
  File "/usr/local/lib/python3.9/runpy.py", line 197, in _run_module_as_main
    return _run_code(code, main_globals, None,
  File "/usr/local/lib/python3.9/runpy.py", line 87, in _run_code
    exec(code, run_globals)
  File "/usr/src/homeassistant/homeassistant/__main__.py", line 203, in <module>
    sys.exit(main())
  File "/usr/src/homeassistant/homeassistant/__main__.py", line 191, in main
    exit_code = runner.run(runtime_conf)
  File "/usr/src/homeassistant/homeassistant/runner.py", line 119, in run
    return loop.run_until_complete(setup_and_run_hass(runtime_config))
  File "/usr/local/lib/python3.9/asyncio/base_events.py", line 629, in run_until_complete
    self.run_forever()
  File "/usr/local/lib/python3.9/asyncio/base_events.py", line 596, in run_forever
    self._run_once()
  File "/usr/local/lib/python3.9/asyncio/base_events.py", line 1890, in _run_once
    handle._run()
  File "/usr/local/lib/python3.9/asyncio/events.py", line 80, in _run
    self._context.run(self._callback, *self._args)
  File "/usr/src/homeassistant/homeassistant/helpers/entity_platform.py", line 510, in _async_add_entity
    entry = entity_registry.async_get_or_create(
  File "/usr/src/homeassistant/homeassistant/helpers/entity_registry.py", line 401, in async_get_or_create
    entity_category=_convert_to_entity_category(entity_category),
  File "/usr/src/homeassistant/homeassistant/helpers/entity_registry.py", line 103, in _convert_to_entity_category
    return convert_to_entity_category(value, raise_report=raise_report)
  File "/usr/src/homeassistant/homeassistant/helpers/entity.py", line 214, in convert_to_entity_category
    report(
  File "/usr/src/homeassistant/homeassistant/helpers/frame.py", line 74, in report
    _LOGGER.warning(msg, stack_info=True)
Stack (most recent call last):
  File "/usr/local/lib/python3.9/runpy.py", line 197, in _run_module_as_main
    return _run_code(code, main_globals, None,
  File "/usr/local/lib/python3.9/runpy.py", line 87, in _run_code
    exec(code, run_globals)
  File "/usr/src/homeassistant/homeassistant/__main__.py", line 203, in <module>
    sys.exit(main())
  File "/usr/src/homeassistant/homeassistant/__main__.py", line 191, in main
    exit_code = runner.run(runtime_conf)
  File "/usr/src/homeassistant/homeassistant/runner.py", line 119, in run
    return loop.run_until_complete(setup_and_run_hass(runtime_config))
  File "/usr/local/lib/python3.9/asyncio/base_events.py", line 629, in run_until_complete
    self.run_forever()
  File "/usr/local/lib/python3.9/asyncio/base_events.py", line 596, in run_forever
    self._run_once()
  File "/usr/local/lib/python3.9/asyncio/base_events.py", line 1890, in _run_once
    handle._run()
  File "/usr/local/lib/python3.9/asyncio/events.py", line 80, in _run
    self._context.run(self._callback, *self._args)
  File "/usr/src/homeassistant/homeassistant/helpers/entity_platform.py", line 510, in _async_add_entity
    entry = entity_registry.async_get_or_create(
  File "/usr/src/homeassistant/homeassistant/helpers/entity_registry.py", line 401, in async_get_or_create
    entity_category=_convert_to_entity_category(entity_category),
  File "/usr/src/homeassistant/homeassistant/helpers/entity_registry.py", line 103, in _convert_to_entity_category
    return convert_to_entity_category(value, raise_report=raise_report)
  File "/usr/src/homeassistant/homeassistant/helpers/entity.py", line 214, in convert_to_entity_category
    report(
  File "/usr/src/homeassistant/homeassistant/helpers/frame.py", line 74, in report
    _LOGGER.warning(msg, stack_info=True)
2022-02-05 20:39:38 WARNING (MainThread) [homeassistant.helpers.frame] Detected code that uses str (diagnostic) for entity category. This is deprecated and will stop working in Home Assistant 2022.4, it should be updated to use EntityCategory instead. Please report this issue.
Stack (most recent call last):
  File "/usr/local/lib/python3.9/runpy.py", line 197, in _run_module_as_main
    return _run_code(code, main_globals, None,
  File "/usr/local/lib/python3.9/runpy.py", line 87, in _run_code
    exec(code, run_globals)
  File "/usr/src/homeassistant/homeassistant/__main__.py", line 203, in <module>
    sys.exit(main())
  File "/usr/src/homeassistant/homeassistant/__main__.py", line 191, in main
    exit_code = runner.run(runtime_conf)
  File "/usr/src/homeassistant/homeassistant/runner.py", line 119, in run
    return loop.run_until_complete(setup_and_run_hass(runtime_config))
  File "/usr/local/lib/python3.9/asyncio/base_events.py", line 629, in run_until_complete
    self.run_forever()
  File "/usr/local/lib/python3.9/asyncio/base_events.py", line 596, in run_forever
    self._run_once()
  File "/usr/local/lib/python3.9/asyncio/base_events.py", line 1890, in _run_once
    handle._run()
  File "/usr/local/lib/python3.9/asyncio/events.py", line 80, in _run
    self._context.run(self._callback, *self._args)
  File "/usr/src/homeassistant/homeassistant/helpers/entity_platform.py", line 510, in _async_add_entity
    entry = entity_registry.async_get_or_create(
  File "/usr/src/homeassistant/homeassistant/helpers/entity_registry.py", line 401, in async_get_or_create
    entity_category=_convert_to_entity_category(entity_category),
  File "/usr/src/homeassistant/homeassistant/helpers/entity_registry.py", line 103, in _convert_to_entity_category
    return convert_to_entity_category(value, raise_report=raise_report)
  File "/usr/src/homeassistant/homeassistant/helpers/entity.py", line 214, in convert_to_entity_category
    report(
  File "/usr/src/homeassistant/homeassistant/helpers/frame.py", line 74, in report
    _LOGGER.warning(msg, stack_info=True)
Stack (most recent call last):
  File "/usr/local/lib/python3.9/runpy.py", line 197, in _run_module_as_main
    return _run_code(code, main_globals, None,
  File "/usr/local/lib/python3.9/runpy.py", line 87, in _run_code
    exec(code, run_globals)
  File "/usr/src/homeassistant/homeassistant/__main__.py", line 203, in <module>
    sys.exit(main())
  File "/usr/src/homeassistant/homeassistant/__main__.py", line 191, in main
    exit_code = runner.run(runtime_conf)
  File "/usr/src/homeassistant/homeassistant/runner.py", line 119, in run
    return loop.run_until_complete(setup_and_run_hass(runtime_config))
  File "/usr/local/lib/python3.9/asyncio/base_events.py", line 629, in run_until_complete
    self.run_forever()
  File "/usr/local/lib/python3.9/asyncio/base_events.py", line 596, in run_forever
    self._run_once()
  File "/usr/local/lib/python3.9/asyncio/base_events.py", line 1890, in _run_once
    handle._run()
  File "/usr/local/lib/python3.9/asyncio/events.py", line 80, in _run
    self._context.run(self._callback, *self._args)
  File "/usr/src/homeassistant/homeassistant/helpers/entity_platform.py", line 510, in _async_add_entity
    entry = entity_registry.async_get_or_create(
  File "/usr/src/homeassistant/homeassistant/helpers/entity_registry.py", line 401, in async_get_or_create
    entity_category=_convert_to_entity_category(entity_category),
  File "/usr/src/homeassistant/homeassistant/helpers/entity_registry.py", line 103, in _convert_to_entity_category
    return convert_to_entity_category(value, raise_report=raise_report)
  File "/usr/src/homeassistant/homeassistant/helpers/entity.py", line 214, in convert_to_entity_category
    report(
  File "/usr/src/homeassistant/homeassistant/helpers/frame.py", line 74, in report
    _LOGGER.warning(msg, stack_info=True)
2022-02-05 20:39:38 WARNING (MainThread) [homeassistant.helpers.frame] Detected code that uses str (diagnostic) for entity category. This is deprecated and will stop working in Home Assistant 2022.4, it should be updated to use EntityCategory instead. Please report this issue.
Stack (most recent call last):
  File "/usr/local/lib/python3.9/runpy.py", line 197, in _run_module_as_main
    return _run_code(code, main_globals, None,
  File "/usr/local/lib/python3.9/runpy.py", line 87, in _run_code
    exec(code, run_globals)
  File "/usr/src/homeassistant/homeassistant/__main__.py", line 203, in <module>
    sys.exit(main())
  File "/usr/src/homeassistant/homeassistant/__main__.py", line 191, in main
    exit_code = runner.run(runtime_conf)
  File "/usr/src/homeassistant/homeassistant/runner.py", line 119, in run
    return loop.run_until_complete(setup_and_run_hass(runtime_config))
  File "/usr/local/lib/python3.9/asyncio/base_events.py", line 629, in run_until_complete
    self.run_forever()
  File "/usr/local/lib/python3.9/asyncio/base_events.py", line 596, in run_forever
    self._run_once()
  File "/usr/local/lib/python3.9/asyncio/base_events.py", line 1890, in _run_once
    handle._run()
  File "/usr/local/lib/python3.9/asyncio/events.py", line 80, in _run
    self._context.run(self._callback, *self._args)
  File "/usr/src/homeassistant/homeassistant/helpers/entity_platform.py", line 510, in _async_add_entity
    entry = entity_registry.async_get_or_create(
  File "/usr/src/homeassistant/homeassistant/helpers/entity_registry.py", line 401, in async_get_or_create
    entity_category=_convert_to_entity_category(entity_category),
  File "/usr/src/homeassistant/homeassistant/helpers/entity_registry.py", line 103, in _convert_to_entity_category
    return convert_to_entity_category(value, raise_report=raise_report)
  File "/usr/src/homeassistant/homeassistant/helpers/entity.py", line 214, in convert_to_entity_category
    report(
  File "/usr/src/homeassistant/homeassistant/helpers/frame.py", line 74, in report
    _LOGGER.warning(msg, stack_info=True)
Stack (most recent call last):
  File "/usr/local/lib/python3.9/runpy.py", line 197, in _run_module_as_main
    return _run_code(code, main_globals, None,
  File "/usr/local/lib/python3.9/runpy.py", line 87, in _run_code
    exec(code, run_globals)
  File "/usr/src/homeassistant/homeassistant/__main__.py", line 203, in <module>
    sys.exit(main())
  File "/usr/src/homeassistant/homeassistant/__main__.py", line 191, in main
    exit_code = runner.run(runtime_conf)
  File "/usr/src/homeassistant/homeassistant/runner.py", line 119, in run
    return loop.run_until_complete(setup_and_run_hass(runtime_config))
  File "/usr/local/lib/python3.9/asyncio/base_events.py", line 629, in run_until_complete
    self.run_forever()
  File "/usr/local/lib/python3.9/asyncio/base_events.py", line 596, in run_forever
    self._run_once()
  File "/usr/local/lib/python3.9/asyncio/base_events.py", line 1890, in _run_once
    handle._run()
  File "/usr/local/lib/python3.9/asyncio/events.py", line 80, in _run
    self._context.run(self._callback, *self._args)
  File "/usr/src/homeassistant/homeassistant/helpers/entity_platform.py", line 510, in _async_add_entity
    entry = entity_registry.async_get_or_create(
  File "/usr/src/homeassistant/homeassistant/helpers/entity_registry.py", line 401, in async_get_or_create
    entity_category=_convert_to_entity_category(entity_category),
  File "/usr/src/homeassistant/homeassistant/helpers/entity_registry.py", line 103, in _convert_to_entity_category
    return convert_to_entity_category(value, raise_report=raise_report)
  File "/usr/src/homeassistant/homeassistant/helpers/entity.py", line 214, in convert_to_entity_category
    report(
  File "/usr/src/homeassistant/homeassistant/helpers/frame.py", line 74, in report
    _LOGGER.warning(msg, stack_info=True)
2022-02-05 20:39:38 WARNING (MainThread) [homeassistant.helpers.frame] Detected code that uses str (diagnostic) for entity category. This is deprecated and will stop working in Home Assistant 2022.4, it should be updated to use EntityCategory instead. Please report this issue.
Stack (most recent call last):
  File "/usr/local/lib/python3.9/runpy.py", line 197, in _run_module_as_main
    return _run_code(code, main_globals, None,
  File "/usr/local/lib/python3.9/runpy.py", line 87, in _run_code
    exec(code, run_globals)
  File "/usr/src/homeassistant/homeassistant/__main__.py", line 203, in <module>
    sys.exit(main())
  File "/usr/src/homeassistant/homeassistant/__main__.py", line 191, in main
    exit_code = runner.run(runtime_conf)
  File "/usr/src/homeassistant/homeassistant/runner.py", line 119, in run
    return loop.run_until_complete(setup_and_run_hass(runtime_config))
  File "/usr/local/lib/python3.9/asyncio/base_events.py", line 629, in run_until_complete
    self.run_forever()
  File "/usr/local/lib/python3.9/asyncio/base_events.py", line 596, in run_forever
    self._run_once()
  File "/usr/local/lib/python3.9/asyncio/base_events.py", line 1890, in _run_once
    handle._run()
  File "/usr/local/lib/python3.9/asyncio/events.py", line 80, in _run
    self._context.run(self._callback, *self._args)
  File "/usr/src/homeassistant/homeassistant/helpers/entity_platform.py", line 510, in _async_add_entity
    entry = entity_registry.async_get_or_create(
  File "/usr/src/homeassistant/homeassistant/helpers/entity_registry.py", line 401, in async_get_or_create
    entity_category=_convert_to_entity_category(entity_category),
  File "/usr/src/homeassistant/homeassistant/helpers/entity_registry.py", line 103, in _convert_to_entity_category
    return convert_to_entity_category(value, raise_report=raise_report)
  File "/usr/src/homeassistant/homeassistant/helpers/entity.py", line 214, in convert_to_entity_category
    report(
  File "/usr/src/homeassistant/homeassistant/helpers/frame.py", line 74, in report
    _LOGGER.warning(msg, stack_info=True)
Stack (most recent call last):
  File "/usr/local/lib/python3.9/runpy.py", line 197, in _run_module_as_main
    return _run_code(code, main_globals, None,
  File "/usr/local/lib/python3.9/runpy.py", line 87, in _run_code
    exec(code, run_globals)
  File "/usr/src/homeassistant/homeassistant/__main__.py", line 203, in <module>
    sys.exit(main())
  File "/usr/src/homeassistant/homeassistant/__main__.py", line 191, in main
    exit_code = runner.run(runtime_conf)
  File "/usr/src/homeassistant/homeassistant/runner.py", line 119, in run
    return loop.run_until_complete(setup_and_run_hass(runtime_config))
  File "/usr/local/lib/python3.9/asyncio/base_events.py", line 629, in run_until_complete
    self.run_forever()
  File "/usr/local/lib/python3.9/asyncio/base_events.py", line 596, in run_forever
    self._run_once()
  File "/usr/local/lib/python3.9/asyncio/base_events.py", line 1890, in _run_once
    handle._run()
  File "/usr/local/lib/python3.9/asyncio/events.py", line 80, in _run
    self._context.run(self._callback, *self._args)
  File "/usr/src/homeassistant/homeassistant/helpers/entity_platform.py", line 510, in _async_add_entity
    entry = entity_registry.async_get_or_create(
  File "/usr/src/homeassistant/homeassistant/helpers/entity_registry.py", line 401, in async_get_or_create
    entity_category=_convert_to_entity_category(entity_category),
  File "/usr/src/homeassistant/homeassistant/helpers/entity_registry.py", line 103, in _convert_to_entity_category
    return convert_to_entity_category(value, raise_report=raise_report)
  File "/usr/src/homeassistant/homeassistant/helpers/entity.py", line 214, in convert_to_entity_category
    report(
  File "/usr/src/homeassistant/homeassistant/helpers/frame.py", line 74, in report
    _LOGGER.warning(msg, stack_info=True)
2022-02-05 20:39:38 WARNING (MainThread) [homeassistant.helpers.frame] Detected code that uses str (diagnostic) for entity category. This is deprecated and will stop working in Home Assistant 2022.4, it should be updated to use EntityCategory instead. Please report this issue.
Stack (most recent call last):
  File "/usr/local/lib/python3.9/runpy.py", line 197, in _run_module_as_main
    return _run_code(code, main_globals, None,
  File "/usr/local/lib/python3.9/runpy.py", line 87, in _run_code
    exec(code, run_globals)
  File "/usr/src/homeassistant/homeassistant/__main__.py", line 203, in <module>
    sys.exit(main())
  File "/usr/src/homeassistant/homeassistant/__main__.py", line 191, in main
    exit_code = runner.run(runtime_conf)
  File "/usr/src/homeassistant/homeassistant/runner.py", line 119, in run
    return loop.run_until_complete(setup_and_run_hass(runtime_config))
  File "/usr/local/lib/python3.9/asyncio/base_events.py", line 629, in run_until_complete
    self.run_forever()
  File "/usr/local/lib/python3.9/asyncio/base_events.py", line 596, in run_forever
    self._run_once()
  File "/usr/local/lib/python3.9/asyncio/base_events.py", line 1890, in _run_once
    handle._run()
  File "/usr/local/lib/python3.9/asyncio/events.py", line 80, in _run
    self._context.run(self._callback, *self._args)
  File "/usr/src/homeassistant/homeassistant/helpers/entity_platform.py", line 510, in _async_add_entity
    entry = entity_registry.async_get_or_create(
  File "/usr/src/homeassistant/homeassistant/helpers/entity_registry.py", line 401, in async_get_or_create
    entity_category=_convert_to_entity_category(entity_category),
  File "/usr/src/homeassistant/homeassistant/helpers/entity_registry.py", line 103, in _convert_to_entity_category
    return convert_to_entity_category(value, raise_report=raise_report)
  File "/usr/src/homeassistant/homeassistant/helpers/entity.py", line 214, in convert_to_entity_category
    report(
  File "/usr/src/homeassistant/homeassistant/helpers/frame.py", line 74, in report
    _LOGGER.warning(msg, stack_info=True)
Stack (most recent call last):
  File "/usr/local/lib/python3.9/runpy.py", line 197, in _run_module_as_main
    return _run_code(code, main_globals, None,
  File "/usr/local/lib/python3.9/runpy.py", line 87, in _run_code
    exec(code, run_globals)
  File "/usr/src/homeassistant/homeassistant/__main__.py", line 203, in <module>
    sys.exit(main())
  File "/usr/src/homeassistant/homeassistant/__main__.py", line 191, in main
    exit_code = runner.run(runtime_conf)
  File "/usr/src/homeassistant/homeassistant/runner.py", line 119, in run
    return loop.run_until_complete(setup_and_run_hass(runtime_config))
  File "/usr/local/lib/python3.9/asyncio/base_events.py", line 629, in run_until_complete
    self.run_forever()
  File "/usr/local/lib/python3.9/asyncio/base_events.py", line 596, in run_forever
    self._run_once()
  File "/usr/local/lib/python3.9/asyncio/base_events.py", line 1890, in _run_once
    handle._run()
  File "/usr/local/lib/python3.9/asyncio/events.py", line 80, in _run
    self._context.run(self._callback, *self._args)
  File "/usr/src/homeassistant/homeassistant/helpers/entity_platform.py", line 510, in _async_add_entity
    entry = entity_registry.async_get_or_create(
  File "/usr/src/homeassistant/homeassistant/helpers/entity_registry.py", line 401, in async_get_or_create
    entity_category=_convert_to_entity_category(entity_category),
  File "/usr/src/homeassistant/homeassistant/helpers/entity_registry.py", line 103, in _convert_to_entity_category
    return convert_to_entity_category(value, raise_report=raise_report)
  File "/usr/src/homeassistant/homeassistant/helpers/entity.py", line 214, in convert_to_entity_category
    report(
  File "/usr/src/homeassistant/homeassistant/helpers/frame.py", line 74, in report
    _LOGGER.warning(msg, stack_info=True)
2022-02-05 20:39:38 WARNING (MainThread) [homeassistant.helpers.frame] Detected code that uses str (diagnostic) for entity category. This is deprecated and will stop working in Home Assistant 2022.4, it should be updated to use EntityCategory instead. Please report this issue.
Stack (most recent call last):
  File "/usr/local/lib/python3.9/runpy.py", line 197, in _run_module_as_main
    return _run_code(code, main_globals, None,
  File "/usr/local/lib/python3.9/runpy.py", line 87, in _run_code
    exec(code, run_globals)
  File "/usr/src/homeassistant/homeassistant/__main__.py", line 203, in <module>
    sys.exit(main())
  File "/usr/src/homeassistant/homeassistant/__main__.py", line 191, in main
    exit_code = runner.run(runtime_conf)
  File "/usr/src/homeassistant/homeassistant/runner.py", line 119, in run
    return loop.run_until_complete(setup_and_run_hass(runtime_config))
  File "/usr/local/lib/python3.9/asyncio/base_events.py", line 629, in run_until_complete
    self.run_forever()
  File "/usr/local/lib/python3.9/asyncio/base_events.py", line 596, in run_forever
    self._run_once()
  File "/usr/local/lib/python3.9/asyncio/base_events.py", line 1890, in _run_once
    handle._run()
  File "/usr/local/lib/python3.9/asyncio/events.py", line 80, in _run
    self._context.run(self._callback, *self._args)
  File "/usr/src/homeassistant/homeassistant/helpers/entity_platform.py", line 510, in _async_add_entity
    entry = entity_registry.async_get_or_create(
  File "/usr/src/homeassistant/homeassistant/helpers/entity_registry.py", line 401, in async_get_or_create
    entity_category=_convert_to_entity_category(entity_category),
  File "/usr/src/homeassistant/homeassistant/helpers/entity_registry.py", line 103, in _convert_to_entity_category
    return convert_to_entity_category(value, raise_report=raise_report)
  File "/usr/src/homeassistant/homeassistant/helpers/entity.py", line 214, in convert_to_entity_category
    report(
  File "/usr/src/homeassistant/homeassistant/helpers/frame.py", line 74, in report
    _LOGGER.warning(msg, stack_info=True)
Stack (most recent call last):
  File "/usr/local/lib/python3.9/runpy.py", line 197, in _run_module_as_main
    return _run_code(code, main_globals, None,
  File "/usr/local/lib/python3.9/runpy.py", line 87, in _run_code
    exec(code, run_globals)
  File "/usr/src/homeassistant/homeassistant/__main__.py", line 203, in <module>
    sys.exit(main())
  File "/usr/src/homeassistant/homeassistant/__main__.py", line 191, in main
    exit_code = runner.run(runtime_conf)
  File "/usr/src/homeassistant/homeassistant/runner.py", line 119, in run
    return loop.run_until_complete(setup_and_run_hass(runtime_config))
  File "/usr/local/lib/python3.9/asyncio/base_events.py", line 629, in run_until_complete
    self.run_forever()
  File "/usr/local/lib/python3.9/asyncio/base_events.py", line 596, in run_forever
    self._run_once()
  File "/usr/local/lib/python3.9/asyncio/base_events.py", line 1890, in _run_once
    handle._run()
  File "/usr/local/lib/python3.9/asyncio/events.py", line 80, in _run
    self._context.run(self._callback, *self._args)
  File "/usr/src/homeassistant/homeassistant/helpers/entity_platform.py", line 510, in _async_add_entity
    entry = entity_registry.async_get_or_create(
  File "/usr/src/homeassistant/homeassistant/helpers/entity_registry.py", line 401, in async_get_or_create
    entity_category=_convert_to_entity_category(entity_category),
  File "/usr/src/homeassistant/homeassistant/helpers/entity_registry.py", line 103, in _convert_to_entity_category
    return convert_to_entity_category(value, raise_report=raise_report)
  File "/usr/src/homeassistant/homeassistant/helpers/entity.py", line 214, in convert_to_entity_category
    report(
  File "/usr/src/homeassistant/homeassistant/helpers/frame.py", line 74, in report
    _LOGGER.warning(msg, stack_info=True)
2022-02-05 20:39:39 ERROR (MainThread) [homeassistant.components.github] Bad credentials
Traceback (most recent call last):
  File "/usr/src/homeassistant/homeassistant/components/github/coordinator.py", line 65, in _async_update_data
    response = await self.fetch_data()
  File "/usr/src/homeassistant/homeassistant/components/github/coordinator.py", line 93, in fetch_data
    return await self._client.repos.get(self.repository, **{"etag": self._etag})
  File "/usr/local/lib/python3.9/site-packages/aiogithubapi/namespaces/repos.py", line 82, in get
    response = await self._client.async_call_api(
  File "/usr/local/lib/python3.9/site-packages/aiogithubapi/client.py", line 134, in async_call_api
    raise exception(message or response.data)
aiogithubapi.exceptions.GitHubAuthenticationException: Bad credentials
2022-02-05 20:39:39 WARNING (MainThread) [homeassistant.config_entries] Config entry '' for github integration not ready yet: Bad credentials; Retrying in background
2022-02-05 20:39:40 ERROR (MainThread) [custom_components.hacs] HACS is disabled - HacsDisabledReason.INVALID_TOKEN
2022-02-05 20:39:40 ERROR (MainThread) [custom_components.hacs] Bad credentials
Traceback (most recent call last):
  File "/config/custom_components/hacs/base.py", line 428, in async_can_update
    response = await self.async_github_api_method(self.githubapi.rate_limit)
  File "/config/custom_components/hacs/base.py", line 479, in async_github_api_method
    raise HacsException(_exception)
custom_components.hacs.exceptions.HacsException: Bad credentials
2022-02-05 20:40:12 ERROR (SyncWorker_3) [spotipy.client] Max Retries reached
2022-02-05 20:40:12 WARNING (MainThread) [homeassistant.config_entries] Config entry 'Mgerasika@gmail.com' for spotify integration not ready yet: http status: 429, code:-1 - /v1/me/:
 Max Retries, reason: too many 429 error responses; Retrying in background
2022-02-05 20:40:13 ERROR (MainThread) [homeassistant.components.github] Bad credentials
Traceback (most recent call last):
  File "/usr/src/homeassistant/homeassistant/components/github/coordinator.py", line 65, in _async_update_data
    response = await self.fetch_data()
  File "/usr/src/homeassistant/homeassistant/components/github/coordinator.py", line 93, in fetch_data
    return await self._client.repos.get(self.repository, **{"etag": self._etag})
  File "/usr/local/lib/python3.9/site-packages/aiogithubapi/namespaces/repos.py", line 82, in get
    response = await self._client.async_call_api(
  File "/usr/local/lib/python3.9/site-packages/aiogithubapi/client.py", line 134, in async_call_api
    raise exception(message or response.data)
aiogithubapi.exceptions.GitHubAuthenticationException: Bad credentials
2022-02-05 20:40:24 ERROR (MainThread) [homeassistant.components.github] Bad credentials
Traceback (most recent call last):
  File "/usr/src/homeassistant/homeassistant/components/github/coordinator.py", line 65, in _async_update_data
    response = await self.fetch_data()
  File "/usr/src/homeassistant/homeassistant/components/github/coordinator.py", line 93, in fetch_data
    return await self._client.repos.get(self.repository, **{"etag": self._etag})
  File "/usr/local/lib/python3.9/site-packages/aiogithubapi/namespaces/repos.py", line 82, in get
    response = await self._client.async_call_api(
  File "/usr/local/lib/python3.9/site-packages/aiogithubapi/client.py", line 134, in async_call_api
    raise exception(message or response.data)
aiogithubapi.exceptions.GitHubAuthenticationException: Bad credentials
2022-02-05 20:40:44 ERROR (MainThread) [homeassistant.components.github] Bad credentials
Traceback (most recent call last):
  File "/usr/src/homeassistant/homeassistant/components/github/coordinator.py", line 65, in _async_update_data
    response = await self.fetch_data()
  File "/usr/src/homeassistant/homeassistant/components/github/coordinator.py", line 93, in fetch_data
    return await self._client.repos.get(self.repository, **{"etag": self._etag})
  File "/usr/local/lib/python3.9/site-packages/aiogithubapi/namespaces/repos.py", line 82, in get
    response = await self._client.async_call_api(
  File "/usr/local/lib/python3.9/site-packages/aiogithubapi/client.py", line 134, in async_call_api
    raise exception(message or response.data)
aiogithubapi.exceptions.GitHubAuthenticationException: Bad credentials
2022-02-05 20:41:11 ERROR (SyncWorker_0) [spotipy.client] Max Retries reached
2022-02-05 20:41:25 ERROR (MainThread) [homeassistant.components.github] Bad credentials
Traceback (most recent call last):
  File "/usr/src/homeassistant/homeassistant/components/github/coordinator.py", line 65, in _async_update_data
    response = await self.fetch_data()
  File "/usr/src/homeassistant/homeassistant/components/github/coordinator.py", line 93, in fetch_data
    return await self._client.repos.get(self.repository, **{"etag": self._etag})
  File "/usr/local/lib/python3.9/site-packages/aiogithubapi/namespaces/repos.py", line 82, in get
    response = await self._client.async_call_api(
  File "/usr/local/lib/python3.9/site-packages/aiogithubapi/client.py", line 134, in async_call_api
    raise exception(message or response.data)
aiogithubapi.exceptions.GitHubAuthenticationException: Bad credentials
2022-02-05 20:42:10 ERROR (SyncWorker_2) [spotipy.client] Max Retries reached
2022-02-05 20:42:42 WARNING (Thread-3) [custom_components.ble_monitor.ble_parser.xiaomi] Decryption failed: MAC check failed
2022-02-05 20:42:45 ERROR (MainThread) [homeassistant.components.github] Bad credentials
Traceback (most recent call last):
  File "/usr/src/homeassistant/homeassistant/components/github/coordinator.py", line 65, in _async_update_data
    response = await self.fetch_data()
  File "/usr/src/homeassistant/homeassistant/components/github/coordinator.py", line 93, in fetch_data
    return await self._client.repos.get(self.repository, **{"etag": self._etag})
  File "/usr/local/lib/python3.9/site-packages/aiogithubapi/namespaces/repos.py", line 82, in get
    response = await self._client.async_call_api(
  File "/usr/local/lib/python3.9/site-packages/aiogithubapi/client.py", line 134, in async_call_api
    raise exception(message or response.data)
aiogithubapi.exceptions.GitHubAuthenticationException: Bad credentials
2022-02-05 20:43:21 WARNING (MainThread) [homeassistant.components.media_player] Setup of media_player platform spotify is taking over 10 seconds.
2022-02-05 20:43:41 WARNING (Thread-3) [custom_components.ble_monitor.ble_parser.xiaomi] Decryption failed: MAC check failed
2022-02-05 20:44:05 ERROR (MainThread) [homeassistant.components.github] Bad credentials
Traceback (most recent call last):
  File "/usr/src/homeassistant/homeassistant/components/github/coordinator.py", line 65, in _async_update_data
    response = await self.fetch_data()
  File "/usr/src/homeassistant/homeassistant/components/github/coordinator.py", line 93, in fetch_data
    return await self._client.repos.get(self.repository, **{"etag": self._etag})
  File "/usr/local/lib/python3.9/site-packages/aiogithubapi/namespaces/repos.py", line 82, in get
    response = await self._client.async_call_api(
  File "/usr/local/lib/python3.9/site-packages/aiogithubapi/client.py", line 134, in async_call_api
    raise exception(message or response.data)
aiogithubapi.exceptions.GitHubAuthenticationException: Bad credentials
2022-02-05 20:44:10 ERROR (SyncWorker_2) [spotipy.client] Max Retries reached
2022-02-05 20:44:42 WARNING (Thread-3) [custom_components.ble_monitor.ble_parser.xiaomi] Decryption failed: MAC check failed
2022-02-05 20:44:50 WARNING (MainThread) [homeassistant.helpers.entity] Update of media_player.spotify_mgerasika_gmail_com is taking over 10 seconds
2022-02-05 20:45:10 WARNING (MainThread) [homeassistant.components.media_player] Updating spotify media_player took longer than the scheduled update interval 0:00:30
2022-02-05 20:45:11 ERROR (SyncWorker_4) [spotipy.client] Max Retries reached
2022-02-05 20:45:25 ERROR (MainThread) [homeassistant.components.github] Bad credentials
Traceback (most recent call last):
  File "/usr/src/homeassistant/homeassistant/components/github/coordinator.py", line 65, in _async_update_data
    response = await self.fetch_data()
  File "/usr/src/homeassistant/homeassistant/components/github/coordinator.py", line 93, in fetch_data
    return await self._client.repos.get(self.repository, **{"etag": self._etag})
  File "/usr/local/lib/python3.9/site-packages/aiogithubapi/namespaces/repos.py", line 82, in get
    response = await self._client.async_call_api(
  File "/usr/local/lib/python3.9/site-packages/aiogithubapi/client.py", line 134, in async_call_api
    raise exception(message or response.data)
aiogithubapi.exceptions.GitHubAuthenticationException: Bad credentials
2022-02-05 20:45:50 WARNING (MainThread) [homeassistant.helpers.entity] Update of media_player.spotify_mgerasika_gmail_com is taking over 10 seconds
2022-02-05 20:46:10 WARNING (MainThread) [homeassistant.components.media_player] Updating spotify media_player took longer than the scheduled update interval 0:00:30
2022-02-05 20:46:11 ERROR (SyncWorker_4) [spotipy.client] Max Retries reached
2022-02-05 20:46:46 ERROR (MainThread) [homeassistant.components.github] Bad credentials
Traceback (most recent call last):
  File "/usr/src/homeassistant/homeassistant/components/github/coordinator.py", line 65, in _async_update_data
    response = await self.fetch_data()
  File "/usr/src/homeassistant/homeassistant/components/github/coordinator.py", line 93, in fetch_data
    return await self._client.repos.get(self.repository, **{"etag": self._etag})
  File "/usr/local/lib/python3.9/site-packages/aiogithubapi/namespaces/repos.py", line 82, in get
    response = await self._client.async_call_api(
  File "/usr/local/lib/python3.9/site-packages/aiogithubapi/client.py", line 134, in async_call_api
    raise exception(message or response.data)
aiogithubapi.exceptions.GitHubAuthenticationException: Bad credentials
2022-02-05 20:46:50 WARNING (MainThread) [homeassistant.helpers.entity] Update of media_player.spotify_mgerasika_gmail_com is taking over 10 seconds
2022-02-05 20:47:10 WARNING (MainThread) [homeassistant.components.media_player] Updating spotify media_player took longer than the scheduled update interval 0:00:30
2022-02-05 20:47:11 ERROR (SyncWorker_0) [spotipy.client] Max Retries reached
2022-02-05 20:47:24 ERROR (Thread-3) [custom_components.ble_monitor.ble_parser.xiaomi] No encryption key found for device with MAC A4:C1:38:BE:4C:FB
2022-02-05 20:47:50 WARNING (MainThread) [homeassistant.helpers.entity] Update of media_player.spotify_mgerasika_gmail_com is taking over 10 seconds
2022-02-05 20:48:06 ERROR (MainThread) [homeassistant.components.github] Bad credentials
Traceback (most recent call last):
  File "/usr/src/homeassistant/homeassistant/components/github/coordinator.py", line 65, in _async_update_data
    response = await self.fetch_data()
  File "/usr/src/homeassistant/homeassistant/components/github/coordinator.py", line 93, in fetch_data
    return await self._client.repos.get(self.repository, **{"etag": self._etag})
  File "/usr/local/lib/python3.9/site-packages/aiogithubapi/namespaces/repos.py", line 82, in get
    response = await self._client.async_call_api(
  File "/usr/local/lib/python3.9/site-packages/aiogithubapi/client.py", line 134, in async_call_api
    raise exception(message or response.data)
aiogithubapi.exceptions.GitHubAuthenticationException: Bad credentials
2022-02-05 20:48:10 WARNING (MainThread) [homeassistant.components.media_player] Updating spotify media_player took longer than the scheduled update interval 0:00:30
2022-02-05 20:48:11 ERROR (SyncWorker_0) [spotipy.client] Max Retries reached
2022-02-05 20:48:24 ERROR (Thread-3) [custom_components.ble_monitor.ble_parser.xiaomi] No encryption key found for device with MAC A4:C1:38:BE:4C:FB
2022-02-05 20:48:50 WARNING (MainThread) [homeassistant.helpers.entity] Update of media_player.spotify_mgerasika_gmail_com is taking over 10 seconds
2022-02-05 20:49:10 WARNING (MainThread) [homeassistant.components.media_player] Updating spotify media_player took longer than the scheduled update interval 0:00:30
2022-02-05 20:49:11 ERROR (SyncWorker_0) [spotipy.client] Max Retries reached
2022-02-05 20:49:26 ERROR (MainThread) [homeassistant.components.github] Bad credentials
Traceback (most recent call last):
  File "/usr/src/homeassistant/homeassistant/components/github/coordinator.py", line 65, in _async_update_data
    response = await self.fetch_data()
  File "/usr/src/homeassistant/homeassistant/components/github/coordinator.py", line 93, in fetch_data
    return await self._client.repos.get(self.repository, **{"etag": self._etag})
  File "/usr/local/lib/python3.9/site-packages/aiogithubapi/namespaces/repos.py", line 82, in get
    response = await self._client.async_call_api(
  File "/usr/local/lib/python3.9/site-packages/aiogithubapi/client.py", line 134, in async_call_api
    raise exception(message or response.data)
aiogithubapi.exceptions.GitHubAuthenticationException: Bad credentials
2022-02-05 20:49:50 WARNING (MainThread) [homeassistant.helpers.entity] Update of media_player.spotify_mgerasika_gmail_com is taking over 10 seconds
2022-02-05 20:50:10 WARNING (MainThread) [homeassistant.components.media_player] Updating spotify media_player took longer than the scheduled update interval 0:00:30
2022-02-05 20:50:11 ERROR (SyncWorker_0) [spotipy.client] Max Retries reached
2022-02-05 20:50:46 ERROR (MainThread) [homeassistant.components.github] Bad credentials
Traceback (most recent call last):
  File "/usr/src/homeassistant/homeassistant/components/github/coordinator.py", line 65, in _async_update_data
    response = await self.fetch_data()
  File "/usr/src/homeassistant/homeassistant/components/github/coordinator.py", line 93, in fetch_data
    return await self._client.repos.get(self.repository, **{"etag": self._etag})
  File "/usr/local/lib/python3.9/site-packages/aiogithubapi/namespaces/repos.py", line 82, in get
    response = await self._client.async_call_api(
  File "/usr/local/lib/python3.9/site-packages/aiogithubapi/client.py", line 134, in async_call_api
    raise exception(message or response.data)
aiogithubapi.exceptions.GitHubAuthenticationException: Bad credentials
2022-02-05 20:50:50 WARNING (MainThread) [homeassistant.helpers.entity] Update of media_player.spotify_mgerasika_gmail_com is taking over 10 seconds
2022-02-05 20:51:10 WARNING (MainThread) [homeassistant.components.media_player] Updating spotify media_player took longer than the scheduled update interval 0:00:30
2022-02-05 20:51:40 WARNING (MainThread) [homeassistant.components.media_player] Updating spotify media_player took longer than the scheduled update interval 0:00:30
2022-02-05 20:52:07 ERROR (MainThread) [homeassistant.components.github] Bad credentials
Traceback (most recent call last):
  File "/usr/src/homeassistant/homeassistant/components/github/coordinator.py", line 65, in _async_update_data
    response = await self.fetch_data()
  File "/usr/src/homeassistant/homeassistant/components/github/coordinator.py", line 93, in fetch_data
    return await self._client.repos.get(self.repository, **{"etag": self._etag})
  File "/usr/local/lib/python3.9/site-packages/aiogithubapi/namespaces/repos.py", line 82, in get
    response = await self._client.async_call_api(
  File "/usr/local/lib/python3.9/site-packages/aiogithubapi/client.py", line 134, in async_call_api
    raise exception(message or response.data)
aiogithubapi.exceptions.GitHubAuthenticationException: Bad credentials
2022-02-05 20:52:10 WARNING (MainThread) [homeassistant.components.media_player] Updating spotify media_player took longer than the scheduled update interval 0:00:30
2022-02-05 20:52:50 WARNING (MainThread) [homeassistant.helpers.entity] Update of media_player.spotify_mgerasika_gmail_com is taking over 10 seconds
2022-02-05 20:53:10 WARNING (MainThread) [homeassistant.components.media_player] Updating spotify media_player took longer than the scheduled update interval 0:00:30
2022-02-05 20:53:11 ERROR (SyncWorker_4) [spotipy.client] Max Retries reached
2022-02-05 20:53:27 ERROR (MainThread) [homeassistant.components.github] Bad credentials
Traceback (most recent call last):
  File "/usr/src/homeassistant/homeassistant/components/github/coordinator.py", line 65, in _async_update_data
    response = await self.fetch_data()
  File "/usr/src/homeassistant/homeassistant/components/github/coordinator.py", line 93, in fetch_data
    return await self._client.repos.get(self.repository, **{"etag": self._etag})
  File "/usr/local/lib/python3.9/site-packages/aiogithubapi/namespaces/repos.py", line 82, in get
    response = await self._client.async_call_api(
  File "/usr/local/lib/python3.9/site-packages/aiogithubapi/client.py", line 134, in async_call_api
    raise exception(message or response.data)
aiogithubapi.exceptions.GitHubAuthenticationException: Bad credentials
2022-02-05 20:53:40 WARNING (Thread-3) [custom_components.ble_monitor.ble_parser.xiaomi] Decryption failed: MAC check failed
2022-02-05 20:53:50 WARNING (MainThread) [homeassistant.helpers.entity] Update of media_player.spotify_mgerasika_gmail_com is taking over 10 seconds
2022-02-05 20:54:10 WARNING (MainThread) [homeassistant.components.media_player] Updating spotify media_player took longer than the scheduled update interval 0:00:30
2022-02-05 20:54:11 ERROR (SyncWorker_2) [spotipy.client] Max Retries reached
2022-02-05 20:54:41 WARNING (Thread-3) [custom_components.ble_monitor.ble_parser.xiaomi] Decryption failed: MAC check failed
2022-02-05 20:54:46 ERROR (MainThread) [custom_components.hacs] HACS is disabled - HacsDisabledReason.INVALID_TOKEN
2022-02-05 20:54:46 WARNING (MainThread) [custom_components.hacs] Could not load default repositories: Bad credentials, retrying in 5 minuttes
2022-02-05 20:54:47 ERROR (MainThread) [homeassistant.components.github] Bad credentials
Traceback (most recent call last):
  File "/usr/src/homeassistant/homeassistant/components/github/coordinator.py", line 65, in _async_update_data
    response = await self.fetch_data()
  File "/usr/src/homeassistant/homeassistant/components/github/coordinator.py", line 93, in fetch_data
    return await self._client.repos.get(self.repository, **{"etag": self._etag})
  File "/usr/local/lib/python3.9/site-packages/aiogithubapi/namespaces/repos.py", line 82, in get
    response = await self._client.async_call_api(
  File "/usr/local/lib/python3.9/site-packages/aiogithubapi/client.py", line 134, in async_call_api
    raise exception(message or response.data)
aiogithubapi.exceptions.GitHubAuthenticationException: Bad credentials
2022-02-05 20:54:50 WARNING (MainThread) [homeassistant.helpers.entity] Update of media_player.spotify_mgerasika_gmail_com is taking over 10 seconds
2022-02-05 20:55:10 WARNING (MainThread) [homeassistant.components.media_player] Updating spotify media_player took longer than the scheduled update interval 0:00:30
2022-02-05 20:55:11 ERROR (SyncWorker_3) [spotipy.client] Max Retries reached
2022-02-05 20:55:50 WARNING (MainThread) [homeassistant.helpers.entity] Update of media_player.spotify_mgerasika_gmail_com is taking over 10 seconds
2022-02-05 20:56:07 ERROR (MainThread) [homeassistant.components.github] Bad credentials
Traceback (most recent call last):
  File "/usr/src/homeassistant/homeassistant/components/github/coordinator.py", line 65, in _async_update_data
    response = await self.fetch_data()
  File "/usr/src/homeassistant/homeassistant/components/github/coordinator.py", line 93, in fetch_data
    return await self._client.repos.get(self.repository, **{"etag": self._etag})
  File "/usr/local/lib/python3.9/site-packages/aiogithubapi/namespaces/repos.py", line 82, in get
    response = await self._client.async_call_api(
  File "/usr/local/lib/python3.9/site-packages/aiogithubapi/client.py", line 134, in async_call_api
    raise exception(message or response.data)
aiogithubapi.exceptions.GitHubAuthenticationException: Bad credentials
2022-02-05 20:56:10 WARNING (MainThread) [homeassistant.components.media_player] Updating spotify media_player took longer than the scheduled update interval 0:00:30
2022-02-05 20:56:50 WARNING (MainThread) [homeassistant.helpers.entity] Update of media_player.spotify_mgerasika_gmail_com is taking over 10 seconds
2022-02-05 20:57:10 WARNING (MainThread) [homeassistant.components.media_player] Updating spotify media_player took longer than the scheduled update interval 0:00:30
2022-02-05 20:57:11 ERROR (SyncWorker_1) [spotipy.client] Max Retries reached
2022-02-05 20:57:28 ERROR (MainThread) [homeassistant.components.github] Bad credentials
Traceback (most recent call last):
  File "/usr/src/homeassistant/homeassistant/components/github/coordinator.py", line 65, in _async_update_data
    response = await self.fetch_data()
  File "/usr/src/homeassistant/homeassistant/components/github/coordinator.py", line 93, in fetch_data
    return await self._client.repos.get(self.repository, **{"etag": self._etag})
  File "/usr/local/lib/python3.9/site-packages/aiogithubapi/namespaces/repos.py", line 82, in get
    response = await self._client.async_call_api(
  File "/usr/local/lib/python3.9/site-packages/aiogithubapi/client.py", line 134, in async_call_api
    raise exception(message or response.data)
aiogithubapi.exceptions.GitHubAuthenticationException: Bad credentials
2022-02-05 20:57:50 WARNING (MainThread) [homeassistant.helpers.entity] Update of media_player.spotify_mgerasika_gmail_com is taking over 10 seconds
2022-02-05 20:58:10 WARNING (MainThread) [homeassistant.components.media_player] Updating spotify media_player took longer than the scheduled update interval 0:00:30
2022-02-05 20:58:11 ERROR (SyncWorker_4) [spotipy.client] Max Retries reached
2022-02-05 20:58:23 ERROR (Thread-3) [custom_components.ble_monitor.ble_parser.xiaomi] No encryption key found for device with MAC A4:C1:38:BE:4C:FB
2022-02-05 20:58:48 ERROR (MainThread) [homeassistant.components.github] Bad credentials
Traceback (most recent call last):
  File "/usr/src/homeassistant/homeassistant/components/github/coordinator.py", line 65, in _async_update_data
    response = await self.fetch_data()
  File "/usr/src/homeassistant/homeassistant/components/github/coordinator.py", line 93, in fetch_data
    return await self._client.repos.get(self.repository, **{"etag": self._etag})
  File "/usr/local/lib/python3.9/site-packages/aiogithubapi/namespaces/repos.py", line 82, in get
    response = await self._client.async_call_api(
  File "/usr/local/lib/python3.9/site-packages/aiogithubapi/client.py", line 134, in async_call_api
    raise exception(message or response.data)
aiogithubapi.exceptions.GitHubAuthenticationException: Bad credentials
2022-02-05 20:58:50 WARNING (MainThread) [homeassistant.helpers.entity] Update of media_player.spotify_mgerasika_gmail_com is taking over 10 seconds
2022-02-05 20:59:10 WARNING (MainThread) [homeassistant.components.media_player] Updating spotify media_player took longer than the scheduled update interval 0:00:30
2022-02-05 20:59:11 ERROR (SyncWorker_2) [spotipy.client] Max Retries reached
2022-02-05 20:59:24 ERROR (Thread-3) [custom_components.ble_monitor.ble_parser.xiaomi] No encryption key found for device with MAC A4:C1:38:BE:4C:FB
2022-02-05 20:59:50 WARNING (MainThread) [homeassistant.helpers.entity] Update of media_player.spotify_mgerasika_gmail_com is taking over 10 seconds
2022-02-05 21:00:08 ERROR (MainThread) [homeassistant.components.github] Bad credentials
Traceback (most recent call last):
  File "/usr/src/homeassistant/homeassistant/components/github/coordinator.py", line 65, in _async_update_data
    response = await self.fetch_data()
  File "/usr/src/homeassistant/homeassistant/components/github/coordinator.py", line 93, in fetch_data
    return await self._client.repos.get(self.repository, **{"etag": self._etag})
  File "/usr/local/lib/python3.9/site-packages/aiogithubapi/namespaces/repos.py", line 82, in get
    response = await self._client.async_call_api(
  File "/usr/local/lib/python3.9/site-packages/aiogithubapi/client.py", line 134, in async_call_api
    raise exception(message or response.data)
aiogithubapi.exceptions.GitHubAuthenticationException: Bad credentials
2022-02-05 21:00:10 WARNING (MainThread) [homeassistant.components.media_player] Updating spotify media_player took longer than the scheduled update interval 0:00:30
2022-02-05 21:00:11 ERROR (SyncWorker_2) [spotipy.client] Max Retries reached
2022-02-05 21:00:50 WARNING (MainThread) [homeassistant.helpers.entity] Update of media_player.spotify_mgerasika_gmail_com is taking over 10 seconds
2022-02-05 21:01:10 WARNING (MainThread) [homeassistant.components.media_player] Updating spotify media_player took longer than the scheduled update interval 0:00:30
2022-02-05 21:01:11 ERROR (SyncWorker_3) [spotipy.client] Max Retries reached
2022-02-05 21:01:29 ERROR (MainThread) [homeassistant.components.github] Bad credentials
Traceback (most recent call last):
  File "/usr/src/homeassistant/homeassistant/components/github/coordinator.py", line 65, in _async_update_data
    response = await self.fetch_data()
  File "/usr/src/homeassistant/homeassistant/components/github/coordinator.py", line 93, in fetch_data
    return await self._client.repos.get(self.repository, **{"etag": self._etag})
  File "/usr/local/lib/python3.9/site-packages/aiogithubapi/namespaces/repos.py", line 82, in get
    response = await self._client.async_call_api(
  File "/usr/local/lib/python3.9/site-packages/aiogithubapi/client.py", line 134, in async_call_api
    raise exception(message or response.data)
aiogithubapi.exceptions.GitHubAuthenticationException: Bad credentials
2022-02-05 21:01:50 WARNING (MainThread) [homeassistant.helpers.entity] Update of media_player.spotify_mgerasika_gmail_com is taking over 10 seconds
2022-02-05 21:02:10 WARNING (MainThread) [homeassistant.components.media_player] Updating spotify media_player took longer than the scheduled update interval 0:00:30
2022-02-05 21:02:11 ERROR (SyncWorker_3) [spotipy.client] Max Retries reached
2022-02-05 21:02:49 ERROR (MainThread) [homeassistant.components.github] Bad credentials
Traceback (most recent call last):
  File "/usr/src/homeassistant/homeassistant/components/github/coordinator.py", line 65, in _async_update_data
    response = await self.fetch_data()
  File "/usr/src/homeassistant/homeassistant/components/github/coordinator.py", line 93, in fetch_data
    return await self._client.repos.get(self.repository, **{"etag": self._etag})
  File "/usr/local/lib/python3.9/site-packages/aiogithubapi/namespaces/repos.py", line 82, in get
    response = await self._client.async_call_api(
  File "/usr/local/lib/python3.9/site-packages/aiogithubapi/client.py", line 134, in async_call_api
    raise exception(message or response.data)
aiogithubapi.exceptions.GitHubAuthenticationException: Bad credentials
2022-02-05 21:02:50 WARNING (MainThread) [homeassistant.helpers.entity] Update of media_player.spotify_mgerasika_gmail_com is taking over 10 seconds
2022-02-05 21:03:10 WARNING (MainThread) [homeassistant.components.media_player] Updating spotify media_player took longer than the scheduled update interval 0:00:30
2022-02-05 21:03:40 WARNING (MainThread) [homeassistant.components.media_player] Updating spotify media_player took longer than the scheduled update interval 0:00:30
2022-02-05 21:03:40 ERROR (SyncWorker_4) [spotipy.client] Max Retries reached
2022-02-05 21:04:09 ERROR (MainThread) [homeassistant.components.github] Bad credentials
Traceback (most recent call last):
  File "/usr/src/homeassistant/homeassistant/components/github/coordinator.py", line 65, in _async_update_data
    response = await self.fetch_data()
  File "/usr/src/homeassistant/homeassistant/components/github/coordinator.py", line 93, in fetch_data
    return await self._client.repos.get(self.repository, **{"etag": self._etag})
  File "/usr/local/lib/python3.9/site-packages/aiogithubapi/namespaces/repos.py", line 82, in get
    response = await self._client.async_call_api(
  File "/usr/local/lib/python3.9/site-packages/aiogithubapi/client.py", line 134, in async_call_api
    raise exception(message or response.data)
aiogithubapi.exceptions.GitHubAuthenticationException: Bad credentials
2022-02-05 21:04:20 WARNING (MainThread) [homeassistant.helpers.entity] Update of media_player.spotify_mgerasika_gmail_com is taking over 10 seconds
2022-02-05 21:04:39 WARNING (Thread-3) [custom_components.ble_monitor.ble_parser.xiaomi] Decryption failed: MAC check failed
2022-02-05 21:04:40 WARNING (MainThread) [homeassistant.components.media_player] Updating spotify media_player took longer than the scheduled update interval 0:00:30
2022-02-05 21:04:41 ERROR (SyncWorker_0) [spotipy.client] Max Retries reached
2022-02-05 21:05:20 WARNING (MainThread) [homeassistant.helpers.entity] Update of media_player.spotify_mgerasika_gmail_com is taking over 10 seconds
2022-02-05 21:05:29 ERROR (MainThread) [homeassistant.components.github] Bad credentials
Traceback (most recent call last):
  File "/usr/src/homeassistant/homeassistant/components/github/coordinator.py", line 65, in _async_update_data
    response = await self.fetch_data()
  File "/usr/src/homeassistant/homeassistant/components/github/coordinator.py", line 93, in fetch_data
    return await self._client.repos.get(self.repository, **{"etag": self._etag})
  File "/usr/local/lib/python3.9/site-packages/aiogithubapi/namespaces/repos.py", line 82, in get
    response = await self._client.async_call_api(
  File "/usr/local/lib/python3.9/site-packages/aiogithubapi/client.py", line 134, in async_call_api
    raise exception(message or response.data)
aiogithubapi.exceptions.GitHubAuthenticationException: Bad credentials
2022-02-05 21:05:40 WARNING (MainThread) [homeassistant.components.media_player] Updating spotify media_player took longer than the scheduled update interval 0:00:30
2022-02-05 21:05:40 WARNING (Thread-3) [custom_components.ble_monitor.ble_parser.xiaomi] Decryption failed: MAC check failed
2022-02-05 21:05:41 ERROR (SyncWorker_3) [spotipy.client] Max Retries reached
2022-02-05 21:06:20 WARNING (MainThread) [homeassistant.helpers.entity] Update of media_player.spotify_mgerasika_gmail_com is taking over 10 seconds
2022-02-05 21:06:40 WARNING (MainThread) [homeassistant.components.media_player] Updating spotify media_player took longer than the scheduled update interval 0:00:30
2022-02-05 21:06:41 ERROR (SyncWorker_0) [spotipy.client] Max Retries reached
2022-02-05 21:06:50 ERROR (MainThread) [homeassistant.components.github] Bad credentials
Traceback (most recent call last):
  File "/usr/src/homeassistant/homeassistant/components/github/coordinator.py", line 65, in _async_update_data
    response = await self.fetch_data()
  File "/usr/src/homeassistant/homeassistant/components/github/coordinator.py", line 93, in fetch_data
    return await self._client.repos.get(self.repository, **{"etag": self._etag})
  File "/usr/local/lib/python3.9/site-packages/aiogithubapi/namespaces/repos.py", line 82, in get
    response = await self._client.async_call_api(
  File "/usr/local/lib/python3.9/site-packages/aiogithubapi/client.py", line 134, in async_call_api
    raise exception(message or response.data)
aiogithubapi.exceptions.GitHubAuthenticationException: Bad credentials
2022-02-05 21:07:20 WARNING (MainThread) [homeassistant.helpers.entity] Update of media_player.spotify_mgerasika_gmail_com is taking over 10 seconds
2022-02-05 21:07:40 WARNING (MainThread) [homeassistant.components.media_player] Updating spotify media_player took longer than the scheduled update interval 0:00:30
2022-02-05 21:07:41 ERROR (SyncWorker_2) [spotipy.client] Max Retries reached
2022-02-05 21:08:10 ERROR (MainThread) [homeassistant.components.github] Bad credentials
Traceback (most recent call last):
  File "/usr/src/homeassistant/homeassistant/components/github/coordinator.py", line 65, in _async_update_data
    response = await self.fetch_data()
  File "/usr/src/homeassistant/homeassistant/components/github/coordinator.py", line 93, in fetch_data
    return await self._client.repos.get(self.repository, **{"etag": self._etag})
  File "/usr/local/lib/python3.9/site-packages/aiogithubapi/namespaces/repos.py", line 82, in get
    response = await self._client.async_call_api(
  File "/usr/local/lib/python3.9/site-packages/aiogithubapi/client.py", line 134, in async_call_api
    raise exception(message or response.data)
aiogithubapi.exceptions.GitHubAuthenticationException: Bad credentials
2022-02-05 21:08:20 WARNING (MainThread) [homeassistant.helpers.entity] Update of media_player.spotify_mgerasika_gmail_com is taking over 10 seconds
2022-02-05 21:08:40 WARNING (MainThread) [homeassistant.components.media_player] Updating spotify media_player took longer than the scheduled update interval 0:00:30
2022-02-05 21:08:41 ERROR (SyncWorker_2) [spotipy.client] Max Retries reached
2022-02-05 21:09:20 WARNING (MainThread) [homeassistant.helpers.entity] Update of media_player.spotify_mgerasika_gmail_com is taking over 10 seconds
2022-02-05 21:09:24 ERROR (Thread-3) [custom_components.ble_monitor.ble_parser.xiaomi] No encryption key found for device with MAC A4:C1:38:BE:4C:FB
2022-02-05 21:09:30 ERROR (MainThread) [homeassistant.components.github] Bad credentials
Traceback (most recent call last):
  File "/usr/src/homeassistant/homeassistant/components/github/coordinator.py", line 65, in _async_update_data
    response = await self.fetch_data()
  File "/usr/src/homeassistant/homeassistant/components/github/coordinator.py", line 93, in fetch_data
    return await self._client.repos.get(self.repository, **{"etag": self._etag})
  File "/usr/local/lib/python3.9/site-packages/aiogithubapi/namespaces/repos.py", line 82, in get
    response = await self._client.async_call_api(
  File "/usr/local/lib/python3.9/site-packages/aiogithubapi/client.py", line 134, in async_call_api
    raise exception(message or response.data)
aiogithubapi.exceptions.GitHubAuthenticationException: Bad credentials
2022-02-05 21:09:40 WARNING (MainThread) [homeassistant.components.media_player] Updating spotify media_player took longer than the scheduled update interval 0:00:30
2022-02-05 21:10:10 WARNING (MainThread) [homeassistant.components.media_player] Updating spotify media_player took longer than the scheduled update interval 0:00:30
2022-02-05 21:10:23 ERROR (Thread-3) [custom_components.ble_monitor.ble_parser.xiaomi] No encryption key found for device with MAC A4:C1:38:BE:4C:FB
2022-02-05 21:10:50 WARNING (MainThread) [homeassistant.helpers.entity] Update of media_player.spotify_mgerasika_gmail_com is taking over 10 seconds
2022-02-05 21:10:50 ERROR (MainThread) [homeassistant.components.github] Bad credentials
Traceback (most recent call last):
  File "/usr/src/homeassistant/homeassistant/components/github/coordinator.py", line 65, in _async_update_data
    response = await self.fetch_data()
  File "/usr/src/homeassistant/homeassistant/components/github/coordinator.py", line 93, in fetch_data
    return await self._client.repos.get(self.repository, **{"etag": self._etag})
  File "/usr/local/lib/python3.9/site-packages/aiogithubapi/namespaces/repos.py", line 82, in get
    response = await self._client.async_call_api(
  File "/usr/local/lib/python3.9/site-packages/aiogithubapi/client.py", line 134, in async_call_api
    raise exception(message or response.data)
aiogithubapi.exceptions.GitHubAuthenticationException: Bad credentials
2022-02-05 21:11:10 WARNING (MainThread) [homeassistant.components.media_player] Updating spotify media_player took longer than the scheduled update interval 0:00:30
2022-02-05 21:11:11 ERROR (SyncWorker_0) [spotipy.client] Max Retries reached
2022-02-05 21:11:50 WARNING (MainThread) [homeassistant.helpers.entity] Update of media_player.spotify_mgerasika_gmail_com is taking over 10 seconds
2022-02-05 21:12:10 WARNING (MainThread) [homeassistant.components.media_player] Updating spotify media_player took longer than the scheduled update interval 0:00:30
2022-02-05 21:12:11 ERROR (MainThread) [homeassistant.components.github] Bad credentials
Traceback (most recent call last):
  File "/usr/src/homeassistant/homeassistant/components/github/coordinator.py", line 65, in _async_update_data
    response = await self.fetch_data()
  File "/usr/src/homeassistant/homeassistant/components/github/coordinator.py", line 93, in fetch_data
    return await self._client.repos.get(self.repository, **{"etag": self._etag})
  File "/usr/local/lib/python3.9/site-packages/aiogithubapi/namespaces/repos.py", line 82, in get
    response = await self._client.async_call_api(
  File "/usr/local/lib/python3.9/site-packages/aiogithubapi/client.py", line 134, in async_call_api
    raise exception(message or response.data)
aiogithubapi.exceptions.GitHubAuthenticationException: Bad credentials
2022-02-05 21:12:11 ERROR (SyncWorker_0) [spotipy.client] Max Retries reached
2022-02-05 21:12:43 ERROR (MainThread) [homeassistant.components.hassio.handler] Timeout on /homeassistant/restart request
