2022-02-05 20:21:52 WARNING (SyncWorker_0) [homeassistant.loader] We found a custom integration ble_monitor which has not been tested by Home Assistant. This component might cause stability problems, be sure to disable it if you experience issues with Home Assistant
2022-02-05 20:21:52 WARNING (SyncWorker_1) [homeassistant.loader] We found a custom integration hacs which has not been tested by Home Assistant. This component might cause stability problems, be sure to disable it if you experience issues with Home Assistant
2022-02-05 20:21:53 WARNING (Recorder) [homeassistant.components.recorder.util] The system could not validate that the sqlite3 database at //config/home-assistant_v2.db was shutdown cleanly
2022-02-05 20:21:53 WARNING (Recorder) [homeassistant.components.recorder.util] Ended unfinished session (id=7 from 2022-02-05 16:49:41.055386)
2022-02-05 20:21:59 WARNING (MainThread) [homeassistant.helpers.frame] Detected code that uses str (diagnostic) for entity category. This is deprecated and will stop working in Home Assistant 2022.4, it should be updated to use EntityCategory instead. Please report this issue.
Stack (most recent call last):
  File "/usr/local/lib/python3.9/runpy.py", line 197, in _run_module_as_main
    return _run_code(code, main_globals, None,
  File "/usr/local/lib/python3.9/runpy.py", line 87, in _run_code
    exec(code, run_globals)
  File "/usr/src/homeassistant/homeassistant/__main__.py", line 203, in <module>
    sys.exit(main())
  File "/usr/src/homeassistant/homeassistant/__main__.py", line 191, in main
    exit_code = runner.run(runtime_conf)
  File "/usr/src/homeassistant/homeassistant/runner.py", line 119, in run
    return loop.run_until_complete(setup_and_run_hass(runtime_config))
  File "/usr/local/lib/python3.9/asyncio/base_events.py", line 629, in run_until_complete
    self.run_forever()
  File "/usr/local/lib/python3.9/asyncio/base_events.py", line 596, in run_forever
    self._run_once()
  File "/usr/local/lib/python3.9/asyncio/base_events.py", line 1890, in _run_once
    handle._run()
  File "/usr/local/lib/python3.9/asyncio/events.py", line 80, in _run
    self._context.run(self._callback, *self._args)
  File "/usr/src/homeassistant/homeassistant/helpers/entity_platform.py", line 510, in _async_add_entity
    entry = entity_registry.async_get_or_create(
  File "/usr/src/homeassistant/homeassistant/helpers/entity_registry.py", line 401, in async_get_or_create
    entity_category=_convert_to_entity_category(entity_category),
  File "/usr/src/homeassistant/homeassistant/helpers/entity_registry.py", line 103, in _convert_to_entity_category
    return convert_to_entity_category(value, raise_report=raise_report)
  File "/usr/src/homeassistant/homeassistant/helpers/entity.py", line 214, in convert_to_entity_category
    report(
  File "/usr/src/homeassistant/homeassistant/helpers/frame.py", line 74, in report
    _LOGGER.warning(msg, stack_info=True)
Stack (most recent call last):
  File "/usr/local/lib/python3.9/runpy.py", line 197, in _run_module_as_main
    return _run_code(code, main_globals, None,
  File "/usr/local/lib/python3.9/runpy.py", line 87, in _run_code
    exec(code, run_globals)
  File "/usr/src/homeassistant/homeassistant/__main__.py", line 203, in <module>
    sys.exit(main())
  File "/usr/src/homeassistant/homeassistant/__main__.py", line 191, in main
    exit_code = runner.run(runtime_conf)
  File "/usr/src/homeassistant/homeassistant/runner.py", line 119, in run
    return loop.run_until_complete(setup_and_run_hass(runtime_config))
  File "/usr/local/lib/python3.9/asyncio/base_events.py", line 629, in run_until_complete
    self.run_forever()
  File "/usr/local/lib/python3.9/asyncio/base_events.py", line 596, in run_forever
    self._run_once()
  File "/usr/local/lib/python3.9/asyncio/base_events.py", line 1890, in _run_once
    handle._run()
  File "/usr/local/lib/python3.9/asyncio/events.py", line 80, in _run
    self._context.run(self._callback, *self._args)
  File "/usr/src/homeassistant/homeassistant/helpers/entity_platform.py", line 510, in _async_add_entity
    entry = entity_registry.async_get_or_create(
  File "/usr/src/homeassistant/homeassistant/helpers/entity_registry.py", line 401, in async_get_or_create
    entity_category=_convert_to_entity_category(entity_category),
  File "/usr/src/homeassistant/homeassistant/helpers/entity_registry.py", line 103, in _convert_to_entity_category
    return convert_to_entity_category(value, raise_report=raise_report)
  File "/usr/src/homeassistant/homeassistant/helpers/entity.py", line 214, in convert_to_entity_category
    report(
  File "/usr/src/homeassistant/homeassistant/helpers/frame.py", line 74, in report
    _LOGGER.warning(msg, stack_info=True)
2022-02-05 20:21:59 WARNING (MainThread) [homeassistant.helpers.frame] Detected code that uses str (diagnostic) for entity category. This is deprecated and will stop working in Home Assistant 2022.4, it should be updated to use EntityCategory instead. Please report this issue.
Stack (most recent call last):
  File "/usr/local/lib/python3.9/runpy.py", line 197, in _run_module_as_main
    return _run_code(code, main_globals, None,
  File "/usr/local/lib/python3.9/runpy.py", line 87, in _run_code
    exec(code, run_globals)
  File "/usr/src/homeassistant/homeassistant/__main__.py", line 203, in <module>
    sys.exit(main())
  File "/usr/src/homeassistant/homeassistant/__main__.py", line 191, in main
    exit_code = runner.run(runtime_conf)
  File "/usr/src/homeassistant/homeassistant/runner.py", line 119, in run
    return loop.run_until_complete(setup_and_run_hass(runtime_config))
  File "/usr/local/lib/python3.9/asyncio/base_events.py", line 629, in run_until_complete
    self.run_forever()
  File "/usr/local/lib/python3.9/asyncio/base_events.py", line 596, in run_forever
    self._run_once()
  File "/usr/local/lib/python3.9/asyncio/base_events.py", line 1890, in _run_once
    handle._run()
  File "/usr/local/lib/python3.9/asyncio/events.py", line 80, in _run
    self._context.run(self._callback, *self._args)
  File "/usr/src/homeassistant/homeassistant/helpers/entity_platform.py", line 510, in _async_add_entity
    entry = entity_registry.async_get_or_create(
  File "/usr/src/homeassistant/homeassistant/helpers/entity_registry.py", line 401, in async_get_or_create
    entity_category=_convert_to_entity_category(entity_category),
  File "/usr/src/homeassistant/homeassistant/helpers/entity_registry.py", line 103, in _convert_to_entity_category
    return convert_to_entity_category(value, raise_report=raise_report)
  File "/usr/src/homeassistant/homeassistant/helpers/entity.py", line 214, in convert_to_entity_category
    report(
  File "/usr/src/homeassistant/homeassistant/helpers/frame.py", line 74, in report
    _LOGGER.warning(msg, stack_info=True)
Stack (most recent call last):
  File "/usr/local/lib/python3.9/runpy.py", line 197, in _run_module_as_main
    return _run_code(code, main_globals, None,
  File "/usr/local/lib/python3.9/runpy.py", line 87, in _run_code
    exec(code, run_globals)
  File "/usr/src/homeassistant/homeassistant/__main__.py", line 203, in <module>
    sys.exit(main())
  File "/usr/src/homeassistant/homeassistant/__main__.py", line 191, in main
    exit_code = runner.run(runtime_conf)
  File "/usr/src/homeassistant/homeassistant/runner.py", line 119, in run
    return loop.run_until_complete(setup_and_run_hass(runtime_config))
  File "/usr/local/lib/python3.9/asyncio/base_events.py", line 629, in run_until_complete
    self.run_forever()
  File "/usr/local/lib/python3.9/asyncio/base_events.py", line 596, in run_forever
    self._run_once()
  File "/usr/local/lib/python3.9/asyncio/base_events.py", line 1890, in _run_once
    handle._run()
  File "/usr/local/lib/python3.9/asyncio/events.py", line 80, in _run
    self._context.run(self._callback, *self._args)
  File "/usr/src/homeassistant/homeassistant/helpers/entity_platform.py", line 510, in _async_add_entity
    entry = entity_registry.async_get_or_create(
  File "/usr/src/homeassistant/homeassistant/helpers/entity_registry.py", line 401, in async_get_or_create
    entity_category=_convert_to_entity_category(entity_category),
  File "/usr/src/homeassistant/homeassistant/helpers/entity_registry.py", line 103, in _convert_to_entity_category
    return convert_to_entity_category(value, raise_report=raise_report)
  File "/usr/src/homeassistant/homeassistant/helpers/entity.py", line 214, in convert_to_entity_category
    report(
  File "/usr/src/homeassistant/homeassistant/helpers/frame.py", line 74, in report
    _LOGGER.warning(msg, stack_info=True)
2022-02-05 20:21:59 WARNING (MainThread) [homeassistant.helpers.frame] Detected code that uses str (diagnostic) for entity category. This is deprecated and will stop working in Home Assistant 2022.4, it should be updated to use EntityCategory instead. Please report this issue.
Stack (most recent call last):
  File "/usr/local/lib/python3.9/runpy.py", line 197, in _run_module_as_main
    return _run_code(code, main_globals, None,
  File "/usr/local/lib/python3.9/runpy.py", line 87, in _run_code
    exec(code, run_globals)
  File "/usr/src/homeassistant/homeassistant/__main__.py", line 203, in <module>
    sys.exit(main())
  File "/usr/src/homeassistant/homeassistant/__main__.py", line 191, in main
    exit_code = runner.run(runtime_conf)
  File "/usr/src/homeassistant/homeassistant/runner.py", line 119, in run
    return loop.run_until_complete(setup_and_run_hass(runtime_config))
  File "/usr/local/lib/python3.9/asyncio/base_events.py", line 629, in run_until_complete
    self.run_forever()
  File "/usr/local/lib/python3.9/asyncio/base_events.py", line 596, in run_forever
    self._run_once()
  File "/usr/local/lib/python3.9/asyncio/base_events.py", line 1890, in _run_once
    handle._run()
  File "/usr/local/lib/python3.9/asyncio/events.py", line 80, in _run
    self._context.run(self._callback, *self._args)
  File "/usr/src/homeassistant/homeassistant/helpers/entity_platform.py", line 510, in _async_add_entity
    entry = entity_registry.async_get_or_create(
  File "/usr/src/homeassistant/homeassistant/helpers/entity_registry.py", line 401, in async_get_or_create
    entity_category=_convert_to_entity_category(entity_category),
  File "/usr/src/homeassistant/homeassistant/helpers/entity_registry.py", line 103, in _convert_to_entity_category
    return convert_to_entity_category(value, raise_report=raise_report)
  File "/usr/src/homeassistant/homeassistant/helpers/entity.py", line 214, in convert_to_entity_category
    report(
  File "/usr/src/homeassistant/homeassistant/helpers/frame.py", line 74, in report
    _LOGGER.warning(msg, stack_info=True)
Stack (most recent call last):
  File "/usr/local/lib/python3.9/runpy.py", line 197, in _run_module_as_main
    return _run_code(code, main_globals, None,
  File "/usr/local/lib/python3.9/runpy.py", line 87, in _run_code
    exec(code, run_globals)
  File "/usr/src/homeassistant/homeassistant/__main__.py", line 203, in <module>
    sys.exit(main())
  File "/usr/src/homeassistant/homeassistant/__main__.py", line 191, in main
    exit_code = runner.run(runtime_conf)
  File "/usr/src/homeassistant/homeassistant/runner.py", line 119, in run
    return loop.run_until_complete(setup_and_run_hass(runtime_config))
  File "/usr/local/lib/python3.9/asyncio/base_events.py", line 629, in run_until_complete
    self.run_forever()
  File "/usr/local/lib/python3.9/asyncio/base_events.py", line 596, in run_forever
    self._run_once()
  File "/usr/local/lib/python3.9/asyncio/base_events.py", line 1890, in _run_once
    handle._run()
  File "/usr/local/lib/python3.9/asyncio/events.py", line 80, in _run
    self._context.run(self._callback, *self._args)
  File "/usr/src/homeassistant/homeassistant/helpers/entity_platform.py", line 510, in _async_add_entity
    entry = entity_registry.async_get_or_create(
  File "/usr/src/homeassistant/homeassistant/helpers/entity_registry.py", line 401, in async_get_or_create
    entity_category=_convert_to_entity_category(entity_category),
  File "/usr/src/homeassistant/homeassistant/helpers/entity_registry.py", line 103, in _convert_to_entity_category
    return convert_to_entity_category(value, raise_report=raise_report)
  File "/usr/src/homeassistant/homeassistant/helpers/entity.py", line 214, in convert_to_entity_category
    report(
  File "/usr/src/homeassistant/homeassistant/helpers/frame.py", line 74, in report
    _LOGGER.warning(msg, stack_info=True)
2022-02-05 20:22:00 ERROR (MainThread) [homeassistant.components.github] Bad credentials
Traceback (most recent call last):
  File "/usr/src/homeassistant/homeassistant/components/github/coordinator.py", line 65, in _async_update_data
    response = await self.fetch_data()
  File "/usr/src/homeassistant/homeassistant/components/github/coordinator.py", line 93, in fetch_data
    return await self._client.repos.get(self.repository, **{"etag": self._etag})
  File "/usr/local/lib/python3.9/site-packages/aiogithubapi/namespaces/repos.py", line 82, in get
    response = await self._client.async_call_api(
  File "/usr/local/lib/python3.9/site-packages/aiogithubapi/client.py", line 134, in async_call_api
    raise exception(message or response.data)
aiogithubapi.exceptions.GitHubAuthenticationException: Bad credentials
2022-02-05 20:22:00 WARNING (MainThread) [homeassistant.config_entries] Config entry '' for github integration not ready yet: Bad credentials; Retrying in background
2022-02-05 20:22:01 ERROR (MainThread) [custom_components.hacs] HACS is disabled - HacsDisabledReason.INVALID_TOKEN
2022-02-05 20:22:01 ERROR (MainThread) [custom_components.hacs] Bad credentials
Traceback (most recent call last):
  File "/config/custom_components/hacs/base.py", line 428, in async_can_update
    response = await self.async_github_api_method(self.githubapi.rate_limit)
  File "/config/custom_components/hacs/base.py", line 479, in async_github_api_method
    raise HacsException(_exception)
custom_components.hacs.exceptions.HacsException: Bad credentials
2022-02-05 20:22:21 WARNING (MainThread) [homeassistant.components.media_player] Setup of media_player platform spotify is taking over 10 seconds.
2022-02-05 20:22:26 ERROR (Thread-3) [custom_components.ble_monitor.ble_parser.xiaomi] No encryption key found for device with MAC A4:C1:38:57:29:B5
2022-02-05 20:22:46 ERROR (Thread-3) [custom_components.ble_monitor.ble_parser.xiaomi] No encryption key found for device with MAC A4:C1:38:DF:06:52
2022-02-05 20:22:48 ERROR (Thread-3) [custom_components.ble_monitor.ble_parser.xiaomi] No encryption key found for device with MAC A4:C1:38:28:A0:32
2022-02-05 20:22:54 WARNING (MainThread) [homeassistant.bootstrap] Waiting on integrations to complete setup: media_player.spotify
2022-02-05 20:23:10 ERROR (SyncWorker_4) [spotipy.client] Max Retries reached
2022-02-05 20:23:11 ERROR (MainThread) [homeassistant.components.github] Bad credentials
Traceback (most recent call last):
  File "/usr/src/homeassistant/homeassistant/components/github/coordinator.py", line 65, in _async_update_data
    response = await self.fetch_data()
  File "/usr/src/homeassistant/homeassistant/components/github/coordinator.py", line 93, in fetch_data
    return await self._client.repos.get(self.repository, **{"etag": self._etag})
  File "/usr/local/lib/python3.9/site-packages/aiogithubapi/namespaces/repos.py", line 82, in get
    response = await self._client.async_call_api(
  File "/usr/local/lib/python3.9/site-packages/aiogithubapi/client.py", line 134, in async_call_api
    raise exception(message or response.data)
aiogithubapi.exceptions.GitHubAuthenticationException: Bad credentials
2022-02-05 20:23:22 ERROR (MainThread) [homeassistant.components.github] Bad credentials
Traceback (most recent call last):
  File "/usr/src/homeassistant/homeassistant/components/github/coordinator.py", line 65, in _async_update_data
    response = await self.fetch_data()
  File "/usr/src/homeassistant/homeassistant/components/github/coordinator.py", line 93, in fetch_data
    return await self._client.repos.get(self.repository, **{"etag": self._etag})
  File "/usr/local/lib/python3.9/site-packages/aiogithubapi/namespaces/repos.py", line 82, in get
    response = await self._client.async_call_api(
  File "/usr/local/lib/python3.9/site-packages/aiogithubapi/client.py", line 134, in async_call_api
    raise exception(message or response.data)
aiogithubapi.exceptions.GitHubAuthenticationException: Bad credentials
2022-02-05 20:23:24 ERROR (Thread-3) [custom_components.ble_monitor.ble_parser.xiaomi] No encryption key found for device with MAC A4:C1:38:57:29:B5
2022-02-05 20:23:42 ERROR (MainThread) [homeassistant.components.github] Bad credentials
Traceback (most recent call last):
  File "/usr/src/homeassistant/homeassistant/components/github/coordinator.py", line 65, in _async_update_data
    response = await self.fetch_data()
  File "/usr/src/homeassistant/homeassistant/components/github/coordinator.py", line 93, in fetch_data
    return await self._client.repos.get(self.repository, **{"etag": self._etag})
  File "/usr/local/lib/python3.9/site-packages/aiogithubapi/namespaces/repos.py", line 82, in get
    response = await self._client.async_call_api(
  File "/usr/local/lib/python3.9/site-packages/aiogithubapi/client.py", line 134, in async_call_api
    raise exception(message or response.data)
aiogithubapi.exceptions.GitHubAuthenticationException: Bad credentials
2022-02-05 20:23:45 ERROR (Thread-3) [custom_components.ble_monitor.ble_parser.xiaomi] No encryption key found for device with MAC A4:C1:38:DF:06:52
2022-02-05 20:23:50 WARNING (MainThread) [homeassistant.helpers.entity] Update of media_player.spotify_mgerasika_gmail_com is taking over 10 seconds
2022-02-05 20:24:10 WARNING (MainThread) [homeassistant.components.media_player] Updating spotify media_player took longer than the scheduled update interval 0:00:30
2022-02-05 20:24:11 ERROR (SyncWorker_1) [spotipy.client] Max Retries reached
2022-02-05 20:24:22 ERROR (MainThread) [homeassistant.components.github] Bad credentials
Traceback (most recent call last):
  File "/usr/src/homeassistant/homeassistant/components/github/coordinator.py", line 65, in _async_update_data
    response = await self.fetch_data()
  File "/usr/src/homeassistant/homeassistant/components/github/coordinator.py", line 93, in fetch_data
    return await self._client.repos.get(self.repository, **{"etag": self._etag})
  File "/usr/local/lib/python3.9/site-packages/aiogithubapi/namespaces/repos.py", line 82, in get
    response = await self._client.async_call_api(
  File "/usr/local/lib/python3.9/site-packages/aiogithubapi/client.py", line 134, in async_call_api
    raise exception(message or response.data)
aiogithubapi.exceptions.GitHubAuthenticationException: Bad credentials
2022-02-05 20:24:50 WARNING (MainThread) [homeassistant.helpers.entity] Update of media_player.spotify_mgerasika_gmail_com is taking over 10 seconds
2022-02-05 20:25:10 WARNING (MainThread) [homeassistant.components.media_player] Updating spotify media_player took longer than the scheduled update interval 0:00:30
2022-02-05 20:25:11 ERROR (SyncWorker_2) [spotipy.client] Max Retries reached
2022-02-05 20:25:15 ERROR (Thread-3) [custom_components.ble_monitor.ble_parser.xiaomi] No encryption key found for device with MAC A4:C1:38:28:BD:62
2022-02-05 20:25:25 ERROR (Thread-3) [custom_components.ble_monitor.ble_parser.xiaomi] No encryption key found for device with MAC A4:C1:38:BE:4C:FB
2022-02-05 20:25:38 ERROR (Thread-3) [custom_components.ble_monitor.ble_parser.xiaomi] No encryption key found for device with MAC A4:C1:38:1D:62:4B
2022-02-05 20:25:43 ERROR (MainThread) [homeassistant.components.github] Bad credentials
Traceback (most recent call last):
  File "/usr/src/homeassistant/homeassistant/components/github/coordinator.py", line 65, in _async_update_data
    response = await self.fetch_data()
  File "/usr/src/homeassistant/homeassistant/components/github/coordinator.py", line 93, in fetch_data
    return await self._client.repos.get(self.repository, **{"etag": self._etag})
  File "/usr/local/lib/python3.9/site-packages/aiogithubapi/namespaces/repos.py", line 82, in get
    response = await self._client.async_call_api(
  File "/usr/local/lib/python3.9/site-packages/aiogithubapi/client.py", line 134, in async_call_api
    raise exception(message or response.data)
aiogithubapi.exceptions.GitHubAuthenticationException: Bad credentials
2022-02-05 20:25:50 WARNING (MainThread) [homeassistant.helpers.entity] Update of media_player.spotify_mgerasika_gmail_com is taking over 10 seconds
2022-02-05 20:25:54 ERROR (SyncWorker_3) [homeassistant.util.yaml.loader] while parsing a block mapping
  in "/config/ui-lovelace.yaml", line 8, column 9
expected <block end>, but found '-'
  in "/config/ui-lovelace.yaml", line 41, column 9
2022-02-05 20:26:10 WARNING (MainThread) [homeassistant.components.media_player] Updating spotify media_player took longer than the scheduled update interval 0:00:30
2022-02-05 20:26:11 ERROR (SyncWorker_4) [spotipy.client] Max Retries reached
2022-02-05 20:26:25 ERROR (Thread-3) [custom_components.ble_monitor.ble_parser.xiaomi] No encryption key found for device with MAC A4:C1:38:BE:4C:FB
2022-02-05 20:26:37 ERROR (Thread-3) [custom_components.ble_monitor.ble_parser.xiaomi] No encryption key found for device with MAC A4:C1:38:1D:62:4B
2022-02-05 20:26:50 WARNING (MainThread) [homeassistant.helpers.entity] Update of media_player.spotify_mgerasika_gmail_com is taking over 10 seconds
2022-02-05 20:27:03 ERROR (MainThread) [homeassistant.components.github] Bad credentials
Traceback (most recent call last):
  File "/usr/src/homeassistant/homeassistant/components/github/coordinator.py", line 65, in _async_update_data
    response = await self.fetch_data()
  File "/usr/src/homeassistant/homeassistant/components/github/coordinator.py", line 93, in fetch_data
    return await self._client.repos.get(self.repository, **{"etag": self._etag})
  File "/usr/local/lib/python3.9/site-packages/aiogithubapi/namespaces/repos.py", line 82, in get
    response = await self._client.async_call_api(
  File "/usr/local/lib/python3.9/site-packages/aiogithubapi/client.py", line 134, in async_call_api
    raise exception(message or response.data)
aiogithubapi.exceptions.GitHubAuthenticationException: Bad credentials
2022-02-05 20:27:10 WARNING (MainThread) [homeassistant.components.media_player] Updating spotify media_player took longer than the scheduled update interval 0:00:30
2022-02-05 20:27:12 ERROR (SyncWorker_3) [spotipy.client] Max Retries reached
2022-02-05 20:27:36 ERROR (Thread-3) [custom_components.ble_monitor.ble_parser.xiaomi] No encryption key found for device with MAC A4:C1:38:C0:F4:B7
2022-02-05 20:27:50 WARNING (MainThread) [homeassistant.helpers.entity] Update of media_player.spotify_mgerasika_gmail_com is taking over 10 seconds
2022-02-05 20:28:10 WARNING (MainThread) [homeassistant.components.media_player] Updating spotify media_player took longer than the scheduled update interval 0:00:30
2022-02-05 20:28:11 ERROR (SyncWorker_2) [spotipy.client] Max Retries reached
2022-02-05 20:28:23 ERROR (MainThread) [homeassistant.components.github] Bad credentials
Traceback (most recent call last):
  File "/usr/src/homeassistant/homeassistant/components/github/coordinator.py", line 65, in _async_update_data
    response = await self.fetch_data()
  File "/usr/src/homeassistant/homeassistant/components/github/coordinator.py", line 93, in fetch_data
    return await self._client.repos.get(self.repository, **{"etag": self._etag})
  File "/usr/local/lib/python3.9/site-packages/aiogithubapi/namespaces/repos.py", line 82, in get
    response = await self._client.async_call_api(
  File "/usr/local/lib/python3.9/site-packages/aiogithubapi/client.py", line 134, in async_call_api
    raise exception(message or response.data)
aiogithubapi.exceptions.GitHubAuthenticationException: Bad credentials
2022-02-05 20:28:35 ERROR (Thread-3) [custom_components.ble_monitor.ble_parser.xiaomi] No encryption key found for device with MAC A4:C1:38:C0:F4:B7
2022-02-05 20:28:38 ERROR (Thread-3) [custom_components.ble_monitor.ble_parser.xiaomi] No encryption key found for device with MAC A4:C1:38:C0:F4:B7
2022-02-05 20:28:50 WARNING (MainThread) [homeassistant.helpers.entity] Update of media_player.spotify_mgerasika_gmail_com is taking over 10 seconds
2022-02-05 20:29:09 ERROR (Thread-3) [custom_components.ble_monitor.ble_parser.xiaomi] No encryption key found for device with MAC A4:C1:38:49:72:BA
2022-02-05 20:29:10 WARNING (MainThread) [homeassistant.components.media_player] Updating spotify media_player took longer than the scheduled update interval 0:00:30
2022-02-05 20:29:11 ERROR (SyncWorker_1) [spotipy.client] Max Retries reached
2022-02-05 20:29:43 ERROR (MainThread) [homeassistant.components.github] Bad credentials
Traceback (most recent call last):
  File "/usr/src/homeassistant/homeassistant/components/github/coordinator.py", line 65, in _async_update_data
    response = await self.fetch_data()
  File "/usr/src/homeassistant/homeassistant/components/github/coordinator.py", line 93, in fetch_data
    return await self._client.repos.get(self.repository, **{"etag": self._etag})
  File "/usr/local/lib/python3.9/site-packages/aiogithubapi/namespaces/repos.py", line 82, in get
    response = await self._client.async_call_api(
  File "/usr/local/lib/python3.9/site-packages/aiogithubapi/client.py", line 134, in async_call_api
    raise exception(message or response.data)
aiogithubapi.exceptions.GitHubAuthenticationException: Bad credentials
2022-02-05 20:29:50 WARNING (MainThread) [homeassistant.helpers.entity] Update of media_player.spotify_mgerasika_gmail_com is taking over 10 seconds
2022-02-05 20:30:10 ERROR (Thread-3) [custom_components.ble_monitor.ble_parser.xiaomi] No encryption key found for device with MAC A4:C1:38:49:72:BA
2022-02-05 20:30:10 WARNING (MainThread) [homeassistant.components.media_player] Updating spotify media_player took longer than the scheduled update interval 0:00:30
2022-02-05 20:30:11 ERROR (SyncWorker_2) [spotipy.client] Max Retries reached
2022-02-05 20:30:50 WARNING (MainThread) [homeassistant.helpers.entity] Update of media_player.spotify_mgerasika_gmail_com is taking over 10 seconds
2022-02-05 20:31:04 ERROR (MainThread) [homeassistant.components.github] Bad credentials
Traceback (most recent call last):
  File "/usr/src/homeassistant/homeassistant/components/github/coordinator.py", line 65, in _async_update_data
    response = await self.fetch_data()
  File "/usr/src/homeassistant/homeassistant/components/github/coordinator.py", line 93, in fetch_data
    return await self._client.repos.get(self.repository, **{"etag": self._etag})
  File "/usr/local/lib/python3.9/site-packages/aiogithubapi/namespaces/repos.py", line 82, in get
    response = await self._client.async_call_api(
  File "/usr/local/lib/python3.9/site-packages/aiogithubapi/client.py", line 134, in async_call_api
    raise exception(message or response.data)
aiogithubapi.exceptions.GitHubAuthenticationException: Bad credentials
2022-02-05 20:31:10 WARNING (MainThread) [homeassistant.components.media_player] Updating spotify media_player took longer than the scheduled update interval 0:00:30
2022-02-05 20:31:11 ERROR (SyncWorker_3) [spotipy.client] Max Retries reached
2022-02-05 20:31:50 WARNING (MainThread) [homeassistant.helpers.entity] Update of media_player.spotify_mgerasika_gmail_com is taking over 10 seconds
2022-02-05 20:32:10 WARNING (MainThread) [homeassistant.components.media_player] Updating spotify media_player took longer than the scheduled update interval 0:00:30
2022-02-05 20:32:24 ERROR (MainThread) [homeassistant.components.github] Bad credentials
Traceback (most recent call last):
  File "/usr/src/homeassistant/homeassistant/components/github/coordinator.py", line 65, in _async_update_data
    response = await self.fetch_data()
  File "/usr/src/homeassistant/homeassistant/components/github/coordinator.py", line 93, in fetch_data
    return await self._client.repos.get(self.repository, **{"etag": self._etag})
  File "/usr/local/lib/python3.9/site-packages/aiogithubapi/namespaces/repos.py", line 82, in get
    response = await self._client.async_call_api(
  File "/usr/local/lib/python3.9/site-packages/aiogithubapi/client.py", line 134, in async_call_api
    raise exception(message or response.data)
aiogithubapi.exceptions.GitHubAuthenticationException: Bad credentials
2022-02-05 20:32:40 WARNING (MainThread) [homeassistant.components.media_player] Updating spotify media_player took longer than the scheduled update interval 0:00:30
2022-02-05 20:32:42 ERROR (SyncWorker_2) [spotipy.client] Max Retries reached
2022-02-05 20:32:46 ERROR (Thread-3) [custom_components.ble_monitor.ble_parser.xiaomi] No encryption key found for device with MAC A4:C1:38:28:A0:32
2022-02-05 20:33:20 WARNING (MainThread) [homeassistant.helpers.entity] Update of media_player.spotify_mgerasika_gmail_com is taking over 10 seconds
2022-02-05 20:33:24 ERROR (Thread-3) [custom_components.ble_monitor.ble_parser.xiaomi] No encryption key found for device with MAC A4:C1:38:57:29:B5
2022-02-05 20:33:40 WARNING (MainThread) [homeassistant.components.media_player] Updating spotify media_player took longer than the scheduled update interval 0:00:30
2022-02-05 20:33:41 ERROR (SyncWorker_1) [spotipy.client] Max Retries reached
2022-02-05 20:33:44 ERROR (MainThread) [homeassistant.components.github] Bad credentials
Traceback (most recent call last):
  File "/usr/src/homeassistant/homeassistant/components/github/coordinator.py", line 65, in _async_update_data
    response = await self.fetch_data()
  File "/usr/src/homeassistant/homeassistant/components/github/coordinator.py", line 93, in fetch_data
    return await self._client.repos.get(self.repository, **{"etag": self._etag})
  File "/usr/local/lib/python3.9/site-packages/aiogithubapi/namespaces/repos.py", line 82, in get
    response = await self._client.async_call_api(
  File "/usr/local/lib/python3.9/site-packages/aiogithubapi/client.py", line 134, in async_call_api
    raise exception(message or response.data)
aiogithubapi.exceptions.GitHubAuthenticationException: Bad credentials
2022-02-05 20:33:44 ERROR (Thread-3) [custom_components.ble_monitor.ble_parser.xiaomi] No encryption key found for device with MAC A4:C1:38:DF:06:52
2022-02-05 20:33:45 ERROR (Thread-3) [custom_components.ble_monitor.ble_parser.xiaomi] No encryption key found for device with MAC A4:C1:38:28:A0:32
2022-02-05 20:34:09 ERROR (Thread-3) [custom_components.ble_monitor.ble_parser.xiaomi] No encryption key found for device with MAC A4:C1:38:49:72:BA
2022-02-05 20:34:20 WARNING (MainThread) [homeassistant.helpers.entity] Update of media_player.spotify_mgerasika_gmail_com is taking over 10 seconds
2022-02-05 20:34:24 ERROR (Thread-3) [custom_components.ble_monitor.ble_parser.xiaomi] No encryption key found for device with MAC A4:C1:38:57:29:B5
2022-02-05 20:34:40 WARNING (MainThread) [homeassistant.components.media_player] Updating spotify media_player took longer than the scheduled update interval 0:00:30
2022-02-05 20:34:41 ERROR (SyncWorker_0) [spotipy.client] Max Retries reached
2022-02-05 20:34:45 ERROR (Thread-3) [custom_components.ble_monitor.ble_parser.xiaomi] No encryption key found for device with MAC A4:C1:38:DF:06:52
2022-02-05 20:35:05 ERROR (MainThread) [homeassistant.components.github] Bad credentials
Traceback (most recent call last):
  File "/usr/src/homeassistant/homeassistant/components/github/coordinator.py", line 65, in _async_update_data
    response = await self.fetch_data()
  File "/usr/src/homeassistant/homeassistant/components/github/coordinator.py", line 93, in fetch_data
    return await self._client.repos.get(self.repository, **{"etag": self._etag})
  File "/usr/local/lib/python3.9/site-packages/aiogithubapi/namespaces/repos.py", line 82, in get
    response = await self._client.async_call_api(
  File "/usr/local/lib/python3.9/site-packages/aiogithubapi/client.py", line 134, in async_call_api
    raise exception(message or response.data)
aiogithubapi.exceptions.GitHubAuthenticationException: Bad credentials
2022-02-05 20:35:20 WARNING (MainThread) [homeassistant.helpers.entity] Update of media_player.spotify_mgerasika_gmail_com is taking over 10 seconds
2022-02-05 20:35:40 WARNING (MainThread) [homeassistant.components.media_player] Updating spotify media_player took longer than the scheduled update interval 0:00:30
2022-02-05 20:35:41 ERROR (SyncWorker_0) [spotipy.client] Max Retries reached
2022-02-05 20:36:13 ERROR (Thread-3) [custom_components.ble_monitor.ble_parser.xiaomi] No encryption key found for device with MAC A4:C1:38:6E:30:3F
2022-02-05 20:36:15 ERROR (Thread-3) [custom_components.ble_monitor.ble_parser.xiaomi] No encryption key found for device with MAC A4:C1:38:28:BD:62
2022-02-05 20:36:20 WARNING (MainThread) [homeassistant.helpers.entity] Update of media_player.spotify_mgerasika_gmail_com is taking over 10 seconds
2022-02-05 20:36:24 ERROR (Thread-3) [custom_components.ble_monitor.ble_parser.xiaomi] No encryption key found for device with MAC A4:C1:38:BE:4C:FB
2022-02-05 20:36:25 ERROR (MainThread) [homeassistant.components.github] Bad credentials
Traceback (most recent call last):
  File "/usr/src/homeassistant/homeassistant/components/github/coordinator.py", line 65, in _async_update_data
    response = await self.fetch_data()
  File "/usr/src/homeassistant/homeassistant/components/github/coordinator.py", line 93, in fetch_data
    return await self._client.repos.get(self.repository, **{"etag": self._etag})
  File "/usr/local/lib/python3.9/site-packages/aiogithubapi/namespaces/repos.py", line 82, in get
    response = await self._client.async_call_api(
  File "/usr/local/lib/python3.9/site-packages/aiogithubapi/client.py", line 134, in async_call_api
    raise exception(message or response.data)
aiogithubapi.exceptions.GitHubAuthenticationException: Bad credentials
2022-02-05 20:36:36 ERROR (Thread-3) [custom_components.ble_monitor.ble_parser.xiaomi] No encryption key found for device with MAC A4:C1:38:1D:62:4B
2022-02-05 20:36:40 WARNING (MainThread) [homeassistant.components.media_player] Updating spotify media_player took longer than the scheduled update interval 0:00:30
2022-02-05 20:36:41 ERROR (SyncWorker_4) [spotipy.client] Max Retries reached
2022-02-05 20:37:07 ERROR (MainThread) [custom_components.hacs] HACS is disabled - HacsDisabledReason.INVALID_TOKEN
2022-02-05 20:37:07 WARNING (MainThread) [custom_components.hacs] Could not load default repositories: Bad credentials, retrying in 5 minuttes
2022-02-05 20:37:12 ERROR (Thread-3) [custom_components.ble_monitor.ble_parser.xiaomi] No encryption key found for device with MAC A4:C1:38:6E:30:3F
2022-02-05 20:37:20 WARNING (MainThread) [homeassistant.helpers.entity] Update of media_player.spotify_mgerasika_gmail_com is taking over 10 seconds
2022-02-05 20:37:25 ERROR (Thread-3) [custom_components.ble_monitor.ble_parser.xiaomi] No encryption key found for device with MAC A4:C1:38:BE:4C:FB
2022-02-05 20:37:37 ERROR (Thread-3) [custom_components.ble_monitor.ble_parser.xiaomi] No encryption key found for device with MAC A4:C1:38:1D:62:4B
2022-02-05 20:37:40 WARNING (MainThread) [homeassistant.components.media_player] Updating spotify media_player took longer than the scheduled update interval 0:00:30
2022-02-05 20:37:41 ERROR (SyncWorker_4) [spotipy.client] Max Retries reached
2022-02-05 20:37:45 ERROR (MainThread) [homeassistant.components.github] Bad credentials
Traceback (most recent call last):
  File "/usr/src/homeassistant/homeassistant/components/github/coordinator.py", line 65, in _async_update_data
    response = await self.fetch_data()
  File "/usr/src/homeassistant/homeassistant/components/github/coordinator.py", line 93, in fetch_data
    return await self._client.repos.get(self.repository, **{"etag": self._etag})
  File "/usr/local/lib/python3.9/site-packages/aiogithubapi/namespaces/repos.py", line 82, in get
    response = await self._client.async_call_api(
  File "/usr/local/lib/python3.9/site-packages/aiogithubapi/client.py", line 134, in async_call_api
    raise exception(message or response.data)
aiogithubapi.exceptions.GitHubAuthenticationException: Bad credentials
2022-02-05 20:38:12 ERROR (Thread-3) [custom_components.ble_monitor.ble_parser.xiaomi] No encryption key found for device with MAC A4:C1:38:6E:30:3F
2022-02-05 20:38:20 WARNING (MainThread) [homeassistant.helpers.entity] Update of media_player.spotify_mgerasika_gmail_com is taking over 10 seconds
2022-02-05 20:38:34 ERROR (Thread-3) [custom_components.ble_monitor.ble_parser.xiaomi] No encryption key found for device with MAC A4:C1:38:C0:F4:B7
2022-02-05 20:38:40 WARNING (MainThread) [homeassistant.components.media_player] Updating spotify media_player took longer than the scheduled update interval 0:00:30
2022-02-05 20:38:41 ERROR (SyncWorker_4) [spotipy.client] Max Retries reached
2022-02-05 20:39:05 ERROR (MainThread) [homeassistant.components.github] Bad credentials
Traceback (most recent call last):
  File "/usr/src/homeassistant/homeassistant/components/github/coordinator.py", line 65, in _async_update_data
    response = await self.fetch_data()
  File "/usr/src/homeassistant/homeassistant/components/github/coordinator.py", line 93, in fetch_data
    return await self._client.repos.get(self.repository, **{"etag": self._etag})
  File "/usr/local/lib/python3.9/site-packages/aiogithubapi/namespaces/repos.py", line 82, in get
    response = await self._client.async_call_api(
  File "/usr/local/lib/python3.9/site-packages/aiogithubapi/client.py", line 134, in async_call_api
    raise exception(message or response.data)
aiogithubapi.exceptions.GitHubAuthenticationException: Bad credentials
2022-02-05 20:39:18 ERROR (MainThread) [homeassistant.components.hassio.handler] Timeout on /homeassistant/restart request
