2022-02-05 21:12:55 WARNING (SyncWorker_0) [homeassistant.loader] We found a custom integration ble_monitor which has not been tested by Home Assistant. This component might cause stability problems, be sure to disable it if you experience issues with Home Assistant
2022-02-05 21:12:55 WARNING (SyncWorker_0) [homeassistant.loader] We found a custom integration hacs which has not been tested by Home Assistant. This component might cause stability problems, be sure to disable it if you experience issues with Home Assistant
2022-02-05 21:13:02 ERROR (MainThread) [homeassistant.components.github] Bad credentials
Traceback (most recent call last):
  File "/usr/src/homeassistant/homeassistant/components/github/coordinator.py", line 65, in _async_update_data
    response = await self.fetch_data()
  File "/usr/src/homeassistant/homeassistant/components/github/coordinator.py", line 93, in fetch_data
    return await self._client.repos.get(self.repository, **{"etag": self._etag})
  File "/usr/local/lib/python3.9/site-packages/aiogithubapi/namespaces/repos.py", line 82, in get
    response = await self._client.async_call_api(
  File "/usr/local/lib/python3.9/site-packages/aiogithubapi/client.py", line 134, in async_call_api
    raise exception(message or response.data)
aiogithubapi.exceptions.GitHubAuthenticationException: Bad credentials
2022-02-05 21:13:02 WARNING (MainThread) [homeassistant.config_entries] Config entry '' for github integration not ready yet: Bad credentials; Retrying in background
2022-02-05 21:13:07 ERROR (MainThread) [custom_components.hacs] HACS is disabled - HacsDisabledReason.INVALID_TOKEN
2022-02-05 21:13:07 ERROR (MainThread) [custom_components.hacs] Bad credentials
Traceback (most recent call last):
  File "/config/custom_components/hacs/base.py", line 428, in async_can_update
    response = await self.async_github_api_method(self.githubapi.rate_limit)
  File "/config/custom_components/hacs/base.py", line 479, in async_github_api_method
    raise HacsException(_exception)
custom_components.hacs.exceptions.HacsException: Bad credentials
2022-02-05 21:13:51 WARNING (MainThread) [homeassistant.components.media_player] Setup of media_player platform spotify is taking over 10 seconds.
2022-02-05 21:13:59 WARNING (MainThread) [homeassistant.bootstrap] Waiting on integrations to complete setup: media_player.spotify
2022-02-05 21:14:11 ERROR (SyncWorker_0) [spotipy.client] Max Retries reached
2022-02-05 21:14:12 ERROR (MainThread) [homeassistant.components.github] Bad credentials
Traceback (most recent call last):
  File "/usr/src/homeassistant/homeassistant/components/github/coordinator.py", line 65, in _async_update_data
    response = await self.fetch_data()
  File "/usr/src/homeassistant/homeassistant/components/github/coordinator.py", line 93, in fetch_data
    return await self._client.repos.get(self.repository, **{"etag": self._etag})
  File "/usr/local/lib/python3.9/site-packages/aiogithubapi/namespaces/repos.py", line 82, in get
    response = await self._client.async_call_api(
  File "/usr/local/lib/python3.9/site-packages/aiogithubapi/client.py", line 134, in async_call_api
    raise exception(message or response.data)
aiogithubapi.exceptions.GitHubAuthenticationException: Bad credentials
2022-02-05 21:14:23 ERROR (Thread-3) [custom_components.ble_monitor.ble_parser.xiaomi] No encryption key found for device with MAC A4:C1:38:BE:4C:FB
2022-02-05 21:14:23 ERROR (MainThread) [homeassistant.components.github] Bad credentials
Traceback (most recent call last):
  File "/usr/src/homeassistant/homeassistant/components/github/coordinator.py", line 65, in _async_update_data
    response = await self.fetch_data()
  File "/usr/src/homeassistant/homeassistant/components/github/coordinator.py", line 93, in fetch_data
    return await self._client.repos.get(self.repository, **{"etag": self._etag})
  File "/usr/local/lib/python3.9/site-packages/aiogithubapi/namespaces/repos.py", line 82, in get
    response = await self._client.async_call_api(
  File "/usr/local/lib/python3.9/site-packages/aiogithubapi/client.py", line 134, in async_call_api
    raise exception(message or response.data)
aiogithubapi.exceptions.GitHubAuthenticationException: Bad credentials
2022-02-05 21:14:44 ERROR (MainThread) [homeassistant.components.github] Bad credentials
Traceback (most recent call last):
  File "/usr/src/homeassistant/homeassistant/components/github/coordinator.py", line 65, in _async_update_data
    response = await self.fetch_data()
  File "/usr/src/homeassistant/homeassistant/components/github/coordinator.py", line 93, in fetch_data
    return await self._client.repos.get(self.repository, **{"etag": self._etag})
  File "/usr/local/lib/python3.9/site-packages/aiogithubapi/namespaces/repos.py", line 82, in get
    response = await self._client.async_call_api(
  File "/usr/local/lib/python3.9/site-packages/aiogithubapi/client.py", line 134, in async_call_api
    raise exception(message or response.data)
aiogithubapi.exceptions.GitHubAuthenticationException: Bad credentials
2022-02-05 21:14:51 WARNING (MainThread) [homeassistant.helpers.entity] Update of media_player.spotify_mgerasika_gmail_com is taking over 10 seconds
2022-02-05 21:15:11 WARNING (MainThread) [homeassistant.components.media_player] Updating spotify media_player took longer than the scheduled update interval 0:00:30
2022-02-05 21:15:24 ERROR (MainThread) [homeassistant.components.github] Bad credentials
Traceback (most recent call last):
  File "/usr/src/homeassistant/homeassistant/components/github/coordinator.py", line 65, in _async_update_data
    response = await self.fetch_data()
  File "/usr/src/homeassistant/homeassistant/components/github/coordinator.py", line 93, in fetch_data
    return await self._client.repos.get(self.repository, **{"etag": self._etag})
  File "/usr/local/lib/python3.9/site-packages/aiogithubapi/namespaces/repos.py", line 82, in get
    response = await self._client.async_call_api(
  File "/usr/local/lib/python3.9/site-packages/aiogithubapi/client.py", line 134, in async_call_api
    raise exception(message or response.data)
aiogithubapi.exceptions.GitHubAuthenticationException: Bad credentials
2022-02-05 21:15:40 ERROR (SyncWorker_2) [spotipy.client] Max Retries reached
2022-02-05 21:15:41 WARNING (Thread-3) [custom_components.ble_monitor.ble_parser.xiaomi] Decryption failed: MAC check failed
2022-02-05 21:15:51 WARNING (MainThread) [homeassistant.helpers.entity] Update of media_player.spotify_mgerasika_gmail_com is taking over 10 seconds
2022-02-05 21:16:11 WARNING (MainThread) [homeassistant.components.media_player] Updating spotify media_player took longer than the scheduled update interval 0:00:30
2022-02-05 21:16:40 ERROR (SyncWorker_3) [spotipy.client] Max Retries reached
2022-02-05 21:16:40 WARNING (Thread-3) [custom_components.ble_monitor.ble_parser.xiaomi] Decryption failed: MAC check failed
2022-02-05 21:16:44 ERROR (MainThread) [homeassistant.components.github] Bad credentials
Traceback (most recent call last):
  File "/usr/src/homeassistant/homeassistant/components/github/coordinator.py", line 65, in _async_update_data
    response = await self.fetch_data()
  File "/usr/src/homeassistant/homeassistant/components/github/coordinator.py", line 93, in fetch_data
    return await self._client.repos.get(self.repository, **{"etag": self._etag})
  File "/usr/local/lib/python3.9/site-packages/aiogithubapi/namespaces/repos.py", line 82, in get
    response = await self._client.async_call_api(
  File "/usr/local/lib/python3.9/site-packages/aiogithubapi/client.py", line 134, in async_call_api
    raise exception(message or response.data)
aiogithubapi.exceptions.GitHubAuthenticationException: Bad credentials
2022-02-05 21:16:51 WARNING (MainThread) [homeassistant.helpers.entity] Update of media_player.spotify_mgerasika_gmail_com is taking over 10 seconds
2022-02-05 21:17:11 WARNING (MainThread) [homeassistant.components.media_player] Updating spotify media_player took longer than the scheduled update interval 0:00:30
2022-02-05 21:17:40 ERROR (SyncWorker_1) [spotipy.client] Max Retries reached
2022-02-05 21:17:51 WARNING (MainThread) [homeassistant.helpers.entity] Update of media_player.spotify_mgerasika_gmail_com is taking over 10 seconds
2022-02-05 21:18:04 ERROR (MainThread) [homeassistant.components.github] Bad credentials
Traceback (most recent call last):
  File "/usr/src/homeassistant/homeassistant/components/github/coordinator.py", line 65, in _async_update_data
    response = await self.fetch_data()
  File "/usr/src/homeassistant/homeassistant/components/github/coordinator.py", line 93, in fetch_data
    return await self._client.repos.get(self.repository, **{"etag": self._etag})
  File "/usr/local/lib/python3.9/site-packages/aiogithubapi/namespaces/repos.py", line 82, in get
    response = await self._client.async_call_api(
  File "/usr/local/lib/python3.9/site-packages/aiogithubapi/client.py", line 134, in async_call_api
    raise exception(message or response.data)
aiogithubapi.exceptions.GitHubAuthenticationException: Bad credentials
2022-02-05 21:18:11 WARNING (MainThread) [homeassistant.components.media_player] Updating spotify media_player took longer than the scheduled update interval 0:00:30
2022-02-05 21:18:40 ERROR (SyncWorker_0) [spotipy.client] Max Retries reached
2022-02-05 21:18:51 WARNING (MainThread) [homeassistant.helpers.entity] Update of media_player.spotify_mgerasika_gmail_com is taking over 10 seconds
2022-02-05 21:19:11 WARNING (MainThread) [homeassistant.components.media_player] Updating spotify media_player took longer than the scheduled update interval 0:00:30
2022-02-05 21:19:25 ERROR (MainThread) [homeassistant.components.github] Bad credentials
Traceback (most recent call last):
  File "/usr/src/homeassistant/homeassistant/components/github/coordinator.py", line 65, in _async_update_data
    response = await self.fetch_data()
  File "/usr/src/homeassistant/homeassistant/components/github/coordinator.py", line 93, in fetch_data
    return await self._client.repos.get(self.repository, **{"etag": self._etag})
  File "/usr/local/lib/python3.9/site-packages/aiogithubapi/namespaces/repos.py", line 82, in get
    response = await self._client.async_call_api(
  File "/usr/local/lib/python3.9/site-packages/aiogithubapi/client.py", line 134, in async_call_api
    raise exception(message or response.data)
aiogithubapi.exceptions.GitHubAuthenticationException: Bad credentials
2022-02-05 21:19:40 ERROR (SyncWorker_3) [spotipy.client] Max Retries reached
2022-02-05 21:19:51 WARNING (MainThread) [homeassistant.helpers.entity] Update of media_player.spotify_mgerasika_gmail_com is taking over 10 seconds
2022-02-05 21:20:11 WARNING (MainThread) [homeassistant.components.media_player] Updating spotify media_player took longer than the scheduled update interval 0:00:30
2022-02-05 21:20:22 ERROR (Thread-3) [custom_components.ble_monitor.ble_parser.xiaomi] No encryption key found for device with MAC A4:C1:38:BE:4C:FB
2022-02-05 21:20:40 ERROR (SyncWorker_0) [spotipy.client] Max Retries reached
2022-02-05 21:20:45 ERROR (MainThread) [homeassistant.components.github] Bad credentials
Traceback (most recent call last):
  File "/usr/src/homeassistant/homeassistant/components/github/coordinator.py", line 65, in _async_update_data
    response = await self.fetch_data()
  File "/usr/src/homeassistant/homeassistant/components/github/coordinator.py", line 93, in fetch_data
    return await self._client.repos.get(self.repository, **{"etag": self._etag})
  File "/usr/local/lib/python3.9/site-packages/aiogithubapi/namespaces/repos.py", line 82, in get
    response = await self._client.async_call_api(
  File "/usr/local/lib/python3.9/site-packages/aiogithubapi/client.py", line 134, in async_call_api
    raise exception(message or response.data)
aiogithubapi.exceptions.GitHubAuthenticationException: Bad credentials
2022-02-05 21:20:51 WARNING (MainThread) [homeassistant.helpers.entity] Update of media_player.spotify_mgerasika_gmail_com is taking over 10 seconds
2022-02-05 21:21:11 WARNING (MainThread) [homeassistant.components.media_player] Updating spotify media_player took longer than the scheduled update interval 0:00:30
2022-02-05 21:21:23 ERROR (Thread-3) [custom_components.ble_monitor.ble_parser.xiaomi] No encryption key found for device with MAC A4:C1:38:BE:4C:FB
2022-02-05 21:21:40 ERROR (SyncWorker_1) [spotipy.client] Max Retries reached
2022-02-05 21:21:51 WARNING (MainThread) [homeassistant.helpers.entity] Update of media_player.spotify_mgerasika_gmail_com is taking over 10 seconds
2022-02-05 21:22:05 ERROR (MainThread) [homeassistant.components.github] Bad credentials
Traceback (most recent call last):
  File "/usr/src/homeassistant/homeassistant/components/github/coordinator.py", line 65, in _async_update_data
    response = await self.fetch_data()
  File "/usr/src/homeassistant/homeassistant/components/github/coordinator.py", line 93, in fetch_data
    return await self._client.repos.get(self.repository, **{"etag": self._etag})
  File "/usr/local/lib/python3.9/site-packages/aiogithubapi/namespaces/repos.py", line 82, in get
    response = await self._client.async_call_api(
  File "/usr/local/lib/python3.9/site-packages/aiogithubapi/client.py", line 134, in async_call_api
    raise exception(message or response.data)
aiogithubapi.exceptions.GitHubAuthenticationException: Bad credentials
2022-02-05 21:22:11 WARNING (MainThread) [homeassistant.components.media_player] Updating spotify media_player took longer than the scheduled update interval 0:00:30
2022-02-05 21:22:40 ERROR (SyncWorker_2) [spotipy.client] Max Retries reached
2022-02-05 21:22:51 WARNING (MainThread) [homeassistant.helpers.entity] Update of media_player.spotify_mgerasika_gmail_com is taking over 10 seconds
2022-02-05 21:23:11 WARNING (MainThread) [homeassistant.components.media_player] Updating spotify media_player took longer than the scheduled update interval 0:00:30
2022-02-05 21:23:25 ERROR (MainThread) [homeassistant.components.github] Bad credentials
Traceback (most recent call last):
  File "/usr/src/homeassistant/homeassistant/components/github/coordinator.py", line 65, in _async_update_data
    response = await self.fetch_data()
  File "/usr/src/homeassistant/homeassistant/components/github/coordinator.py", line 93, in fetch_data
    return await self._client.repos.get(self.repository, **{"etag": self._etag})
  File "/usr/local/lib/python3.9/site-packages/aiogithubapi/namespaces/repos.py", line 82, in get
    response = await self._client.async_call_api(
  File "/usr/local/lib/python3.9/site-packages/aiogithubapi/client.py", line 134, in async_call_api
    raise exception(message or response.data)
aiogithubapi.exceptions.GitHubAuthenticationException: Bad credentials
2022-02-05 21:23:40 ERROR (SyncWorker_4) [spotipy.client] Max Retries reached
2022-02-05 21:23:51 WARNING (MainThread) [homeassistant.helpers.entity] Update of media_player.spotify_mgerasika_gmail_com is taking over 10 seconds
2022-02-05 21:24:11 WARNING (MainThread) [homeassistant.components.media_player] Updating spotify media_player took longer than the scheduled update interval 0:00:30
2022-02-05 21:24:40 ERROR (SyncWorker_0) [spotipy.client] Max Retries reached
2022-02-05 21:24:46 ERROR (MainThread) [homeassistant.components.github] Bad credentials
Traceback (most recent call last):
  File "/usr/src/homeassistant/homeassistant/components/github/coordinator.py", line 65, in _async_update_data
    response = await self.fetch_data()
  File "/usr/src/homeassistant/homeassistant/components/github/coordinator.py", line 93, in fetch_data
    return await self._client.repos.get(self.repository, **{"etag": self._etag})
  File "/usr/local/lib/python3.9/site-packages/aiogithubapi/namespaces/repos.py", line 82, in get
    response = await self._client.async_call_api(
  File "/usr/local/lib/python3.9/site-packages/aiogithubapi/client.py", line 134, in async_call_api
    raise exception(message or response.data)
aiogithubapi.exceptions.GitHubAuthenticationException: Bad credentials
2022-02-05 21:24:51 WARNING (MainThread) [homeassistant.helpers.entity] Update of media_player.spotify_mgerasika_gmail_com is taking over 10 seconds
2022-02-05 21:25:11 WARNING (MainThread) [homeassistant.components.media_player] Updating spotify media_player took longer than the scheduled update interval 0:00:30
2022-02-05 21:25:40 ERROR (SyncWorker_4) [spotipy.client] Max Retries reached
2022-02-05 21:25:51 WARNING (MainThread) [homeassistant.helpers.entity] Update of media_player.spotify_mgerasika_gmail_com is taking over 10 seconds
2022-02-05 21:26:06 ERROR (MainThread) [homeassistant.components.github] Bad credentials
Traceback (most recent call last):
  File "/usr/src/homeassistant/homeassistant/components/github/coordinator.py", line 65, in _async_update_data
    response = await self.fetch_data()
  File "/usr/src/homeassistant/homeassistant/components/github/coordinator.py", line 93, in fetch_data
    return await self._client.repos.get(self.repository, **{"etag": self._etag})
  File "/usr/local/lib/python3.9/site-packages/aiogithubapi/namespaces/repos.py", line 82, in get
    response = await self._client.async_call_api(
  File "/usr/local/lib/python3.9/site-packages/aiogithubapi/client.py", line 134, in async_call_api
    raise exception(message or response.data)
aiogithubapi.exceptions.GitHubAuthenticationException: Bad credentials
2022-02-05 21:26:11 WARNING (MainThread) [homeassistant.components.media_player] Updating spotify media_player took longer than the scheduled update interval 0:00:30
2022-02-05 21:26:39 WARNING (Thread-3) [custom_components.ble_monitor.ble_parser.xiaomi] Decryption failed: MAC check failed
2022-02-05 21:26:40 ERROR (SyncWorker_3) [spotipy.client] Max Retries reached
2022-02-05 21:26:51 WARNING (MainThread) [homeassistant.helpers.entity] Update of media_player.spotify_mgerasika_gmail_com is taking over 10 seconds
2022-02-05 21:27:11 WARNING (MainThread) [homeassistant.components.media_player] Updating spotify media_player took longer than the scheduled update interval 0:00:30
2022-02-05 21:27:26 ERROR (MainThread) [homeassistant.components.github] Bad credentials
Traceback (most recent call last):
  File "/usr/src/homeassistant/homeassistant/components/github/coordinator.py", line 65, in _async_update_data
    response = await self.fetch_data()
  File "/usr/src/homeassistant/homeassistant/components/github/coordinator.py", line 93, in fetch_data
    return await self._client.repos.get(self.repository, **{"etag": self._etag})
  File "/usr/local/lib/python3.9/site-packages/aiogithubapi/namespaces/repos.py", line 82, in get
    response = await self._client.async_call_api(
  File "/usr/local/lib/python3.9/site-packages/aiogithubapi/client.py", line 134, in async_call_api
    raise exception(message or response.data)
aiogithubapi.exceptions.GitHubAuthenticationException: Bad credentials
2022-02-05 21:27:40 WARNING (Thread-3) [custom_components.ble_monitor.ble_parser.xiaomi] Decryption failed: MAC check failed
2022-02-05 21:27:40 ERROR (SyncWorker_0) [spotipy.client] Max Retries reached
2022-02-05 21:27:51 WARNING (MainThread) [homeassistant.helpers.entity] Update of media_player.spotify_mgerasika_gmail_com is taking over 10 seconds
2022-02-05 21:28:11 WARNING (MainThread) [homeassistant.components.media_player] Updating spotify media_player took longer than the scheduled update interval 0:00:30
2022-02-05 21:28:12 ERROR (MainThread) [custom_components.hacs] HACS is disabled - HacsDisabledReason.INVALID_TOKEN
2022-02-05 21:28:12 WARNING (MainThread) [custom_components.hacs] Could not load default repositories: Bad credentials, retrying in 5 minuttes
2022-02-05 21:28:40 ERROR (SyncWorker_3) [spotipy.client] Max Retries reached
2022-02-05 21:28:47 ERROR (MainThread) [homeassistant.components.github] Bad credentials
Traceback (most recent call last):
  File "/usr/src/homeassistant/homeassistant/components/github/coordinator.py", line 65, in _async_update_data
    response = await self.fetch_data()
  File "/usr/src/homeassistant/homeassistant/components/github/coordinator.py", line 93, in fetch_data
    return await self._client.repos.get(self.repository, **{"etag": self._etag})
  File "/usr/local/lib/python3.9/site-packages/aiogithubapi/namespaces/repos.py", line 82, in get
    response = await self._client.async_call_api(
  File "/usr/local/lib/python3.9/site-packages/aiogithubapi/client.py", line 134, in async_call_api
    raise exception(message or response.data)
aiogithubapi.exceptions.GitHubAuthenticationException: Bad credentials
2022-02-05 21:28:51 WARNING (MainThread) [homeassistant.helpers.entity] Update of media_player.spotify_mgerasika_gmail_com is taking over 10 seconds
2022-02-05 21:29:11 WARNING (MainThread) [homeassistant.components.media_player] Updating spotify media_player took longer than the scheduled update interval 0:00:30
2022-02-05 21:29:40 ERROR (SyncWorker_1) [spotipy.client] Max Retries reached
2022-02-05 21:29:51 WARNING (MainThread) [homeassistant.helpers.entity] Update of media_player.spotify_mgerasika_gmail_com is taking over 10 seconds
2022-02-05 21:30:07 ERROR (MainThread) [homeassistant.components.github] Bad credentials
Traceback (most recent call last):
  File "/usr/src/homeassistant/homeassistant/components/github/coordinator.py", line 65, in _async_update_data
    response = await self.fetch_data()
  File "/usr/src/homeassistant/homeassistant/components/github/coordinator.py", line 93, in fetch_data
    return await self._client.repos.get(self.repository, **{"etag": self._etag})
  File "/usr/local/lib/python3.9/site-packages/aiogithubapi/namespaces/repos.py", line 82, in get
    response = await self._client.async_call_api(
  File "/usr/local/lib/python3.9/site-packages/aiogithubapi/client.py", line 134, in async_call_api
    raise exception(message or response.data)
aiogithubapi.exceptions.GitHubAuthenticationException: Bad credentials
2022-02-05 21:30:11 WARNING (MainThread) [homeassistant.components.media_player] Updating spotify media_player took longer than the scheduled update interval 0:00:30
2022-02-05 21:30:40 ERROR (SyncWorker_4) [spotipy.client] Max Retries reached
2022-02-05 21:30:51 WARNING (MainThread) [homeassistant.helpers.entity] Update of media_player.spotify_mgerasika_gmail_com is taking over 10 seconds
2022-02-05 21:31:11 WARNING (MainThread) [homeassistant.components.media_player] Updating spotify media_player took longer than the scheduled update interval 0:00:30
2022-02-05 21:31:23 ERROR (Thread-3) [custom_components.ble_monitor.ble_parser.xiaomi] No encryption key found for device with MAC A4:C1:38:BE:4C:FB
2022-02-05 21:31:27 ERROR (MainThread) [homeassistant.components.github] Bad credentials
Traceback (most recent call last):
  File "/usr/src/homeassistant/homeassistant/components/github/coordinator.py", line 65, in _async_update_data
    response = await self.fetch_data()
  File "/usr/src/homeassistant/homeassistant/components/github/coordinator.py", line 93, in fetch_data
    return await self._client.repos.get(self.repository, **{"etag": self._etag})
  File "/usr/local/lib/python3.9/site-packages/aiogithubapi/namespaces/repos.py", line 82, in get
    response = await self._client.async_call_api(
  File "/usr/local/lib/python3.9/site-packages/aiogithubapi/client.py", line 134, in async_call_api
    raise exception(message or response.data)
aiogithubapi.exceptions.GitHubAuthenticationException: Bad credentials
2022-02-05 21:31:40 ERROR (SyncWorker_0) [spotipy.client] Max Retries reached
2022-02-05 21:31:51 WARNING (MainThread) [homeassistant.helpers.entity] Update of media_player.spotify_mgerasika_gmail_com is taking over 10 seconds
2022-02-05 21:32:11 WARNING (MainThread) [homeassistant.components.media_player] Updating spotify media_player took longer than the scheduled update interval 0:00:30
2022-02-05 21:32:22 ERROR (Thread-3) [custom_components.ble_monitor.ble_parser.xiaomi] No encryption key found for device with MAC A4:C1:38:BE:4C:FB
2022-02-05 21:32:41 WARNING (MainThread) [homeassistant.components.media_player] Updating spotify media_player took longer than the scheduled update interval 0:00:30
2022-02-05 21:32:47 ERROR (MainThread) [homeassistant.components.github] Bad credentials
Traceback (most recent call last):
  File "/usr/src/homeassistant/homeassistant/components/github/coordinator.py", line 65, in _async_update_data
    response = await self.fetch_data()
  File "/usr/src/homeassistant/homeassistant/components/github/coordinator.py", line 93, in fetch_data
    return await self._client.repos.get(self.repository, **{"etag": self._etag})
  File "/usr/local/lib/python3.9/site-packages/aiogithubapi/namespaces/repos.py", line 82, in get
    response = await self._client.async_call_api(
  File "/usr/local/lib/python3.9/site-packages/aiogithubapi/client.py", line 134, in async_call_api
    raise exception(message or response.data)
aiogithubapi.exceptions.GitHubAuthenticationException: Bad credentials
2022-02-05 21:33:11 WARNING (MainThread) [homeassistant.components.media_player] Updating spotify media_player took longer than the scheduled update interval 0:00:30
2022-02-05 21:33:12 ERROR (SyncWorker_2) [spotipy.client] Max Retries reached
2022-02-05 21:33:51 WARNING (MainThread) [homeassistant.helpers.entity] Update of media_player.spotify_mgerasika_gmail_com is taking over 10 seconds
2022-02-05 21:34:08 ERROR (MainThread) [homeassistant.components.github] Bad credentials
Traceback (most recent call last):
  File "/usr/src/homeassistant/homeassistant/components/github/coordinator.py", line 65, in _async_update_data
    response = await self.fetch_data()
  File "/usr/src/homeassistant/homeassistant/components/github/coordinator.py", line 93, in fetch_data
    return await self._client.repos.get(self.repository, **{"etag": self._etag})
  File "/usr/local/lib/python3.9/site-packages/aiogithubapi/namespaces/repos.py", line 82, in get
    response = await self._client.async_call_api(
  File "/usr/local/lib/python3.9/site-packages/aiogithubapi/client.py", line 134, in async_call_api
    raise exception(message or response.data)
aiogithubapi.exceptions.GitHubAuthenticationException: Bad credentials
2022-02-05 21:34:11 WARNING (MainThread) [homeassistant.components.media_player] Updating spotify media_player took longer than the scheduled update interval 0:00:30
2022-02-05 21:34:40 ERROR (SyncWorker_0) [spotipy.client] Max Retries reached
2022-02-05 21:34:51 WARNING (MainThread) [homeassistant.helpers.entity] Update of media_player.spotify_mgerasika_gmail_com is taking over 10 seconds
2022-02-05 21:35:11 WARNING (MainThread) [homeassistant.components.media_player] Updating spotify media_player took longer than the scheduled update interval 0:00:30
2022-02-05 21:35:28 ERROR (MainThread) [homeassistant.components.github] Bad credentials
Traceback (most recent call last):
  File "/usr/src/homeassistant/homeassistant/components/github/coordinator.py", line 65, in _async_update_data
    response = await self.fetch_data()
  File "/usr/src/homeassistant/homeassistant/components/github/coordinator.py", line 93, in fetch_data
    return await self._client.repos.get(self.repository, **{"etag": self._etag})
  File "/usr/local/lib/python3.9/site-packages/aiogithubapi/namespaces/repos.py", line 82, in get
    response = await self._client.async_call_api(
  File "/usr/local/lib/python3.9/site-packages/aiogithubapi/client.py", line 134, in async_call_api
    raise exception(message or response.data)
aiogithubapi.exceptions.GitHubAuthenticationException: Bad credentials
2022-02-05 21:35:40 ERROR (SyncWorker_3) [spotipy.client] Max Retries reached
2022-02-05 21:35:51 WARNING (MainThread) [homeassistant.helpers.entity] Update of media_player.spotify_mgerasika_gmail_com is taking over 10 seconds
2022-02-05 21:36:11 WARNING (MainThread) [homeassistant.components.media_player] Updating spotify media_player took longer than the scheduled update interval 0:00:30
2022-02-05 21:36:40 ERROR (SyncWorker_1) [spotipy.client] Max Retries reached
2022-02-05 21:36:48 ERROR (MainThread) [homeassistant.components.github] Bad credentials
Traceback (most recent call last):
  File "/usr/src/homeassistant/homeassistant/components/github/coordinator.py", line 65, in _async_update_data
    response = await self.fetch_data()
  File "/usr/src/homeassistant/homeassistant/components/github/coordinator.py", line 93, in fetch_data
    return await self._client.repos.get(self.repository, **{"etag": self._etag})
  File "/usr/local/lib/python3.9/site-packages/aiogithubapi/namespaces/repos.py", line 82, in get
    response = await self._client.async_call_api(
  File "/usr/local/lib/python3.9/site-packages/aiogithubapi/client.py", line 134, in async_call_api
    raise exception(message or response.data)
aiogithubapi.exceptions.GitHubAuthenticationException: Bad credentials
2022-02-05 21:36:51 WARNING (MainThread) [homeassistant.helpers.entity] Update of media_player.spotify_mgerasika_gmail_com is taking over 10 seconds
2022-02-05 21:37:11 WARNING (MainThread) [homeassistant.components.media_player] Updating spotify media_player took longer than the scheduled update interval 0:00:30
2022-02-05 21:37:40 WARNING (Thread-3) [custom_components.ble_monitor.ble_parser.xiaomi] Decryption failed: MAC check failed
2022-02-05 21:37:40 ERROR (SyncWorker_3) [spotipy.client] Max Retries reached
2022-02-05 21:37:51 WARNING (MainThread) [homeassistant.helpers.entity] Update of media_player.spotify_mgerasika_gmail_com is taking over 10 seconds
2022-02-05 21:38:08 ERROR (MainThread) [homeassistant.components.github] Bad credentials
Traceback (most recent call last):
  File "/usr/src/homeassistant/homeassistant/components/github/coordinator.py", line 65, in _async_update_data
    response = await self.fetch_data()
  File "/usr/src/homeassistant/homeassistant/components/github/coordinator.py", line 93, in fetch_data
    return await self._client.repos.get(self.repository, **{"etag": self._etag})
  File "/usr/local/lib/python3.9/site-packages/aiogithubapi/namespaces/repos.py", line 82, in get
    response = await self._client.async_call_api(
  File "/usr/local/lib/python3.9/site-packages/aiogithubapi/client.py", line 134, in async_call_api
    raise exception(message or response.data)
aiogithubapi.exceptions.GitHubAuthenticationException: Bad credentials
2022-02-05 21:38:11 WARNING (MainThread) [homeassistant.components.media_player] Updating spotify media_player took longer than the scheduled update interval 0:00:30
2022-02-05 21:38:39 WARNING (Thread-3) [custom_components.ble_monitor.ble_parser.xiaomi] Decryption failed: MAC check failed
2022-02-05 21:38:40 ERROR (SyncWorker_0) [spotipy.client] Max Retries reached
2022-02-05 21:38:51 WARNING (MainThread) [homeassistant.helpers.entity] Update of media_player.spotify_mgerasika_gmail_com is taking over 10 seconds
2022-02-05 21:39:11 WARNING (MainThread) [homeassistant.components.media_player] Updating spotify media_player took longer than the scheduled update interval 0:00:30
2022-02-05 21:39:29 ERROR (MainThread) [homeassistant.components.github] Bad credentials
Traceback (most recent call last):
  File "/usr/src/homeassistant/homeassistant/components/github/coordinator.py", line 65, in _async_update_data
    response = await self.fetch_data()
  File "/usr/src/homeassistant/homeassistant/components/github/coordinator.py", line 93, in fetch_data
    return await self._client.repos.get(self.repository, **{"etag": self._etag})
  File "/usr/local/lib/python3.9/site-packages/aiogithubapi/namespaces/repos.py", line 82, in get
    response = await self._client.async_call_api(
  File "/usr/local/lib/python3.9/site-packages/aiogithubapi/client.py", line 134, in async_call_api
    raise exception(message or response.data)
aiogithubapi.exceptions.GitHubAuthenticationException: Bad credentials
2022-02-05 21:39:40 ERROR (SyncWorker_3) [spotipy.client] Max Retries reached
2022-02-05 21:39:51 WARNING (MainThread) [homeassistant.helpers.entity] Update of media_player.spotify_mgerasika_gmail_com is taking over 10 seconds
2022-02-05 21:40:11 WARNING (MainThread) [homeassistant.components.media_player] Updating spotify media_player took longer than the scheduled update interval 0:00:30
2022-02-05 21:40:40 ERROR (SyncWorker_0) [spotipy.client] Max Retries reached
2022-02-05 21:40:49 ERROR (MainThread) [homeassistant.components.github] Bad credentials
Traceback (most recent call last):
  File "/usr/src/homeassistant/homeassistant/components/github/coordinator.py", line 65, in _async_update_data
    response = await self.fetch_data()
  File "/usr/src/homeassistant/homeassistant/components/github/coordinator.py", line 93, in fetch_data
    return await self._client.repos.get(self.repository, **{"etag": self._etag})
  File "/usr/local/lib/python3.9/site-packages/aiogithubapi/namespaces/repos.py", line 82, in get
    response = await self._client.async_call_api(
  File "/usr/local/lib/python3.9/site-packages/aiogithubapi/client.py", line 134, in async_call_api
    raise exception(message or response.data)
aiogithubapi.exceptions.GitHubAuthenticationException: Bad credentials
2022-02-05 21:40:51 WARNING (MainThread) [homeassistant.helpers.entity] Update of media_player.spotify_mgerasika_gmail_com is taking over 10 seconds
2022-02-05 21:41:11 WARNING (MainThread) [homeassistant.components.media_player] Updating spotify media_player took longer than the scheduled update interval 0:00:30
2022-02-05 21:41:40 ERROR (SyncWorker_3) [spotipy.client] Max Retries reached
2022-02-05 21:41:51 WARNING (MainThread) [homeassistant.helpers.entity] Update of media_player.spotify_mgerasika_gmail_com is taking over 10 seconds
2022-02-05 21:42:09 ERROR (MainThread) [homeassistant.components.github] Bad credentials
Traceback (most recent call last):
  File "/usr/src/homeassistant/homeassistant/components/github/coordinator.py", line 65, in _async_update_data
    response = await self.fetch_data()
  File "/usr/src/homeassistant/homeassistant/components/github/coordinator.py", line 93, in fetch_data
    return await self._client.repos.get(self.repository, **{"etag": self._etag})
  File "/usr/local/lib/python3.9/site-packages/aiogithubapi/namespaces/repos.py", line 82, in get
    response = await self._client.async_call_api(
  File "/usr/local/lib/python3.9/site-packages/aiogithubapi/client.py", line 134, in async_call_api
    raise exception(message or response.data)
aiogithubapi.exceptions.GitHubAuthenticationException: Bad credentials
2022-02-05 21:42:11 WARNING (MainThread) [homeassistant.components.media_player] Updating spotify media_player took longer than the scheduled update interval 0:00:30
2022-02-05 21:42:21 ERROR (Thread-3) [custom_components.ble_monitor.ble_parser.xiaomi] No encryption key found for device with MAC A4:C1:38:BE:4C:FB
2022-02-05 21:42:40 ERROR (SyncWorker_1) [spotipy.client] Max Retries reached
2022-02-05 21:42:51 WARNING (MainThread) [homeassistant.helpers.entity] Update of media_player.spotify_mgerasika_gmail_com is taking over 10 seconds
2022-02-05 21:43:11 WARNING (MainThread) [homeassistant.components.media_player] Updating spotify media_player took longer than the scheduled update interval 0:00:30
2022-02-05 21:43:22 ERROR (Thread-3) [custom_components.ble_monitor.ble_parser.xiaomi] No encryption key found for device with MAC A4:C1:38:BE:4C:FB
2022-02-05 21:43:29 ERROR (MainThread) [homeassistant.components.github] Bad credentials
Traceback (most recent call last):
  File "/usr/src/homeassistant/homeassistant/components/github/coordinator.py", line 65, in _async_update_data
    response = await self.fetch_data()
  File "/usr/src/homeassistant/homeassistant/components/github/coordinator.py", line 93, in fetch_data
    return await self._client.repos.get(self.repository, **{"etag": self._etag})
  File "/usr/local/lib/python3.9/site-packages/aiogithubapi/namespaces/repos.py", line 82, in get
    response = await self._client.async_call_api(
  File "/usr/local/lib/python3.9/site-packages/aiogithubapi/client.py", line 134, in async_call_api
    raise exception(message or response.data)
aiogithubapi.exceptions.GitHubAuthenticationException: Bad credentials
2022-02-05 21:43:40 ERROR (SyncWorker_3) [spotipy.client] Max Retries reached
2022-02-05 21:43:51 WARNING (MainThread) [homeassistant.helpers.entity] Update of media_player.spotify_mgerasika_gmail_com is taking over 10 seconds
2022-02-05 21:44:11 WARNING (MainThread) [homeassistant.components.media_player] Updating spotify media_player took longer than the scheduled update interval 0:00:30
2022-02-05 21:44:39 WARNING (Thread-3) [custom_components.ble_monitor.ble_parser.xiaomi] Decryption failed: MAC check failed
2022-02-05 21:44:40 ERROR (SyncWorker_4) [spotipy.client] Max Retries reached
2022-02-05 21:44:50 ERROR (MainThread) [homeassistant.components.github] Bad credentials
Traceback (most recent call last):
  File "/usr/src/homeassistant/homeassistant/components/github/coordinator.py", line 65, in _async_update_data
    response = await self.fetch_data()
  File "/usr/src/homeassistant/homeassistant/components/github/coordinator.py", line 93, in fetch_data
    return await self._client.repos.get(self.repository, **{"etag": self._etag})
  File "/usr/local/lib/python3.9/site-packages/aiogithubapi/namespaces/repos.py", line 82, in get
    response = await self._client.async_call_api(
  File "/usr/local/lib/python3.9/site-packages/aiogithubapi/client.py", line 134, in async_call_api
    raise exception(message or response.data)
aiogithubapi.exceptions.GitHubAuthenticationException: Bad credentials
2022-02-05 21:44:51 WARNING (MainThread) [homeassistant.helpers.entity] Update of media_player.spotify_mgerasika_gmail_com is taking over 10 seconds
2022-02-05 21:45:11 WARNING (MainThread) [homeassistant.components.media_player] Updating spotify media_player took longer than the scheduled update interval 0:00:30
2022-02-05 21:45:40 ERROR (SyncWorker_3) [spotipy.client] Max Retries reached
2022-02-05 21:45:51 WARNING (MainThread) [homeassistant.helpers.entity] Update of media_player.spotify_mgerasika_gmail_com is taking over 10 seconds
2022-02-05 21:46:10 ERROR (MainThread) [homeassistant.components.github] Bad credentials
Traceback (most recent call last):
  File "/usr/src/homeassistant/homeassistant/components/github/coordinator.py", line 65, in _async_update_data
    response = await self.fetch_data()
  File "/usr/src/homeassistant/homeassistant/components/github/coordinator.py", line 93, in fetch_data
    return await self._client.repos.get(self.repository, **{"etag": self._etag})
  File "/usr/local/lib/python3.9/site-packages/aiogithubapi/namespaces/repos.py", line 82, in get
    response = await self._client.async_call_api(
  File "/usr/local/lib/python3.9/site-packages/aiogithubapi/client.py", line 134, in async_call_api
    raise exception(message or response.data)
aiogithubapi.exceptions.GitHubAuthenticationException: Bad credentials
2022-02-05 21:46:11 WARNING (MainThread) [homeassistant.components.media_player] Updating spotify media_player took longer than the scheduled update interval 0:00:30
2022-02-05 21:46:40 ERROR (SyncWorker_0) [spotipy.client] Max Retries reached
2022-02-05 21:46:51 WARNING (MainThread) [homeassistant.helpers.entity] Update of media_player.spotify_mgerasika_gmail_com is taking over 10 seconds
2022-02-05 21:47:11 WARNING (MainThread) [homeassistant.components.media_player] Updating spotify media_player took longer than the scheduled update interval 0:00:30
2022-02-05 21:47:30 ERROR (MainThread) [homeassistant.components.github] Bad credentials
Traceback (most recent call last):
  File "/usr/src/homeassistant/homeassistant/components/github/coordinator.py", line 65, in _async_update_data
    response = await self.fetch_data()
  File "/usr/src/homeassistant/homeassistant/components/github/coordinator.py", line 93, in fetch_data
    return await self._client.repos.get(self.repository, **{"etag": self._etag})
  File "/usr/local/lib/python3.9/site-packages/aiogithubapi/namespaces/repos.py", line 82, in get
    response = await self._client.async_call_api(
  File "/usr/local/lib/python3.9/site-packages/aiogithubapi/client.py", line 134, in async_call_api
    raise exception(message or response.data)
aiogithubapi.exceptions.GitHubAuthenticationException: Bad credentials
2022-02-05 21:47:40 ERROR (SyncWorker_4) [spotipy.client] Max Retries reached
2022-02-05 21:47:51 WARNING (MainThread) [homeassistant.helpers.entity] Update of media_player.spotify_mgerasika_gmail_com is taking over 10 seconds
2022-02-05 21:48:11 WARNING (MainThread) [homeassistant.components.media_player] Updating spotify media_player took longer than the scheduled update interval 0:00:30
2022-02-05 21:48:39 WARNING (Thread-3) [custom_components.ble_monitor.ble_parser.xiaomi] Decryption failed: MAC check failed
2022-02-05 21:48:40 ERROR (SyncWorker_2) [spotipy.client] Max Retries reached
2022-02-05 21:48:51 ERROR (MainThread) [homeassistant.components.github] Bad credentials
Traceback (most recent call last):
  File "/usr/src/homeassistant/homeassistant/components/github/coordinator.py", line 65, in _async_update_data
    response = await self.fetch_data()
  File "/usr/src/homeassistant/homeassistant/components/github/coordinator.py", line 93, in fetch_data
    return await self._client.repos.get(self.repository, **{"etag": self._etag})
  File "/usr/local/lib/python3.9/site-packages/aiogithubapi/namespaces/repos.py", line 82, in get
    response = await self._client.async_call_api(
  File "/usr/local/lib/python3.9/site-packages/aiogithubapi/client.py", line 134, in async_call_api
    raise exception(message or response.data)
aiogithubapi.exceptions.GitHubAuthenticationException: Bad credentials
2022-02-05 21:48:51 WARNING (MainThread) [homeassistant.helpers.entity] Update of media_player.spotify_mgerasika_gmail_com is taking over 10 seconds
2022-02-05 21:49:11 WARNING (MainThread) [homeassistant.components.media_player] Updating spotify media_player took longer than the scheduled update interval 0:00:30
2022-02-05 21:49:39 WARNING (Thread-3) [custom_components.ble_monitor.ble_parser.xiaomi] Decryption failed: MAC check failed
2022-02-05 21:49:40 ERROR (SyncWorker_4) [spotipy.client] Max Retries reached
2022-02-05 21:49:51 WARNING (MainThread) [homeassistant.helpers.entity] Update of media_player.spotify_mgerasika_gmail_com is taking over 10 seconds
2022-02-05 21:50:11 ERROR (MainThread) [homeassistant.components.github] Bad credentials
Traceback (most recent call last):
  File "/usr/src/homeassistant/homeassistant/components/github/coordinator.py", line 65, in _async_update_data
    response = await self.fetch_data()
  File "/usr/src/homeassistant/homeassistant/components/github/coordinator.py", line 93, in fetch_data
    return await self._client.repos.get(self.repository, **{"etag": self._etag})
  File "/usr/local/lib/python3.9/site-packages/aiogithubapi/namespaces/repos.py", line 82, in get
    response = await self._client.async_call_api(
  File "/usr/local/lib/python3.9/site-packages/aiogithubapi/client.py", line 134, in async_call_api
    raise exception(message or response.data)
aiogithubapi.exceptions.GitHubAuthenticationException: Bad credentials
2022-02-05 21:50:11 WARNING (MainThread) [homeassistant.components.media_player] Updating spotify media_player took longer than the scheduled update interval 0:00:30
2022-02-05 21:50:40 ERROR (SyncWorker_2) [spotipy.client] Max Retries reached
2022-02-05 21:50:51 WARNING (MainThread) [homeassistant.helpers.entity] Update of media_player.spotify_mgerasika_gmail_com is taking over 10 seconds
2022-02-05 21:51:11 WARNING (MainThread) [homeassistant.components.media_player] Updating spotify media_player took longer than the scheduled update interval 0:00:30
2022-02-05 21:51:31 ERROR (MainThread) [homeassistant.components.github] Bad credentials
Traceback (most recent call last):
  File "/usr/src/homeassistant/homeassistant/components/github/coordinator.py", line 65, in _async_update_data
    response = await self.fetch_data()
  File "/usr/src/homeassistant/homeassistant/components/github/coordinator.py", line 93, in fetch_data
    return await self._client.repos.get(self.repository, **{"etag": self._etag})
  File "/usr/local/lib/python3.9/site-packages/aiogithubapi/namespaces/repos.py", line 82, in get
    response = await self._client.async_call_api(
  File "/usr/local/lib/python3.9/site-packages/aiogithubapi/client.py", line 134, in async_call_api
    raise exception(message or response.data)
aiogithubapi.exceptions.GitHubAuthenticationException: Bad credentials
2022-02-05 21:51:40 ERROR (SyncWorker_0) [spotipy.client] Max Retries reached
2022-02-05 21:51:51 WARNING (MainThread) [homeassistant.helpers.entity] Update of media_player.spotify_mgerasika_gmail_com is taking over 10 seconds
2022-02-05 21:52:11 WARNING (MainThread) [homeassistant.components.media_player] Updating spotify media_player took longer than the scheduled update interval 0:00:30
2022-02-05 21:52:40 ERROR (SyncWorker_1) [spotipy.client] Max Retries reached
2022-02-05 21:52:51 WARNING (MainThread) [homeassistant.helpers.entity] Update of media_player.spotify_mgerasika_gmail_com is taking over 10 seconds
2022-02-05 21:52:51 ERROR (MainThread) [homeassistant.components.github] Bad credentials
Traceback (most recent call last):
  File "/usr/src/homeassistant/homeassistant/components/github/coordinator.py", line 65, in _async_update_data
    response = await self.fetch_data()
  File "/usr/src/homeassistant/homeassistant/components/github/coordinator.py", line 93, in fetch_data
    return await self._client.repos.get(self.repository, **{"etag": self._etag})
  File "/usr/local/lib/python3.9/site-packages/aiogithubapi/namespaces/repos.py", line 82, in get
    response = await self._client.async_call_api(
  File "/usr/local/lib/python3.9/site-packages/aiogithubapi/client.py", line 134, in async_call_api
    raise exception(message or response.data)
aiogithubapi.exceptions.GitHubAuthenticationException: Bad credentials
2022-02-05 21:53:11 WARNING (MainThread) [homeassistant.components.media_player] Updating spotify media_player took longer than the scheduled update interval 0:00:30
2022-02-05 21:53:21 ERROR (Thread-3) [custom_components.ble_monitor.ble_parser.xiaomi] No encryption key found for device with MAC A4:C1:38:BE:4C:FB
2022-02-05 21:53:40 ERROR (SyncWorker_3) [spotipy.client] Max Retries reached
2022-02-05 21:53:51 WARNING (MainThread) [homeassistant.helpers.entity] Update of media_player.spotify_mgerasika_gmail_com is taking over 10 seconds
2022-02-05 21:53:53 ERROR (MainThread) [homeassistant] Error doing job: Task exception was never retrieved
Traceback (most recent call last):
  File "/usr/src/homeassistant/homeassistant/components/hassio/ingress.py", line 254, in _websocket_forward
    await ws_to.send_bytes(msg.data)
  File "/usr/local/lib/python3.9/site-packages/aiohttp/client_ws.py", line 156, in send_bytes
    await self._writer.send(data, binary=True, compress=compress)
  File "/usr/local/lib/python3.9/site-packages/aiohttp/http_websocket.py", line 688, in send
    await self._send_frame(message, WSMsgType.BINARY, compress)
  File "/usr/local/lib/python3.9/site-packages/aiohttp/http_websocket.py", line 659, in _send_frame
    await self.protocol._drain_helper()
  File "/usr/local/lib/python3.9/site-packages/aiohttp/base_protocol.py", line 87, in _drain_helper
    await asyncio.shield(waiter)
aiohttp.client_exceptions.ClientOSError: [Errno 104] Connection reset by peer
2022-02-05 21:53:53 ERROR (MainThread) [homeassistant] Error doing job: Task exception was never retrieved
Traceback (most recent call last):
  File "/usr/src/homeassistant/homeassistant/components/hassio/ingress.py", line 254, in _websocket_forward
    await ws_to.send_bytes(msg.data)
  File "/usr/local/lib/python3.9/site-packages/aiohttp/client_ws.py", line 156, in send_bytes
    await self._writer.send(data, binary=True, compress=compress)
  File "/usr/local/lib/python3.9/site-packages/aiohttp/http_websocket.py", line 688, in send
    await self._send_frame(message, WSMsgType.BINARY, compress)
  File "/usr/local/lib/python3.9/site-packages/aiohttp/http_websocket.py", line 659, in _send_frame
    await self.protocol._drain_helper()
  File "/usr/local/lib/python3.9/site-packages/aiohttp/base_protocol.py", line 87, in _drain_helper
    await asyncio.shield(waiter)
aiohttp.client_exceptions.ClientOSError: [Errno 32] Broken pipe
2022-02-05 21:54:11 WARNING (MainThread) [homeassistant.components.media_player] Updating spotify media_player took longer than the scheduled update interval 0:00:30
2022-02-05 21:54:12 ERROR (MainThread) [homeassistant.components.github] Bad credentials
Traceback (most recent call last):
  File "/usr/src/homeassistant/homeassistant/components/github/coordinator.py", line 65, in _async_update_data
    response = await self.fetch_data()
  File "/usr/src/homeassistant/homeassistant/components/github/coordinator.py", line 93, in fetch_data
    return await self._client.repos.get(self.repository, **{"etag": self._etag})
  File "/usr/local/lib/python3.9/site-packages/aiogithubapi/namespaces/repos.py", line 82, in get
    response = await self._client.async_call_api(
  File "/usr/local/lib/python3.9/site-packages/aiogithubapi/client.py", line 134, in async_call_api
    raise exception(message or response.data)
aiogithubapi.exceptions.GitHubAuthenticationException: Bad credentials
2022-02-05 21:54:22 ERROR (Thread-3) [custom_components.ble_monitor.ble_parser.xiaomi] No encryption key found for device with MAC A4:C1:38:BE:4C:FB
2022-02-05 21:54:27 ERROR (MainThread) [homeassistant] Error doing job: Task exception was never retrieved
Traceback (most recent call last):
  File "/usr/src/homeassistant/homeassistant/components/hassio/ingress.py", line 254, in _websocket_forward
    await ws_to.send_bytes(msg.data)
  File "/usr/local/lib/python3.9/site-packages/aiohttp/client_ws.py", line 156, in send_bytes
    await self._writer.send(data, binary=True, compress=compress)
  File "/usr/local/lib/python3.9/site-packages/aiohttp/http_websocket.py", line 688, in send
    await self._send_frame(message, WSMsgType.BINARY, compress)
  File "/usr/local/lib/python3.9/site-packages/aiohttp/http_websocket.py", line 659, in _send_frame
    await self.protocol._drain_helper()
  File "/usr/local/lib/python3.9/site-packages/aiohttp/base_protocol.py", line 87, in _drain_helper
    await asyncio.shield(waiter)
aiohttp.client_exceptions.ClientOSError: [Errno 104] Connection reset by peer
2022-02-05 21:54:40 ERROR (SyncWorker_1) [spotipy.client] Max Retries reached
2022-02-05 21:54:51 WARNING (MainThread) [homeassistant.helpers.entity] Update of media_player.spotify_mgerasika_gmail_com is taking over 10 seconds
2022-02-05 21:55:11 WARNING (MainThread) [homeassistant.components.media_player] Updating spotify media_player took longer than the scheduled update interval 0:00:30
